Workbook

Sheet 使用说明
A1: 动作要素工时与员工负荷表模板
A3: 用途 | B3: 用于录入单个工序下的多个动作要素测量时间，自动计算动作平均ST、工序总ST、宽放ST，并生成动作堆叠山积图和员工负荷表。
A4: 容量 | B4: 无宏稳定模板，预置 140 个工序，每个工序 5 行动作要素，共 700 行。
A5: 动作序号 | B5: 动作序号按 ST1、ST2、ST3、ST4、ST5 填充，表示一个工序内的五个动作段。
A6: 山积分析 | B6: 山积图柱形展示真实动作平均ST堆叠，并显示每段时间标签；TT基准用折线显示。
A7: 员工负荷表 | B7: 横向自动抓取工序号、工序名称、动作名称、动作时间、总工时、目标节拍和实际节拍。

Sheet 参数设置
A1: 参数设置
A2: 参数 | B2: 数值 | C2: 说明
A3: 计划单班产量(pcs/班) | C3: 由用户自行填写，用于计算目标节拍 TT
A4: 班次工时(h/班) | B4: 11 | C4: 单班可用工时
A5: 稼动率 | B5: 1 | C5: 有效生产时间比例
A6: 宽放率 | B6: 0.05 | C6: 用于补充计算宽放ST，不参与山积图柱形
A7: 目标节拍TT(s) | B7: =IFERROR(B4*3600*B5/B3,"") | C7: 单班可用秒数除以计划单班产量

Sheet 动作要素测量
A1: 动作要素测量
A2: 工序号 | B2: 工序名称 | C2: 动作序号 | D2: 动作单元描述 | E2: ST1 | F2: ST2 | G2: ST3 | H2: ST4 | I2: ST5 | J2: 平均ST | K2: 工序总ST | L2: 宽放ST | M2: TT基准 | N2: 状态 | O2: 备注
A3: 1 | C3: ST1 | J3: =IF(COUNT(E3:I3)=0,"",AVERAGE(E3:I3)) | K3: =IF(C3<>"ST1","",IF(COUNTIFS($A:$A,A3,$J:$J,"<>")=0,"",SUMIFS($J:$J,$A:$A,A3))) -> 0 | L3: =IF(C3<>"ST1","",IF(K3="","",K3*(1+参数设置!$B$6))) -> 0 | M3: =IF(A3="","",参数设置!$B$7) | N3: =IF(K3="","",IF(M3="","",IF(K3>M3,"超节拍",IF(K3>=M3*0.9,"接近上限","正常"))))
A4: 1 | C4: ST2 | J4: =IF(COUNT(E4:I4)=0,"",AVERAGE(E4:I4)) | K4: =IF(C4<>"ST1","",IF(COUNTIFS($A:$A,A4,$J:$J,"<>")=0,"",SUMIFS($J:$J,$A:$A,A4))) | L4: =IF(C4<>"ST1","",IF(K4="","",K4*(1+参数设置!$B$6))) | M4: =IF(A4="","",参数设置!$B$7) | N4: =IF(K4="","",IF(M4="","",IF(K4>M4,"超节拍",IF(K4>=M4*0.9,"接近上限","正常"))))
A5: 1 | C5: ST3 | J5: =IF(COUNT(E5:I5)=0,"",AVERAGE(E5:I5)) | K5: =IF(C5<>"ST1","",IF(COUNTIFS($A:$A,A5,$J:$J,"<>")=0,"",SUMIFS($J:$J,$A:$A,A5))) | L5: =IF(C5<>"ST1","",IF(K5="","",K5*(1+参数设置!$B$6))) | M5: =IF(A5="","",参数设置!$B$7) | N5: =IF(K5="","",IF(M5="","",IF(K5>M5,"超节拍",IF(K5>=M5*0.9,"接近上限","正常"))))
A6: 1 | C6: ST4 | J6: =IF(COUNT(E6:I6)=0,"",AVERAGE(E6:I6)) | K6: =IF(C6<>"ST1","",IF(COUNTIFS($A:$A,A6,$J:$J,"<>")=0,"",SUMIFS($J:$J,$A:$A,A6))) | L6: =IF(C6<>"ST1","",IF(K6="","",K6*(1+参数设置!$B$6))) | M6: =IF(A6="","",参数设置!$B$7) | N6: =IF(K6="","",IF(M6="","",IF(K6>M6,"超节拍",IF(K6>=M6*0.9,"接近上限","正常"))))
A7: 1 | C7: ST5 | J7: =IF(COUNT(E7:I7)=0,"",AVERAGE(E7:I7)) | K7: =IF(C7<>"ST1","",IF(COUNTIFS($A:$A,A7,$J:$J,"<>")=0,"",SUMIFS($J:$J,$A:$A,A7))) | L7: =IF(C7<>"ST1","",IF(K7="","",K7*(1+参数设置!$B$6))) | M7: =IF(A7="","",参数设置!$B$7) | N7: =IF(K7="","",IF(M7="","",IF(K7>M7,"超节拍",IF(K7>=M7*0.9,"接近上限","正常"))))
A8: 2 | C8: ST1 | J8: =IF(COUNT(E8:I8)=0,"",AVERAGE(E8:I8)) | K8: =IF(C8<>"ST1","",IF(COUNTIFS($A:$A,A8,$J:$J,"<>")=0,"",SUMIFS($J:$J,$A:$A,A8))) -> 0 | L8: =IF(C8<>"ST1","",IF(K8="","",K8*(1+参数设置!$B$6))) -> 0 | M8: =IF(A8="","",参数设置!$B$7) | N8: =IF(K8="","",IF(M8="","",IF(K8>M8,"超节拍",IF(K8>=M8*0.9,"接近上限","正常"))))
A9: 2 | C9: ST2 | J9: =IF(COUNT(E9:I9)=0,"",AVERAGE(E9:I9)) | K9: =IF(C9<>"ST1","",IF(COUNTIFS($A:$A,A9,$J:$J,"<>")=0,"",SUMIFS($J:$J,$A:$A,A9))) | L9: =IF(C9<>"ST1","",IF(K9="","",K9*(1+参数设置!$B$6))) | M9: =IF(A9="","",参数设置!$B$7) | N9: =IF(K9="","",IF(M9="","",IF(K9>M9,"超节拍",IF(K9>=M9*0.9,"接近上限","正常"))))
A10: 2 | C10: ST3 | J10: =IF(COUNT(E10:I10)=0,"",AVERAGE(E10:I10)) | K10: =IF(C10<>"ST1","",IF(COUNTIFS($A:$A,A10,$J:$J,"<>")=0,"",SUMIFS($J:$J,$A:$A,A10))) | L10: =IF(C10<>"ST1","",IF(K10="","",K10*(1+参数设置!$B$6))) | M10: =IF(A10="","",参数设置!$B$7) | N10: =IF(K10="","",IF(M10="","",IF(K10>M10,"超节拍",IF(K10>=M10*0.9,"接近上限","正常"))))
A11: 2 | C11: ST4 | J11: =IF(COUNT(E11:I11)=0,"",AVERAGE(E11:I11)) | K11: =IF(C11<>"ST1","",IF(COUNTIFS($A:$A,A11,$J:$J,"<>")=0,"",SUMIFS($J:$J,$A:$A,A11))) | L11: =IF(C11<>"ST1","",IF(K11="","",K11*(1+参数设置!$B$6))) | M11: =IF(A11="","",参数设置!$B$7) | N11: =IF(K11="","",IF(M11="","",IF(K11>M11,"超节拍",IF(K11>=M11*0.9,"接近上限","正常"))))
A12: 2 | C12: ST5 | J12: =IF(COUNT(E12:I12)=0,"",AVERAGE(E12:I12)) | K12: =IF(C12<>"ST1","",IF(COUNTIFS($A:$A,A12,$J:$J,"<>")=0,"",SUMIFS($J:$J,$A:$A,A12))) | L12: =IF(C12<>"ST1","",IF(K12="","",K12*(1+参数设置!$B$6))) | M12: =IF(A12="","",参数设置!$B$7) | N12: =IF(K12="","",IF(M12="","",IF(K12>M12,"超节拍",IF(K12>=M12*0.9,"接近上限","正常"))))
A13: 3 | C13: ST1 | J13: =IF(COUNT(E13:I13)=0,"",AVERAGE(E13:I13)) | K13: =IF(C13<>"ST1","",IF(COUNTIFS($A:$A,A13,$J:$J,"<>")=0,"",SUMIFS($J:$J,$A:$A,A13))) -> 0 | L13: =IF(C13<>"ST1","",IF(K13="","",K13*(1+参数设置!$B$6))) -> 0 | M13: =IF(A13="","",参数设置!$B$7) | N13: =IF(K13="","",IF(M13="","",IF(K13>M13,"超节拍",IF(K13>=M13*0.9,"接近上限","正常"))))
A14: 3 | C14: ST2 | J14: =IF(COUNT(E14:I14)=0,"",AVERAGE(E14:I14)) | K14: =IF(C14<>"ST1","",IF(COUNTIFS($A:$A,A14,$J:$J,"<>")=0,"",SUMIFS($J:$J,$A:$A,A14))) | L14: =IF(C14<>"ST1","",IF(K14="","",K14*(1+参数设置!$B$6))) | M14: =IF(A14="","",参数设置!$B$7) | N14: =IF(K14="","",IF(M14="","",IF(K14>M14,"超节拍",IF(K14>=M14*0.9,"接近上限","正常"))))
... A702: 140 | C702: ST5 | J702: =IF(COUNT(E702:I702)=0,"",AVERAGE(E702:I702)) | K702: =IF(C702<>"ST1","",IF(COUNTIFS($A:$A,A702,$J:$J,"<>")=0,"",SUMIFS($J:$J,$A:$A,A702))) | L702: =IF(C702<>"ST1","",IF(K702="","",K702*(1+参数设置!$B$6))) | M702: =IF(A702="","",参数设置!$B$7) | N702: =IF(K702="","",IF(M702="","",IF(K702>M702,"超节拍",IF(K702>=M702*0.9,"接近上限","正常"))))

Sheet 员工负荷表
A1: 工序序号 | B1: =动作要素测量!A3 -> 1 | C1: =动作要素测量!A8 -> 2 | D1: =动作要素测量!A13 -> 3 | E1: =动作要素测量!A18 -> 4 | F1: =动作要素测量!A23 -> 5 | G1: =动作要素测量!A28 -> 6 | H1: =动作要素测量!A33 -> 7 | I1: =动作要素测量!A38 -> 8 | J1: =动作要素测量!A43 -> 9 | K1: =动作要素测量!A48 -> 10 | L1: =动作要素测量!A53 -> 11 | M1: =动作要素测量!A58 -> 12 | N1: =动作要素测量!A63 -> 13 | O1: =动作要素测量!A68 -> 14 | P1: =动作要素测量!A73 -> 15 | Q1: =动作要素测量!A78 -> 16 | R1: =动作要素测量!A83 -> 17 | S1: =动作要素测量!A88 -> 18 | T1: =动作要素测量!A93 -> 19 | U1: =动作要素测量!A98 -> 20 | V1: =动作要素测量!A103 -> 21 | W1: =动作要素测量!A108 -> 22 | X1: =动作要素测量!A113 -> 23 | Y1: =动作要素测量!A118 -> 24 | Z1: =动作要素测量!A123 -> 25 | AA1: =动作要素测量!A128 -> 26 | AB1: =动作要素测量!A133 -> 27 | AC1: =动作要素测量!A138 -> 28 | AD1: =动作要素测量!A143 -> 29 | AE1: =动作要素测量!A148 -> 30 | AF1: =动作要素测量!A153 -> 31 | AG1: =动作要素测量!A158 -> 32 | AH1: =动作要素测量!A163 -> 33 | AI1: =动作要素测量!A168 -> 34 | AJ1: =动作要素测量!A173 -> 35 | AK1: =动作要素测量!A178 -> 36 | AL1: =动作要素测量!A183 -> 37 | AM1: =动作要素测量!A188 -> 38 | AN1: =动作要素测量!A193 -> 39 | AO1: =动作要素测量!A198 -> 40 | AP1: =动作要素测量!A203 -> 41 | AQ1: =动作要素测量!A208 -> 42 | AR1: =动作要素测量!A213 -> 43 | AS1: =动作要素测量!A218 -> 44 | AT1: =动作要素测量!A223 -> 45 | AU1: =动作要素测量!A228 -> 46 | AV1: =动作要素测量!A233 -> 47 | AW1: =动作要素测量!A238 -> 48 | AX1: =动作要素测量!A243 -> 49 | AY1: =动作要素测量!A248 -> 50 | AZ1: =动作要素测量!A253 -> 51 | BA1: =动作要素测量!A258 -> 52 | BB1: =动作要素测量!A263 -> 53 | BC1: =动作要素测量!A268 -> 54 | BD1: =动作要素测量!A273 -> 55 | BE1: =动作要素测量!A278 -> 56 | BF1: =动作要素测量!A283 -> 57 | BG1: =动作要素测量!A288 -> 58 | BH1: =动作要素测量!A293 -> 59 | BI1: =动作要素测量!A298 -> 60 | BJ1: =动作要素测量!A303 -> 61 | BK1: =动作要素测量!A308 -> 62 | BL1: =动作要素测量!A313 -> 63 | BM1: =动作要素测量!A318 -> 64 | BN1: =动作要素测量!A323 -> 65 | BO1: =动作要素测量!A328 -> 66 | BP1: =动作要素测量!A333 -> 67 | BQ1: =动作要素测量!A338 -> 68 | BR1: =动作要素测量!A343 -> 69 | BS1: =动作要素测量!A348 -> 70 | BT1: =动作要素测量!A353 -> 71 | BU1: =动作要素测量!A358 -> 72 | BV1: =动作要素测量!A363 -> 73 | BW1: =动作要素测量!A368 -> 74 | BX1: =动作要素测量!A373 -> 75 | BY1: =动作要素测量!A378 -> 76 | BZ1: =动作要素测量!A383 -> 77 | CA1: =动作要素测量!A388 -> 78 | CB1: =动作要素测量!A393 -> 79 | CC1: =动作要素测量!A398 -> 80 | CD1: =动作要素测量!A403 -> 81 | CE1: =动作要素测量!A408 -> 82 | CF1: =动作要素测量!A413 -> 83 | CG1: =动作要素测量!A418 -> 84 | CH1: =动作要素测量!A423 -> 85 | CI1: =动作要素测量!A428 -> 86 | CJ1: =动作要素测量!A433 -> 87 | CK1: =动作要素测量!A438 -> 88 | CL1: =动作要素测量!A443 -> 89 | CM1: =动作要素测量!A448 -> 90 | CN1: =动作要素测量!A453 -> 91 | CO1: =动作要素测量!A458 -> 92 | CP1: =动作要素测量!A463 -> 93 | CQ1: =动作要素测量!A468 -> 94 | CR1: =动作要素测量!A473 -> 95 | CS1: =动作要素测量!A478 -> 96 | CT1: =动作要素测量!A483 -> 97 | CU1: =动作要素测量!A488 -> 98 | CV1: =动作要素测量!A493 -> 99 | CW1: =动作要素测量!A498 -> 100 | CX1: =动作要素测量!A503 -> 101 | CY1: =动作要素测量!A508 -> 102 | CZ1: =动作要素测量!A513 -> 103 | DA1: =动作要素测量!A518 -> 104 | DB1: =动作要素测量!A523 -> 105 | DC1: =动作要素测量!A528 -> 106 | DD1: =动作要素测量!A533 -> 107 | DE1: =动作要素测量!A538 -> 108 | DF1: =动作要素测量!A543 -> 109 | DG1: =动作要素测量!A548 -> 110 | DH1: =动作要素测量!A553 -> 111 | DI1: =动作要素测量!A558 -> 112 | DJ1: =动作要素测量!A563 -> 113 | DK1: =动作要素测量!A568 -> 114 | DL1: =动作要素测量!A573 -> 115 | DM1: =动作要素测量!A578 -> 116 | DN1: =动作要素测量!A583 -> 117 | DO1: =动作要素测量!A588 -> 118 | DP1: =动作要素测量!A593 -> 119 | DQ1: =动作要素测量!A598 -> 120 | DR1: =动作要素测量!A603 -> 121 | DS1: =动作要素测量!A608 -> 122 | DT1: =动作要素测量!A613 -> 123 | DU1: =动作要素测量!A618 -> 124 | DV1: =动作要素测量!A623 -> 125 | DW1: =动作要素测量!A628 -> 126 | DX1: =动作要素测量!A633 -> 127 | DY1: =动作要素测量!A638 -> 128 | DZ1: =动作要素测量!A643 -> 129 | EA1: =动作要素测量!A648 -> 130 | EB1: =动作要素测量!A653 -> 131 | EC1: =动作要素测量!A658 -> 132 | ED1: =动作要素测量!A663 -> 133 | EE1: =动作要素测量!A668 -> 134 | EF1: =动作要素测量!A673 -> 135 | EG1: =动作要素测量!A678 -> 136 | EH1: =动作要素测量!A683 -> 137 | EI1: =动作要素测量!A688 -> 138 | EJ1: =动作要素测量!A693 -> 139 | EK1: =动作要素测量!A698 -> 140
A2: 工序名称 | B2: =IF(动作要素测量!B3="","",动作要素测量!B3) | C2: =IF(动作要素测量!B8="","",动作要素测量!B8) | D2: =IF(动作要素测量!B13="","",动作要素测量!B13) | E2: =IF(动作要素测量!B18="","",动作要素测量!B18) | F2: =IF(动作要素测量!B23="","",动作要素测量!B23) | G2: =IF(动作要素测量!B28="","",动作要素测量!B28) | H2: =IF(动作要素测量!B33="","",动作要素测量!B33) | I2: =IF(动作要素测量!B38="","",动作要素测量!B38) | J2: =IF(动作要素测量!B43="","",动作要素测量!B43) | K2: =IF(动作要素测量!B48="","",动作要素测量!B48) | L2: =IF(动作要素测量!B53="","",动作要素测量!B53) | M2: =IF(动作要素测量!B58="","",动作要素测量!B58) | N2: =IF(动作要素测量!B63="","",动作要素测量!B63) | O2: =IF(动作要素测量!B68="","",动作要素测量!B68) | P2: =IF(动作要素测量!B73="","",动作要素测量!B73) | Q2: =IF(动作要素测量!B78="","",动作要素测量!B78) | R2: =IF(动作要素测量!B83="","",动作要素测量!B83) | S2: =IF(动作要素测量!B88="","",动作要素测量!B88) | T2: =IF(动作要素测量!B93="","",动作要素测量!B93) | U2: =IF(动作要素测量!B98="","",动作要素测量!B98) | V2: =IF(动作要素测量!B103="","",动作要素测量!B103) | W2: =IF(动作要素测量!B108="","",动作要素测量!B108) | X2: =IF(动作要素测量!B113="","",动作要素测量!B113) | Y2: =IF(动作要素测量!B118="","",动作要素测量!B118) | Z2: =IF(动作要素测量!B123="","",动作要素测量!B123) | AA2: =IF(动作要素测量!B128="","",动作要素测量!B128) | AB2: =IF(动作要素测量!B133="","",动作要素测量!B133) | AC2: =IF(动作要素测量!B138="","",动作要素测量!B138) | AD2: =IF(动作要素测量!B143="","",动作要素测量!B143) | AE2: =IF(动作要素测量!B148="","",动作要素测量!B148) | AF2: =IF(动作要素测量!B153="","",动作要素测量!B153) | AG2: =IF(动作要素测量!B158="","",动作要素测量!B158) | AH2: =IF(动作要素测量!B163="","",动作要素测量!B163) | AI2: =IF(动作要素测量!B168="","",动作要素测量!B168) | AJ2: =IF(动作要素测量!B173="","",动作要素测量!B173) | AK2: =IF(动作要素测量!B178="","",动作要素测量!B178) | AL2: =IF(动作要素测量!B183="","",动作要素测量!B183) | AM2: =IF(动作要素测量!B188="","",动作要素测量!B188) | AN2: =IF(动作要素测量!B193="","",动作要素测量!B193) | AO2: =IF(动作要素测量!B198="","",动作要素测量!B198) | AP2: =IF(动作要素测量!B203="","",动作要素测量!B203) | AQ2: =IF(动作要素测量!B208="","",动作要素测量!B208) | AR2: =IF(动作要素测量!B213="","",动作要素测量!B213) | AS2: =IF(动作要素测量!B218="","",动作要素测量!B218) | AT2: =IF(动作要素测量!B223="","",动作要素测量!B223) | AU2: =IF(动作要素测量!B228="","",动作要素测量!B228) | AV2: =IF(动作要素测量!B233="","",动作要素测量!B233) | AW2: =IF(动作要素测量!B238="","",动作要素测量!B238) | AX2: =IF(动作要素测量!B243="","",动作要素测量!B243) | AY2: =IF(动作要素测量!B248="","",动作要素测量!B248) | AZ2: =IF(动作要素测量!B253="","",动作要素测量!B253) | BA2: =IF(动作要素测量!B258="","",动作要素测量!B258) | BB2: =IF(动作要素测量!B263="","",动作要素测量!B263) | BC2: =IF(动作要素测量!B268="","",动作要素测量!B268) | BD2: =IF(动作要素测量!B273="","",动作要素测量!B273) | BE2: =IF(动作要素测量!B278="","",动作要素测量!B278) | BF2: =IF(动作要素测量!B283="","",动作要素测量!B283) | BG2: =IF(动作要素测量!B288="","",动作要素测量!B288) | BH2: =IF(动作要素测量!B293="","",动作要素测量!B293) | BI2: =IF(动作要素测量!B298="","",动作要素测量!B298) | BJ2: =IF(动作要素测量!B303="","",动作要素测量!B303) | BK2: =IF(动作要素测量!B308="","",动作要素测量!B308) | BL2: =IF(动作要素测量!B313="","",动作要素测量!B313) | BM2: =IF(动作要素测量!B318="","",动作要素测量!B318) | BN2: =IF(动作要素测量!B323="","",动作要素测量!B323) | BO2: =IF(动作要素测量!B328="","",动作要素测量!B328) | BP2: =IF(动作要素测量!B333="","",动作要素测量!B333) | BQ2: =IF(动作要素测量!B338="","",动作要素测量!B338) | BR2: =IF(动作要素测量!B343="","",动作要素测量!B343) | BS2: =IF(动作要素测量!B348="","",动作要素测量!B348) | BT2: =IF(动作要素测量!B353="","",动作要素测量!B353) | BU2: =IF(动作要素测量!B358="","",动作要素测量!B358) | BV2: =IF(动作要素测量!B363="","",动作要素测量!B363) | BW2: =IF(动作要素测量!B368="","",动作要素测量!B368) | BX2: =IF(动作要素测量!B373="","",动作要素测量!B373) | BY2: =IF(动作要素测量!B378="","",动作要素测量!B378) | BZ2: =IF(动作要素测量!B383="","",动作要素测量!B383) | CA2: =IF(动作要素测量!B388="","",动作要素测量!B388) | CB2: =IF(动作要素测量!B393="","",动作要素测量!B393) | CC2: =IF(动作要素测量!B398="","",动作要素测量!B398) | CD2: =IF(动作要素测量!B403="","",动作要素测量!B403) | CE2: =IF(动作要素测量!B408="","",动作要素测量!B408) | CF2: =IF(动作要素测量!B413="","",动作要素测量!B413) | CG2: =IF(动作要素测量!B418="","",动作要素测量!B418) | CH2: =IF(动作要素测量!B423="","",动作要素测量!B423) | CI2: =IF(动作要素测量!B428="","",动作要素测量!B428) | CJ2: =IF(动作要素测量!B433="","",动作要素测量!B433) | CK2: =IF(动作要素测量!B438="","",动作要素测量!B438) | CL2: =IF(动作要素测量!B443="","",动作要素测量!B443) | CM2: =IF(动作要素测量!B448="","",动作要素测量!B448) | CN2: =IF(动作要素测量!B453="","",动作要素测量!B453) | CO2: =IF(动作要素测量!B458="","",动作要素测量!B458) | CP2: =IF(动作要素测量!B463="","",动作要素测量!B463) | CQ2: =IF(动作要素测量!B468="","",动作要素测量!B468) | CR2: =IF(动作要素测量!B473="","",动作要素测量!B473) | CS2: =IF(动作要素测量!B478="","",动作要素测量!B478) | CT2: =IF(动作要素测量!B483="","",动作要素测量!B483) | CU2: =IF(动作要素测量!B488="","",动作要素测量!B488) | CV2: =IF(动作要素测量!B493="","",动作要素测量!B493) | CW2: =IF(动作要素测量!B498="","",动作要素测量!B498) | CX2: =IF(动作要素测量!B503="","",动作要素测量!B503) | CY2: =IF(动作要素测量!B508="","",动作要素测量!B508) | CZ2: =IF(动作要素测量!B513="","",动作要素测量!B513) | DA2: =IF(动作要素测量!B518="","",动作要素测量!B518) | DB2: =IF(动作要素测量!B523="","",动作要素测量!B523) | DC2: =IF(动作要素测量!B528="","",动作要素测量!B528) | DD2: =IF(动作要素测量!B533="","",动作要素测量!B533) | DE2: =IF(动作要素测量!B538="","",动作要素测量!B538) | DF2: =IF(动作要素测量!B543="","",动作要素测量!B543) | DG2: =IF(动作要素测量!B548="","",动作要素测量!B548) | DH2: =IF(动作要素测量!B553="","",动作要素测量!B553) | DI2: =IF(动作要素测量!B558="","",动作要素测量!B558) | DJ2: =IF(动作要素测量!B563="","",动作要素测量!B563) | DK2: =IF(动作要素测量!B568="","",动作要素测量!B568) | DL2: =IF(动作要素测量!B573="","",动作要素测量!B573) | DM2: =IF(动作要素测量!B578="","",动作要素测量!B578) | DN2: =IF(动作要素测量!B583="","",动作要素测量!B583) | DO2: =IF(动作要素测量!B588="","",动作要素测量!B588) | DP2: =IF(动作要素测量!B593="","",动作要素测量!B593) | DQ2: =IF(动作要素测量!B598="","",动作要素测量!B598) | DR2: =IF(动作要素测量!B603="","",动作要素测量!B603) | DS2: =IF(动作要素测量!B608="","",动作要素测量!B608) | DT2: =IF(动作要素测量!B613="","",动作要素测量!B613) | DU2: =IF(动作要素测量!B618="","",动作要素测量!B618) | DV2: =IF(动作要素测量!B623="","",动作要素测量!B623) | DW2: =IF(动作要素测量!B628="","",动作要素测量!B628) | DX2: =IF(动作要素测量!B633="","",动作要素测量!B633) | DY2: =IF(动作要素测量!B638="","",动作要素测量!B638) | DZ2: =IF(动作要素测量!B643="","",动作要素测量!B643) | EA2: =IF(动作要素测量!B648="","",动作要素测量!B648) | EB2: =IF(动作要素测量!B653="","",动作要素测量!B653) | EC2: =IF(动作要素测量!B658="","",动作要素测量!B658) | ED2: =IF(动作要素测量!B663="","",动作要素测量!B663) | EE2: =IF(动作要素测量!B668="","",动作要素测量!B668) | EF2: =IF(动作要素测量!B673="","",动作要素测量!B673) | EG2: =IF(动作要素测量!B678="","",动作要素测量!B678) | EH2: =IF(动作要素测量!B683="","",动作要素测量!B683) | EI2: =IF(动作要素测量!B688="","",动作要素测量!B688) | EJ2: =IF(动作要素测量!B693="","",动作要素测量!B693) | EK2: =IF(动作要素测量!B698="","",动作要素测量!B698)
A3: ST1动作 | B3: =IF(动作要素测量!D3="","",动作要素测量!D3) | C3: =IF(动作要素测量!D8="","",动作要素测量!D8) | D3: =IF(动作要素测量!D13="","",动作要素测量!D13) | E3: =IF(动作要素测量!D18="","",动作要素测量!D18) | F3: =IF(动作要素测量!D23="","",动作要素测量!D23) | G3: =IF(动作要素测量!D28="","",动作要素测量!D28) | H3: =IF(动作要素测量!D33="","",动作要素测量!D33) | I3: =IF(动作要素测量!D38="","",动作要素测量!D38) | J3: =IF(动作要素测量!D43="","",动作要素测量!D43) | K3: =IF(动作要素测量!D48="","",动作要素测量!D48) | L3: =IF(动作要素测量!D53="","",动作要素测量!D53) | M3: =IF(动作要素测量!D58="","",动作要素测量!D58) | N3: =IF(动作要素测量!D63="","",动作要素测量!D63) | O3: =IF(动作要素测量!D68="","",动作要素测量!D68) | P3: =IF(动作要素测量!D73="","",动作要素测量!D73) | Q3: =IF(动作要素测量!D78="","",动作要素测量!D78) | R3: =IF(动作要素测量!D83="","",动作要素测量!D83) | S3: =IF(动作要素测量!D88="","",动作要素测量!D88) | T3: =IF(动作要素测量!D93="","",动作要素测量!D93) | U3: =IF(动作要素测量!D98="","",动作要素测量!D98) | V3: =IF(动作要素测量!D103="","",动作要素测量!D103) | W3: =IF(动作要素测量!D108="","",动作要素测量!D108) | X3: =IF(动作要素测量!D113="","",动作要素测量!D113) | Y3: =IF(动作要素测量!D118="","",动作要素测量!D118) | Z3: =IF(动作要素测量!D123="","",动作要素测量!D123) | AA3: =IF(动作要素测量!D128="","",动作要素测量!D128) | AB3: =IF(动作要素测量!D133="","",动作要素测量!D133) | AC3: =IF(动作要素测量!D138="","",动作要素测量!D138) | AD3: =IF(动作要素测量!D143="","",动作要素测量!D143) | AE3: =IF(动作要素测量!D148="","",动作要素测量!D148) | AF3: =IF(动作要素测量!D153="","",动作要素测量!D153) | AG3: =IF(动作要素测量!D158="","",动作要素测量!D158) | AH3: =IF(动作要素测量!D163="","",动作要素测量!D163) | AI3: =IF(动作要素测量!D168="","",动作要素测量!D168) | AJ3: =IF(动作要素测量!D173="","",动作要素测量!D173) | AK3: =IF(动作要素测量!D178="","",动作要素测量!D178) | AL3: =IF(动作要素测量!D183="","",动作要素测量!D183) | AM3: =IF(动作要素测量!D188="","",动作要素测量!D188) | AN3: =IF(动作要素测量!D193="","",动作要素测量!D193) | AO3: =IF(动作要素测量!D198="","",动作要素测量!D198) | AP3: =IF(动作要素测量!D203="","",动作要素测量!D203) | AQ3: =IF(动作要素测量!D208="","",动作要素测量!D208) | AR3: =IF(动作要素测量!D213="","",动作要素测量!D213) | AS3: =IF(动作要素测量!D218="","",动作要素测量!D218) | AT3: =IF(动作要素测量!D223="","",动作要素测量!D223) | AU3: =IF(动作要素测量!D228="","",动作要素测量!D228) | AV3: =IF(动作要素测量!D233="","",动作要素测量!D233) | AW3: =IF(动作要素测量!D238="","",动作要素测量!D238) | AX3: =IF(动作要素测量!D243="","",动作要素测量!D243) | AY3: =IF(动作要素测量!D248="","",动作要素测量!D248) | AZ3: =IF(动作要素测量!D253="","",动作要素测量!D253) | BA3: =IF(动作要素测量!D258="","",动作要素测量!D258) | BB3: =IF(动作要素测量!D263="","",动作要素测量!D263) | BC3: =IF(动作要素测量!D268="","",动作要素测量!D268) | BD3: =IF(动作要素测量!D273="","",动作要素测量!D273) | BE3: =IF(动作要素测量!D278="","",动作要素测量!D278) | BF3: =IF(动作要素测量!D283="","",动作要素测量!D283) | BG3: =IF(动作要素测量!D288="","",动作要素测量!D288) | BH3: =IF(动作要素测量!D293="","",动作要素测量!D293) | BI3: =IF(动作要素测量!D298="","",动作要素测量!D298) | BJ3: =IF(动作要素测量!D303="","",动作要素测量!D303) | BK3: =IF(动作要素测量!D308="","",动作要素测量!D308) | BL3: =IF(动作要素测量!D313="","",动作要素测量!D313) | BM3: =IF(动作要素测量!D318="","",动作要素测量!D318) | BN3: =IF(动作要素测量!D323="","",动作要素测量!D323) | BO3: =IF(动作要素测量!D328="","",动作要素测量!D328) | BP3: =IF(动作要素测量!D333="","",动作要素测量!D333) | BQ3: =IF(动作要素测量!D338="","",动作要素测量!D338) | BR3: =IF(动作要素测量!D343="","",动作要素测量!D343) | BS3: =IF(动作要素测量!D348="","",动作要素测量!D348) | BT3: =IF(动作要素测量!D353="","",动作要素测量!D353) | BU3: =IF(动作要素测量!D358="","",动作要素测量!D358) | BV3: =IF(动作要素测量!D363="","",动作要素测量!D363) | BW3: =IF(动作要素测量!D368="","",动作要素测量!D368) | BX3: =IF(动作要素测量!D373="","",动作要素测量!D373) | BY3: =IF(动作要素测量!D378="","",动作要素测量!D378) | BZ3: =IF(动作要素测量!D383="","",动作要素测量!D383) | CA3: =IF(动作要素测量!D388="","",动作要素测量!D388) | CB3: =IF(动作要素测量!D393="","",动作要素测量!D393) | CC3: =IF(动作要素测量!D398="","",动作要素测量!D398) | CD3: =IF(动作要素测量!D403="","",动作要素测量!D403) | CE3: =IF(动作要素测量!D408="","",动作要素测量!D408) | CF3: =IF(动作要素测量!D413="","",动作要素测量!D413) | CG3: =IF(动作要素测量!D418="","",动作要素测量!D418) | CH3: =IF(动作要素测量!D423="","",动作要素测量!D423) | CI3: =IF(动作要素测量!D428="","",动作要素测量!D428) | CJ3: =IF(动作要素测量!D433="","",动作要素测量!D433) | CK3: =IF(动作要素测量!D438="","",动作要素测量!D438) | CL3: =IF(动作要素测量!D443="","",动作要素测量!D443) | CM3: =IF(动作要素测量!D448="","",动作要素测量!D448) | CN3: =IF(动作要素测量!D453="","",动作要素测量!D453) | CO3: =IF(动作要素测量!D458="","",动作要素测量!D458) | CP3: =IF(动作要素测量!D463="","",动作要素测量!D463) | CQ3: =IF(动作要素测量!D468="","",动作要素测量!D468) | CR3: =IF(动作要素测量!D473="","",动作要素测量!D473) | CS3: =IF(动作要素测量!D478="","",动作要素测量!D478) | CT3: =IF(动作要素测量!D483="","",动作要素测量!D483) | CU3: =IF(动作要素测量!D488="","",动作要素测量!D488) | CV3: =IF(动作要素测量!D493="","",动作要素测量!D493) | CW3: =IF(动作要素测量!D498="","",动作要素测量!D498) | CX3: =IF(动作要素测量!D503="","",动作要素测量!D503) | CY3: =IF(动作要素测量!D508="","",动作要素测量!D508) | CZ3: =IF(动作要素测量!D513="","",动作要素测量!D513) | DA3: =IF(动作要素测量!D518="","",动作要素测量!D518) | DB3: =IF(动作要素测量!D523="","",动作要素测量!D523) | DC3: =IF(动作要素测量!D528="","",动作要素测量!D528) | DD3: =IF(动作要素测量!D533="","",动作要素测量!D533) | DE3: =IF(动作要素测量!D538="","",动作要素测量!D538) | DF3: =IF(动作要素测量!D543="","",动作要素测量!D543) | DG3: =IF(动作要素测量!D548="","",动作要素测量!D548) | DH3: =IF(动作要素测量!D553="","",动作要素测量!D553) | DI3: =IF(动作要素测量!D558="","",动作要素测量!D558) | DJ3: =IF(动作要素测量!D563="","",动作要素测量!D563) | DK3: =IF(动作要素测量!D568="","",动作要素测量!D568) | DL3: =IF(动作要素测量!D573="","",动作要素测量!D573) | DM3: =IF(动作要素测量!D578="","",动作要素测量!D578) | DN3: =IF(动作要素测量!D583="","",动作要素测量!D583) | DO3: =IF(动作要素测量!D588="","",动作要素测量!D588) | DP3: =IF(动作要素测量!D593="","",动作要素测量!D593) | DQ3: =IF(动作要素测量!D598="","",动作要素测量!D598) | DR3: =IF(动作要素测量!D603="","",动作要素测量!D603) | DS3: =IF(动作要素测量!D608="","",动作要素测量!D608) | DT3: =IF(动作要素测量!D613="","",动作要素测量!D613) | DU3: =IF(动作要素测量!D618="","",动作要素测量!D618) | DV3: =IF(动作要素测量!D623="","",动作要素测量!D623) | DW3: =IF(动作要素测量!D628="","",动作要素测量!D628) | DX3: =IF(动作要素测量!D633="","",动作要素测量!D633) | DY3: =IF(动作要素测量!D638="","",动作要素测量!D638) | DZ3: =IF(动作要素测量!D643="","",动作要素测量!D643) | EA3: =IF(动作要素测量!D648="","",动作要素测量!D648) | EB3: =IF(动作要素测量!D653="","",动作要素测量!D653) | EC3: =IF(动作要素测量!D658="","",动作要素测量!D658) | ED3: =IF(动作要素测量!D663="","",动作要素测量!D663) | EE3: =IF(动作要素测量!D668="","",动作要素测量!D668) | EF3: =IF(动作要素测量!D673="","",动作要素测量!D673) | EG3: =IF(动作要素测量!D678="","",动作要素测量!D678) | EH3: =IF(动作要素测量!D683="","",动作要素测量!D683) | EI3: =IF(动作要素测量!D688="","",动作要素测量!D688) | EJ3: =IF(动作要素测量!D693="","",动作要素测量!D693) | EK3: =IF(动作要素测量!D698="","",动作要素测量!D698)
A4: ST2动作 | B4: =IF(动作要素测量!D4="","",动作要素测量!D4) | C4: =IF(动作要素测量!D9="","",动作要素测量!D9) | D4: =IF(动作要素测量!D14="","",动作要素测量!D14) | E4: =IF(动作要素测量!D19="","",动作要素测量!D19) | F4: =IF(动作要素测量!D24="","",动作要素测量!D24) | G4: =IF(动作要素测量!D29="","",动作要素测量!D29) | H4: =IF(动作要素测量!D34="","",动作要素测量!D34) | I4: =IF(动作要素测量!D39="","",动作要素测量!D39) | J4: =IF(动作要素测量!D44="","",动作要素测量!D44) | K4: =IF(动作要素测量!D49="","",动作要素测量!D49) | L4: =IF(动作要素测量!D54="","",动作要素测量!D54) | M4: =IF(动作要素测量!D59="","",动作要素测量!D59) | N4: =IF(动作要素测量!D64="","",动作要素测量!D64) | O4: =IF(动作要素测量!D69="","",动作要素测量!D69) | P4: =IF(动作要素测量!D74="","",动作要素测量!D74) | Q4: =IF(动作要素测量!D79="","",动作要素测量!D79) | R4: =IF(动作要素测量!D84="","",动作要素测量!D84) | S4: =IF(动作要素测量!D89="","",动作要素测量!D89) | T4: =IF(动作要素测量!D94="","",动作要素测量!D94) | U4: =IF(动作要素测量!D99="","",动作要素测量!D99) | V4: =IF(动作要素测量!D104="","",动作要素测量!D104) | W4: =IF(动作要素测量!D109="","",动作要素测量!D109) | X4: =IF(动作要素测量!D114="","",动作要素测量!D114) | Y4: =IF(动作要素测量!D119="","",动作要素测量!D119) | Z4: =IF(动作要素测量!D124="","",动作要素测量!D124) | AA4: =IF(动作要素测量!D129="","",动作要素测量!D129) | AB4: =IF(动作要素测量!D134="","",动作要素测量!D134) | AC4: =IF(动作要素测量!D139="","",动作要素测量!D139) | AD4: =IF(动作要素测量!D144="","",动作要素测量!D144) | AE4: =IF(动作要素测量!D149="","",动作要素测量!D149) | AF4: =IF(动作要素测量!D154="","",动作要素测量!D154) | AG4: =IF(动作要素测量!D159="","",动作要素测量!D159) | AH4: =IF(动作要素测量!D164="","",动作要素测量!D164) | AI4: =IF(动作要素测量!D169="","",动作要素测量!D169) | AJ4: =IF(动作要素测量!D174="","",动作要素测量!D174) | AK4: =IF(动作要素测量!D179="","",动作要素测量!D179) | AL4: =IF(动作要素测量!D184="","",动作要素测量!D184) | AM4: =IF(动作要素测量!D189="","",动作要素测量!D189) | AN4: =IF(动作要素测量!D194="","",动作要素测量!D194) | AO4: =IF(动作要素测量!D199="","",动作要素测量!D199) | AP4: =IF(动作要素测量!D204="","",动作要素测量!D204) | AQ4: =IF(动作要素测量!D209="","",动作要素测量!D209) | AR4: =IF(动作要素测量!D214="","",动作要素测量!D214) | AS4: =IF(动作要素测量!D219="","",动作要素测量!D219) | AT4: =IF(动作要素测量!D224="","",动作要素测量!D224) | AU4: =IF(动作要素测量!D229="","",动作要素测量!D229) | AV4: =IF(动作要素测量!D234="","",动作要素测量!D234) | AW4: =IF(动作要素测量!D239="","",动作要素测量!D239) | AX4: =IF(动作要素测量!D244="","",动作要素测量!D244) | AY4: =IF(动作要素测量!D249="","",动作要素测量!D249) | AZ4: =IF(动作要素测量!D254="","",动作要素测量!D254) | BA4: =IF(动作要素测量!D259="","",动作要素测量!D259) | BB4: =IF(动作要素测量!D264="","",动作要素测量!D264) | BC4: =IF(动作要素测量!D269="","",动作要素测量!D269) | BD4: =IF(动作要素测量!D274="","",动作要素测量!D274) | BE4: =IF(动作要素测量!D279="","",动作要素测量!D279) | BF4: =IF(动作要素测量!D284="","",动作要素测量!D284) | BG4: =IF(动作要素测量!D289="","",动作要素测量!D289) | BH4: =IF(动作要素测量!D294="","",动作要素测量!D294) | BI4: =IF(动作要素测量!D299="","",动作要素测量!D299) | BJ4: =IF(动作要素测量!D304="","",动作要素测量!D304) | BK4: =IF(动作要素测量!D309="","",动作要素测量!D309) | BL4: =IF(动作要素测量!D314="","",动作要素测量!D314) | BM4: =IF(动作要素测量!D319="","",动作要素测量!D319) | BN4: =IF(动作要素测量!D324="","",动作要素测量!D324) | BO4: =IF(动作要素测量!D329="","",动作要素测量!D329) | BP4: =IF(动作要素测量!D334="","",动作要素测量!D334) | BQ4: =IF(动作要素测量!D339="","",动作要素测量!D339) | BR4: =IF(动作要素测量!D344="","",动作要素测量!D344) | BS4: =IF(动作要素测量!D349="","",动作要素测量!D349) | BT4: =IF(动作要素测量!D354="","",动作要素测量!D354) | BU4: =IF(动作要素测量!D359="","",动作要素测量!D359) | BV4: =IF(动作要素测量!D364="","",动作要素测量!D364) | BW4: =IF(动作要素测量!D369="","",动作要素测量!D369) | BX4: =IF(动作要素测量!D374="","",动作要素测量!D374) | BY4: =IF(动作要素测量!D379="","",动作要素测量!D379) | BZ4: =IF(动作要素测量!D384="","",动作要素测量!D384) | CA4: =IF(动作要素测量!D389="","",动作要素测量!D389) | CB4: =IF(动作要素测量!D394="","",动作要素测量!D394) | CC4: =IF(动作要素测量!D399="","",动作要素测量!D399) | CD4: =IF(动作要素测量!D404="","",动作要素测量!D404) | CE4: =IF(动作要素测量!D409="","",动作要素测量!D409) | CF4: =IF(动作要素测量!D414="","",动作要素测量!D414) | CG4: =IF(动作要素测量!D419="","",动作要素测量!D419) | CH4: =IF(动作要素测量!D424="","",动作要素测量!D424) | CI4: =IF(动作要素测量!D429="","",动作要素测量!D429) | CJ4: =IF(动作要素测量!D434="","",动作要素测量!D434) | CK4: =IF(动作要素测量!D439="","",动作要素测量!D439) | CL4: =IF(动作要素测量!D444="","",动作要素测量!D444) | CM4: =IF(动作要素测量!D449="","",动作要素测量!D449) | CN4: =IF(动作要素测量!D454="","",动作要素测量!D454) | CO4: =IF(动作要素测量!D459="","",动作要素测量!D459) | CP4: =IF(动作要素测量!D464="","",动作要素测量!D464) | CQ4: =IF(动作要素测量!D469="","",动作要素测量!D469) | CR4: =IF(动作要素测量!D474="","",动作要素测量!D474) | CS4: =IF(动作要素测量!D479="","",动作要素测量!D479) | CT4: =IF(动作要素测量!D484="","",动作要素测量!D484) | CU4: =IF(动作要素测量!D489="","",动作要素测量!D489) | CV4: =IF(动作要素测量!D494="","",动作要素测量!D494) | CW4: =IF(动作要素测量!D499="","",动作要素测量!D499) | CX4: =IF(动作要素测量!D504="","",动作要素测量!D504) | CY4: =IF(动作要素测量!D509="","",动作要素测量!D509) | CZ4: =IF(动作要素测量!D514="","",动作要素测量!D514) | DA4: =IF(动作要素测量!D519="","",动作要素测量!D519) | DB4: =IF(动作要素测量!D524="","",动作要素测量!D524) | DC4: =IF(动作要素测量!D529="","",动作要素测量!D529) | DD4: =IF(动作要素测量!D534="","",动作要素测量!D534) | DE4: =IF(动作要素测量!D539="","",动作要素测量!D539) | DF4: =IF(动作要素测量!D544="","",动作要素测量!D544) | DG4: =IF(动作要素测量!D549="","",动作要素测量!D549) | DH4: =IF(动作要素测量!D554="","",动作要素测量!D554) | DI4: =IF(动作要素测量!D559="","",动作要素测量!D559) | DJ4: =IF(动作要素测量!D564="","",动作要素测量!D564) | DK4: =IF(动作要素测量!D569="","",动作要素测量!D569) | DL4: =IF(动作要素测量!D574="","",动作要素测量!D574) | DM4: =IF(动作要素测量!D579="","",动作要素测量!D579) | DN4: =IF(动作要素测量!D584="","",动作要素测量!D584) | DO4: =IF(动作要素测量!D589="","",动作要素测量!D589) | DP4: =IF(动作要素测量!D594="","",动作要素测量!D594) | DQ4: =IF(动作要素测量!D599="","",动作要素测量!D599) | DR4: =IF(动作要素测量!D604="","",动作要素测量!D604) | DS4: =IF(动作要素测量!D609="","",动作要素测量!D609) | DT4: =IF(动作要素测量!D614="","",动作要素测量!D614) | DU4: =IF(动作要素测量!D619="","",动作要素测量!D619) | DV4: =IF(动作要素测量!D624="","",动作要素测量!D624) | DW4: =IF(动作要素测量!D629="","",动作要素测量!D629) | DX4: =IF(动作要素测量!D634="","",动作要素测量!D634) | DY4: =IF(动作要素测量!D639="","",动作要素测量!D639) | DZ4: =IF(动作要素测量!D644="","",动作要素测量!D644) | EA4: =IF(动作要素测量!D649="","",动作要素测量!D649) | EB4: =IF(动作要素测量!D654="","",动作要素测量!D654) | EC4: =IF(动作要素测量!D659="","",动作要素测量!D659) | ED4: =IF(动作要素测量!D664="","",动作要素测量!D664) | EE4: =IF(动作要素测量!D669="","",动作要素测量!D669) | EF4: =IF(动作要素测量!D674="","",动作要素测量!D674) | EG4: =IF(动作要素测量!D679="","",动作要素测量!D679) | EH4: =IF(动作要素测量!D684="","",动作要素测量!D684) | EI4: =IF(动作要素测量!D689="","",动作要素测量!D689) | EJ4: =IF(动作要素测量!D694="","",动作要素测量!D694) | EK4: =IF(动作要素测量!D699="","",动作要素测量!D699)
A5: ST3动作 | B5: =IF(动作要素测量!D5="","",动作要素测量!D5) | C5: =IF(动作要素测量!D10="","",动作要素测量!D10) | D5: =IF(动作要素测量!D15="","",动作要素测量!D15) | E5: =IF(动作要素测量!D20="","",动作要素测量!D20) | F5: =IF(动作要素测量!D25="","",动作要素测量!D25) | G5: =IF(动作要素测量!D30="","",动作要素测量!D30) | H5: =IF(动作要素测量!D35="","",动作要素测量!D35) | I5: =IF(动作要素测量!D40="","",动作要素测量!D40) | J5: =IF(动作要素测量!D45="","",动作要素测量!D45) | K5: =IF(动作要素测量!D50="","",动作要素测量!D50) | L5: =IF(动作要素测量!D55="","",动作要素测量!D55) | M5: =IF(动作要素测量!D60="","",动作要素测量!D60) | N5: =IF(动作要素测量!D65="","",动作要素测量!D65) | O5: =IF(动作要素测量!D70="","",动作要素测量!D70) | P5: =IF(动作要素测量!D75="","",动作要素测量!D75) | Q5: =IF(动作要素测量!D80="","",动作要素测量!D80) | R5: =IF(动作要素测量!D85="","",动作要素测量!D85) | S5: =IF(动作要素测量!D90="","",动作要素测量!D90) | T5: =IF(动作要素测量!D95="","",动作要素测量!D95) | U5: =IF(动作要素测量!D100="","",动作要素测量!D100) | V5: =IF(动作要素测量!D105="","",动作要素测量!D105) | W5: =IF(动作要素测量!D110="","",动作要素测量!D110) | X5: =IF(动作要素测量!D115="","",动作要素测量!D115) | Y5: =IF(动作要素测量!D120="","",动作要素测量!D120) | Z5: =IF(动作要素测量!D125="","",动作要素测量!D125) | AA5: =IF(动作要素测量!D130="","",动作要素测量!D130) | AB5: =IF(动作要素测量!D135="","",动作要素测量!D135) | AC5: =IF(动作要素测量!D140="","",动作要素测量!D140) | AD5: =IF(动作要素测量!D145="","",动作要素测量!D145) | AE5: =IF(动作要素测量!D150="","",动作要素测量!D150) | AF5: =IF(动作要素测量!D155="","",动作要素测量!D155) | AG5: =IF(动作要素测量!D160="","",动作要素测量!D160) | AH5: =IF(动作要素测量!D165="","",动作要素测量!D165) | AI5: =IF(动作要素测量!D170="","",动作要素测量!D170) | AJ5: =IF(动作要素测量!D175="","",动作要素测量!D175) | AK5: =IF(动作要素测量!D180="","",动作要素测量!D180) | AL5: =IF(动作要素测量!D185="","",动作要素测量!D185) | AM5: =IF(动作要素测量!D190="","",动作要素测量!D190) | AN5: =IF(动作要素测量!D195="","",动作要素测量!D195) | AO5: =IF(动作要素测量!D200="","",动作要素测量!D200) | AP5: =IF(动作要素测量!D205="","",动作要素测量!D205) | AQ5: =IF(动作要素测量!D210="","",动作要素测量!D210) | AR5: =IF(动作要素测量!D215="","",动作要素测量!D215) | AS5: =IF(动作要素测量!D220="","",动作要素测量!D220) | AT5: =IF(动作要素测量!D225="","",动作要素测量!D225) | AU5: =IF(动作要素测量!D230="","",动作要素测量!D230) | AV5: =IF(动作要素测量!D235="","",动作要素测量!D235) | AW5: =IF(动作要素测量!D240="","",动作要素测量!D240) | AX5: =IF(动作要素测量!D245="","",动作要素测量!D245) | AY5: =IF(动作要素测量!D250="","",动作要素测量!D250) | AZ5: =IF(动作要素测量!D255="","",动作要素测量!D255) | BA5: =IF(动作要素测量!D260="","",动作要素测量!D260) | BB5: =IF(动作要素测量!D265="","",动作要素测量!D265) | BC5: =IF(动作要素测量!D270="","",动作要素测量!D270) | BD5: =IF(动作要素测量!D275="","",动作要素测量!D275) | BE5: =IF(动作要素测量!D280="","",动作要素测量!D280) | BF5: =IF(动作要素测量!D285="","",动作要素测量!D285) | BG5: =IF(动作要素测量!D290="","",动作要素测量!D290) | BH5: =IF(动作要素测量!D295="","",动作要素测量!D295) | BI5: =IF(动作要素测量!D300="","",动作要素测量!D300) | BJ5: =IF(动作要素测量!D305="","",动作要素测量!D305) | BK5: =IF(动作要素测量!D310="","",动作要素测量!D310) | BL5: =IF(动作要素测量!D315="","",动作要素测量!D315) | BM5: =IF(动作要素测量!D320="","",动作要素测量!D320) | BN5: =IF(动作要素测量!D325="","",动作要素测量!D325) | BO5: =IF(动作要素测量!D330="","",动作要素测量!D330) | BP5: =IF(动作要素测量!D335="","",动作要素测量!D335) | BQ5: =IF(动作要素测量!D340="","",动作要素测量!D340) | BR5: =IF(动作要素测量!D345="","",动作要素测量!D345) | BS5: =IF(动作要素测量!D350="","",动作要素测量!D350) | BT5: =IF(动作要素测量!D355="","",动作要素测量!D355) | BU5: =IF(动作要素测量!D360="","",动作要素测量!D360) | BV5: =IF(动作要素测量!D365="","",动作要素测量!D365) | BW5: =IF(动作要素测量!D370="","",动作要素测量!D370) | BX5: =IF(动作要素测量!D375="","",动作要素测量!D375) | BY5: =IF(动作要素测量!D380="","",动作要素测量!D380) | BZ5: =IF(动作要素测量!D385="","",动作要素测量!D385) | CA5: =IF(动作要素测量!D390="","",动作要素测量!D390) | CB5: =IF(动作要素测量!D395="","",动作要素测量!D395) | CC5: =IF(动作要素测量!D400="","",动作要素测量!D400) | CD5: =IF(动作要素测量!D405="","",动作要素测量!D405) | CE5: =IF(动作要素测量!D410="","",动作要素测量!D410) | CF5: =IF(动作要素测量!D415="","",动作要素测量!D415) | CG5: =IF(动作要素测量!D420="","",动作要素测量!D420) | CH5: =IF(动作要素测量!D425="","",动作要素测量!D425) | CI5: =IF(动作要素测量!D430="","",动作要素测量!D430) | CJ5: =IF(动作要素测量!D435="","",动作要素测量!D435) | CK5: =IF(动作要素测量!D440="","",动作要素测量!D440) | CL5: =IF(动作要素测量!D445="","",动作要素测量!D445) | CM5: =IF(动作要素测量!D450="","",动作要素测量!D450) | CN5: =IF(动作要素测量!D455="","",动作要素测量!D455) | CO5: =IF(动作要素测量!D460="","",动作要素测量!D460) | CP5: =IF(动作要素测量!D465="","",动作要素测量!D465) | CQ5: =IF(动作要素测量!D470="","",动作要素测量!D470) | CR5: =IF(动作要素测量!D475="","",动作要素测量!D475) | CS5: =IF(动作要素测量!D480="","",动作要素测量!D480) | CT5: =IF(动作要素测量!D485="","",动作要素测量!D485) | CU5: =IF(动作要素测量!D490="","",动作要素测量!D490) | CV5: =IF(动作要素测量!D495="","",动作要素测量!D495) | CW5: =IF(动作要素测量!D500="","",动作要素测量!D500) | CX5: =IF(动作要素测量!D505="","",动作要素测量!D505) | CY5: =IF(动作要素测量!D510="","",动作要素测量!D510) | CZ5: =IF(动作要素测量!D515="","",动作要素测量!D515) | DA5: =IF(动作要素测量!D520="","",动作要素测量!D520) | DB5: =IF(动作要素测量!D525="","",动作要素测量!D525) | DC5: =IF(动作要素测量!D530="","",动作要素测量!D530) | DD5: =IF(动作要素测量!D535="","",动作要素测量!D535) | DE5: =IF(动作要素测量!D540="","",动作要素测量!D540) | DF5: =IF(动作要素测量!D545="","",动作要素测量!D545) | DG5: =IF(动作要素测量!D550="","",动作要素测量!D550) | DH5: =IF(动作要素测量!D555="","",动作要素测量!D555) | DI5: =IF(动作要素测量!D560="","",动作要素测量!D560) | DJ5: =IF(动作要素测量!D565="","",动作要素测量!D565) | DK5: =IF(动作要素测量!D570="","",动作要素测量!D570) | DL5: =IF(动作要素测量!D575="","",动作要素测量!D575) | DM5: =IF(动作要素测量!D580="","",动作要素测量!D580) | DN5: =IF(动作要素测量!D585="","",动作要素测量!D585) | DO5: =IF(动作要素测量!D590="","",动作要素测量!D590) | DP5: =IF(动作要素测量!D595="","",动作要素测量!D595) | DQ5: =IF(动作要素测量!D600="","",动作要素测量!D600) | DR5: =IF(动作要素测量!D605="","",动作要素测量!D605) | DS5: =IF(动作要素测量!D610="","",动作要素测量!D610) | DT5: =IF(动作要素测量!D615="","",动作要素测量!D615) | DU5: =IF(动作要素测量!D620="","",动作要素测量!D620) | DV5: =IF(动作要素测量!D625="","",动作要素测量!D625) | DW5: =IF(动作要素测量!D630="","",动作要素测量!D630) | DX5: =IF(动作要素测量!D635="","",动作要素测量!D635) | DY5: =IF(动作要素测量!D640="","",动作要素测量!D640) | DZ5: =IF(动作要素测量!D645="","",动作要素测量!D645) | EA5: =IF(动作要素测量!D650="","",动作要素测量!D650) | EB5: =IF(动作要素测量!D655="","",动作要素测量!D655) | EC5: =IF(动作要素测量!D660="","",动作要素测量!D660) | ED5: =IF(动作要素测量!D665="","",动作要素测量!D665) | EE5: =IF(动作要素测量!D670="","",动作要素测量!D670) | EF5: =IF(动作要素测量!D675="","",动作要素测量!D675) | EG5: =IF(动作要素测量!D680="","",动作要素测量!D680) | EH5: =IF(动作要素测量!D685="","",动作要素测量!D685) | EI5: =IF(动作要素测量!D690="","",动作要素测量!D690) | EJ5: =IF(动作要素测量!D695="","",动作要素测量!D695) | EK5: =IF(动作要素测量!D700="","",动作要素测量!D700)
A6: ST4动作 | B6: =IF(动作要素测量!D6="","",动作要素测量!D6) | C6: =IF(动作要素测量!D11="","",动作要素测量!D11) | D6: =IF(动作要素测量!D16="","",动作要素测量!D16) | E6: =IF(动作要素测量!D21="","",动作要素测量!D21) | F6: =IF(动作要素测量!D26="","",动作要素测量!D26) | G6: =IF(动作要素测量!D31="","",动作要素测量!D31) | H6: =IF(动作要素测量!D36="","",动作要素测量!D36) | I6: =IF(动作要素测量!D41="","",动作要素测量!D41) | J6: =IF(动作要素测量!D46="","",动作要素测量!D46) | K6: =IF(动作要素测量!D51="","",动作要素测量!D51) | L6: =IF(动作要素测量!D56="","",动作要素测量!D56) | M6: =IF(动作要素测量!D61="","",动作要素测量!D61) | N6: =IF(动作要素测量!D66="","",动作要素测量!D66) | O6: =IF(动作要素测量!D71="","",动作要素测量!D71) | P6: =IF(动作要素测量!D76="","",动作要素测量!D76) | Q6: =IF(动作要素测量!D81="","",动作要素测量!D81) | R6: =IF(动作要素测量!D86="","",动作要素测量!D86) | S6: =IF(动作要素测量!D91="","",动作要素测量!D91) | T6: =IF(动作要素测量!D96="","",动作要素测量!D96) | U6: =IF(动作要素测量!D101="","",动作要素测量!D101) | V6: =IF(动作要素测量!D106="","",动作要素测量!D106) | W6: =IF(动作要素测量!D111="","",动作要素测量!D111) | X6: =IF(动作要素测量!D116="","",动作要素测量!D116) | Y6: =IF(动作要素测量!D121="","",动作要素测量!D121) | Z6: =IF(动作要素测量!D126="","",动作要素测量!D126) | AA6: =IF(动作要素测量!D131="","",动作要素测量!D131) | AB6: =IF(动作要素测量!D136="","",动作要素测量!D136) | AC6: =IF(动作要素测量!D141="","",动作要素测量!D141) | AD6: =IF(动作要素测量!D146="","",动作要素测量!D146) | AE6: =IF(动作要素测量!D151="","",动作要素测量!D151) | AF6: =IF(动作要素测量!D156="","",动作要素测量!D156) | AG6: =IF(动作要素测量!D161="","",动作要素测量!D161) | AH6: =IF(动作要素测量!D166="","",动作要素测量!D166) | AI6: =IF(动作要素测量!D171="","",动作要素测量!D171) | AJ6: =IF(动作要素测量!D176="","",动作要素测量!D176) | AK6: =IF(动作要素测量!D181="","",动作要素测量!D181) | AL6: =IF(动作要素测量!D186="","",动作要素测量!D186) | AM6: =IF(动作要素测量!D191="","",动作要素测量!D191) | AN6: =IF(动作要素测量!D196="","",动作要素测量!D196) | AO6: =IF(动作要素测量!D201="","",动作要素测量!D201) | AP6: =IF(动作要素测量!D206="","",动作要素测量!D206) | AQ6: =IF(动作要素测量!D211="","",动作要素测量!D211) | AR6: =IF(动作要素测量!D216="","",动作要素测量!D216) | AS6: =IF(动作要素测量!D221="","",动作要素测量!D221) | AT6: =IF(动作要素测量!D226="","",动作要素测量!D226) | AU6: =IF(动作要素测量!D231="","",动作要素测量!D231) | AV6: =IF(动作要素测量!D236="","",动作要素测量!D236) | AW6: =IF(动作要素测量!D241="","",动作要素测量!D241) | AX6: =IF(动作要素测量!D246="","",动作要素测量!D246) | AY6: =IF(动作要素测量!D251="","",动作要素测量!D251) | AZ6: =IF(动作要素测量!D256="","",动作要素测量!D256) | BA6: =IF(动作要素测量!D261="","",动作要素测量!D261) | BB6: =IF(动作要素测量!D266="","",动作要素测量!D266) | BC6: =IF(动作要素测量!D271="","",动作要素测量!D271) | BD6: =IF(动作要素测量!D276="","",动作要素测量!D276) | BE6: =IF(动作要素测量!D281="","",动作要素测量!D281) | BF6: =IF(动作要素测量!D286="","",动作要素测量!D286) | BG6: =IF(动作要素测量!D291="","",动作要素测量!D291) | BH6: =IF(动作要素测量!D296="","",动作要素测量!D296) | BI6: =IF(动作要素测量!D301="","",动作要素测量!D301) | BJ6: =IF(动作要素测量!D306="","",动作要素测量!D306) | BK6: =IF(动作要素测量!D311="","",动作要素测量!D311) | BL6: =IF(动作要素测量!D316="","",动作要素测量!D316) | BM6: =IF(动作要素测量!D321="","",动作要素测量!D321) | BN6: =IF(动作要素测量!D326="","",动作要素测量!D326) | BO6: =IF(动作要素测量!D331="","",动作要素测量!D331) | BP6: =IF(动作要素测量!D336="","",动作要素测量!D336) | BQ6: =IF(动作要素测量!D341="","",动作要素测量!D341) | BR6: =IF(动作要素测量!D346="","",动作要素测量!D346) | BS6: =IF(动作要素测量!D351="","",动作要素测量!D351) | BT6: =IF(动作要素测量!D356="","",动作要素测量!D356) | BU6: =IF(动作要素测量!D361="","",动作要素测量!D361) | BV6: =IF(动作要素测量!D366="","",动作要素测量!D366) | BW6: =IF(动作要素测量!D371="","",动作要素测量!D371) | BX6: =IF(动作要素测量!D376="","",动作要素测量!D376) | BY6: =IF(动作要素测量!D381="","",动作要素测量!D381) | BZ6: =IF(动作要素测量!D386="","",动作要素测量!D386) | CA6: =IF(动作要素测量!D391="","",动作要素测量!D391) | CB6: =IF(动作要素测量!D396="","",动作要素测量!D396) | CC6: =IF(动作要素测量!D401="","",动作要素测量!D401) | CD6: =IF(动作要素测量!D406="","",动作要素测量!D406) | CE6: =IF(动作要素测量!D411="","",动作要素测量!D411) | CF6: =IF(动作要素测量!D416="","",动作要素测量!D416) | CG6: =IF(动作要素测量!D421="","",动作要素测量!D421) | CH6: =IF(动作要素测量!D426="","",动作要素测量!D426) | CI6: =IF(动作要素测量!D431="","",动作要素测量!D431) | CJ6: =IF(动作要素测量!D436="","",动作要素测量!D436) | CK6: =IF(动作要素测量!D441="","",动作要素测量!D441) | CL6: =IF(动作要素测量!D446="","",动作要素测量!D446) | CM6: =IF(动作要素测量!D451="","",动作要素测量!D451) | CN6: =IF(动作要素测量!D456="","",动作要素测量!D456) | CO6: =IF(动作要素测量!D461="","",动作要素测量!D461) | CP6: =IF(动作要素测量!D466="","",动作要素测量!D466) | CQ6: =IF(动作要素测量!D471="","",动作要素测量!D471) | CR6: =IF(动作要素测量!D476="","",动作要素测量!D476) | CS6: =IF(动作要素测量!D481="","",动作要素测量!D481) | CT6: =IF(动作要素测量!D486="","",动作要素测量!D486) | CU6: =IF(动作要素测量!D491="","",动作要素测量!D491) | CV6: =IF(动作要素测量!D496="","",动作要素测量!D496) | CW6: =IF(动作要素测量!D501="","",动作要素测量!D501) | CX6: =IF(动作要素测量!D506="","",动作要素测量!D506) | CY6: =IF(动作要素测量!D511="","",动作要素测量!D511) | CZ6: =IF(动作要素测量!D516="","",动作要素测量!D516) | DA6: =IF(动作要素测量!D521="","",动作要素测量!D521) | DB6: =IF(动作要素测量!D526="","",动作要素测量!D526) | DC6: =IF(动作要素测量!D531="","",动作要素测量!D531) | DD6: =IF(动作要素测量!D536="","",动作要素测量!D536) | DE6: =IF(动作要素测量!D541="","",动作要素测量!D541) | DF6: =IF(动作要素测量!D546="","",动作要素测量!D546) | DG6: =IF(动作要素测量!D551="","",动作要素测量!D551) | DH6: =IF(动作要素测量!D556="","",动作要素测量!D556) | DI6: =IF(动作要素测量!D561="","",动作要素测量!D561) | DJ6: =IF(动作要素测量!D566="","",动作要素测量!D566) | DK6: =IF(动作要素测量!D571="","",动作要素测量!D571) | DL6: =IF(动作要素测量!D576="","",动作要素测量!D576) | DM6: =IF(动作要素测量!D581="","",动作要素测量!D581) | DN6: =IF(动作要素测量!D586="","",动作要素测量!D586) | DO6: =IF(动作要素测量!D591="","",动作要素测量!D591) | DP6: =IF(动作要素测量!D596="","",动作要素测量!D596) | DQ6: =IF(动作要素测量!D601="","",动作要素测量!D601) | DR6: =IF(动作要素测量!D606="","",动作要素测量!D606) | DS6: =IF(动作要素测量!D611="","",动作要素测量!D611) | DT6: =IF(动作要素测量!D616="","",动作要素测量!D616) | DU6: =IF(动作要素测量!D621="","",动作要素测量!D621) | DV6: =IF(动作要素测量!D626="","",动作要素测量!D626) | DW6: =IF(动作要素测量!D631="","",动作要素测量!D631) | DX6: =IF(动作要素测量!D636="","",动作要素测量!D636) | DY6: =IF(动作要素测量!D641="","",动作要素测量!D641) | DZ6: =IF(动作要素测量!D646="","",动作要素测量!D646) | EA6: =IF(动作要素测量!D651="","",动作要素测量!D651) | EB6: =IF(动作要素测量!D656="","",动作要素测量!D656) | EC6: =IF(动作要素测量!D661="","",动作要素测量!D661) | ED6: =IF(动作要素测量!D666="","",动作要素测量!D666) | EE6: =IF(动作要素测量!D671="","",动作要素测量!D671) | EF6: =IF(动作要素测量!D676="","",动作要素测量!D676) | EG6: =IF(动作要素测量!D681="","",动作要素测量!D681) | EH6: =IF(动作要素测量!D686="","",动作要素测量!D686) | EI6: =IF(动作要素测量!D691="","",动作要素测量!D691) | EJ6: =IF(动作要素测量!D696="","",动作要素测量!D696) | EK6: =IF(动作要素测量!D701="","",动作要素测量!D701)
A7: ST5动作 | B7: =IF(动作要素测量!D7="","",动作要素测量!D7) | C7: =IF(动作要素测量!D12="","",动作要素测量!D12) | D7: =IF(动作要素测量!D17="","",动作要素测量!D17) | E7: =IF(动作要素测量!D22="","",动作要素测量!D22) | F7: =IF(动作要素测量!D27="","",动作要素测量!D27) | G7: =IF(动作要素测量!D32="","",动作要素测量!D32) | H7: =IF(动作要素测量!D37="","",动作要素测量!D37) | I7: =IF(动作要素测量!D42="","",动作要素测量!D42) | J7: =IF(动作要素测量!D47="","",动作要素测量!D47) | K7: =IF(动作要素测量!D52="","",动作要素测量!D52) | L7: =IF(动作要素测量!D57="","",动作要素测量!D57) | M7: =IF(动作要素测量!D62="","",动作要素测量!D62) | N7: =IF(动作要素测量!D67="","",动作要素测量!D67) | O7: =IF(动作要素测量!D72="","",动作要素测量!D72) | P7: =IF(动作要素测量!D77="","",动作要素测量!D77) | Q7: =IF(动作要素测量!D82="","",动作要素测量!D82) | R7: =IF(动作要素测量!D87="","",动作要素测量!D87) | S7: =IF(动作要素测量!D92="","",动作要素测量!D92) | T7: =IF(动作要素测量!D97="","",动作要素测量!D97) | U7: =IF(动作要素测量!D102="","",动作要素测量!D102) | V7: =IF(动作要素测量!D107="","",动作要素测量!D107) | W7: =IF(动作要素测量!D112="","",动作要素测量!D112) | X7: =IF(动作要素测量!D117="","",动作要素测量!D117) | Y7: =IF(动作要素测量!D122="","",动作要素测量!D122) | Z7: =IF(动作要素测量!D127="","",动作要素测量!D127) | AA7: =IF(动作要素测量!D132="","",动作要素测量!D132) | AB7: =IF(动作要素测量!D137="","",动作要素测量!D137) | AC7: =IF(动作要素测量!D142="","",动作要素测量!D142) | AD7: =IF(动作要素测量!D147="","",动作要素测量!D147) | AE7: =IF(动作要素测量!D152="","",动作要素测量!D152) | AF7: =IF(动作要素测量!D157="","",动作要素测量!D157) | AG7: =IF(动作要素测量!D162="","",动作要素测量!D162) | AH7: =IF(动作要素测量!D167="","",动作要素测量!D167) | AI7: =IF(动作要素测量!D172="","",动作要素测量!D172) | AJ7: =IF(动作要素测量!D177="","",动作要素测量!D177) | AK7: =IF(动作要素测量!D182="","",动作要素测量!D182) | AL7: =IF(动作要素测量!D187="","",动作要素测量!D187) | AM7: =IF(动作要素测量!D192="","",动作要素测量!D192) | AN7: =IF(动作要素测量!D197="","",动作要素测量!D197) | AO7: =IF(动作要素测量!D202="","",动作要素测量!D202) | AP7: =IF(动作要素测量!D207="","",动作要素测量!D207) | AQ7: =IF(动作要素测量!D212="","",动作要素测量!D212) | AR7: =IF(动作要素测量!D217="","",动作要素测量!D217) | AS7: =IF(动作要素测量!D222="","",动作要素测量!D222) | AT7: =IF(动作要素测量!D227="","",动作要素测量!D227) | AU7: =IF(动作要素测量!D232="","",动作要素测量!D232) | AV7: =IF(动作要素测量!D237="","",动作要素测量!D237) | AW7: =IF(动作要素测量!D242="","",动作要素测量!D242) | AX7: =IF(动作要素测量!D247="","",动作要素测量!D247) | AY7: =IF(动作要素测量!D252="","",动作要素测量!D252) | AZ7: =IF(动作要素测量!D257="","",动作要素测量!D257) | BA7: =IF(动作要素测量!D262="","",动作要素测量!D262) | BB7: =IF(动作要素测量!D267="","",动作要素测量!D267) | BC7: =IF(动作要素测量!D272="","",动作要素测量!D272) | BD7: =IF(动作要素测量!D277="","",动作要素测量!D277) | BE7: =IF(动作要素测量!D282="","",动作要素测量!D282) | BF7: =IF(动作要素测量!D287="","",动作要素测量!D287) | BG7: =IF(动作要素测量!D292="","",动作要素测量!D292) | BH7: =IF(动作要素测量!D297="","",动作要素测量!D297) | BI7: =IF(动作要素测量!D302="","",动作要素测量!D302) | BJ7: =IF(动作要素测量!D307="","",动作要素测量!D307) | BK7: =IF(动作要素测量!D312="","",动作要素测量!D312) | BL7: =IF(动作要素测量!D317="","",动作要素测量!D317) | BM7: =IF(动作要素测量!D322="","",动作要素测量!D322) | BN7: =IF(动作要素测量!D327="","",动作要素测量!D327) | BO7: =IF(动作要素测量!D332="","",动作要素测量!D332) | BP7: =IF(动作要素测量!D337="","",动作要素测量!D337) | BQ7: =IF(动作要素测量!D342="","",动作要素测量!D342) | BR7: =IF(动作要素测量!D347="","",动作要素测量!D347) | BS7: =IF(动作要素测量!D352="","",动作要素测量!D352) | BT7: =IF(动作要素测量!D357="","",动作要素测量!D357) | BU7: =IF(动作要素测量!D362="","",动作要素测量!D362) | BV7: =IF(动作要素测量!D367="","",动作要素测量!D367) | BW7: =IF(动作要素测量!D372="","",动作要素测量!D372) | BX7: =IF(动作要素测量!D377="","",动作要素测量!D377) | BY7: =IF(动作要素测量!D382="","",动作要素测量!D382) | BZ7: =IF(动作要素测量!D387="","",动作要素测量!D387) | CA7: =IF(动作要素测量!D392="","",动作要素测量!D392) | CB7: =IF(动作要素测量!D397="","",动作要素测量!D397) | CC7: =IF(动作要素测量!D402="","",动作要素测量!D402) | CD7: =IF(动作要素测量!D407="","",动作要素测量!D407) | CE7: =IF(动作要素测量!D412="","",动作要素测量!D412) | CF7: =IF(动作要素测量!D417="","",动作要素测量!D417) | CG7: =IF(动作要素测量!D422="","",动作要素测量!D422) | CH7: =IF(动作要素测量!D427="","",动作要素测量!D427) | CI7: =IF(动作要素测量!D432="","",动作要素测量!D432) | CJ7: =IF(动作要素测量!D437="","",动作要素测量!D437) | CK7: =IF(动作要素测量!D442="","",动作要素测量!D442) | CL7: =IF(动作要素测量!D447="","",动作要素测量!D447) | CM7: =IF(动作要素测量!D452="","",动作要素测量!D452) | CN7: =IF(动作要素测量!D457="","",动作要素测量!D457) | CO7: =IF(动作要素测量!D462="","",动作要素测量!D462) | CP7: =IF(动作要素测量!D467="","",动作要素测量!D467) | CQ7: =IF(动作要素测量!D472="","",动作要素测量!D472) | CR7: =IF(动作要素测量!D477="","",动作要素测量!D477) | CS7: =IF(动作要素测量!D482="","",动作要素测量!D482) | CT7: =IF(动作要素测量!D487="","",动作要素测量!D487) | CU7: =IF(动作要素测量!D492="","",动作要素测量!D492) | CV7: =IF(动作要素测量!D497="","",动作要素测量!D497) | CW7: =IF(动作要素测量!D502="","",动作要素测量!D502) | CX7: =IF(动作要素测量!D507="","",动作要素测量!D507) | CY7: =IF(动作要素测量!D512="","",动作要素测量!D512) | CZ7: =IF(动作要素测量!D517="","",动作要素测量!D517) | DA7: =IF(动作要素测量!D522="","",动作要素测量!D522) | DB7: =IF(动作要素测量!D527="","",动作要素测量!D527) | DC7: =IF(动作要素测量!D532="","",动作要素测量!D532) | DD7: =IF(动作要素测量!D537="","",动作要素测量!D537) | DE7: =IF(动作要素测量!D542="","",动作要素测量!D542) | DF7: =IF(动作要素测量!D547="","",动作要素测量!D547) | DG7: =IF(动作要素测量!D552="","",动作要素测量!D552) | DH7: =IF(动作要素测量!D557="","",动作要素测量!D557) | DI7: =IF(动作要素测量!D562="","",动作要素测量!D562) | DJ7: =IF(动作要素测量!D567="","",动作要素测量!D567) | DK7: =IF(动作要素测量!D572="","",动作要素测量!D572) | DL7: =IF(动作要素测量!D577="","",动作要素测量!D577) | DM7: =IF(动作要素测量!D582="","",动作要素测量!D582) | DN7: =IF(动作要素测量!D587="","",动作要素测量!D587) | DO7: =IF(动作要素测量!D592="","",动作要素测量!D592) | DP7: =IF(动作要素测量!D597="","",动作要素测量!D597) | DQ7: =IF(动作要素测量!D602="","",动作要素测量!D602) | DR7: =IF(动作要素测量!D607="","",动作要素测量!D607) | DS7: =IF(动作要素测量!D612="","",动作要素测量!D612) | DT7: =IF(动作要素测量!D617="","",动作要素测量!D617) | DU7: =IF(动作要素测量!D622="","",动作要素测量!D622) | DV7: =IF(动作要素测量!D627="","",动作要素测量!D627) | DW7: =IF(动作要素测量!D632="","",动作要素测量!D632) | DX7: =IF(动作要素测量!D637="","",动作要素测量!D637) | DY7: =IF(动作要素测量!D642="","",动作要素测量!D642) | DZ7: =IF(动作要素测量!D647="","",动作要素测量!D647) | EA7: =IF(动作要素测量!D652="","",动作要素测量!D652) | EB7: =IF(动作要素测量!D657="","",动作要素测量!D657) | EC7: =IF(动作要素测量!D662="","",动作要素测量!D662) | ED7: =IF(动作要素测量!D667="","",动作要素测量!D667) | EE7: =IF(动作要素测量!D672="","",动作要素测量!D672) | EF7: =IF(动作要素测量!D677="","",动作要素测量!D677) | EG7: =IF(动作要素测量!D682="","",动作要素测量!D682) | EH7: =IF(动作要素测量!D687="","",动作要素测量!D687) | EI7: =IF(动作要素测量!D692="","",动作要素测量!D692) | EJ7: =IF(动作要素测量!D697="","",动作要素测量!D697) | EK7: =IF(动作要素测量!D702="","",动作要素测量!D702)
A8: ST1时间 | B8: =IF(动作要素测量!J3="","",动作要素测量!J3) | C8: =IF(动作要素测量!J8="","",动作要素测量!J8) | D8: =IF(动作要素测量!J13="","",动作要素测量!J13) | E8: =IF(动作要素测量!J18="","",动作要素测量!J18) | F8: =IF(动作要素测量!J23="","",动作要素测量!J23) | G8: =IF(动作要素测量!J28="","",动作要素测量!J28) | H8: =IF(动作要素测量!J33="","",动作要素测量!J33) | I8: =IF(动作要素测量!J38="","",动作要素测量!J38) | J8: =IF(动作要素测量!J43="","",动作要素测量!J43) | K8: =IF(动作要素测量!J48="","",动作要素测量!J48) | L8: =IF(动作要素测量!J53="","",动作要素测量!J53) | M8: =IF(动作要素测量!J58="","",动作要素测量!J58) | N8: =IF(动作要素测量!J63="","",动作要素测量!J63) | O8: =IF(动作要素测量!J68="","",动作要素测量!J68) | P8: =IF(动作要素测量!J73="","",动作要素测量!J73) | Q8: =IF(动作要素测量!J78="","",动作要素测量!J78) | R8: =IF(动作要素测量!J83="","",动作要素测量!J83) | S8: =IF(动作要素测量!J88="","",动作要素测量!J88) | T8: =IF(动作要素测量!J93="","",动作要素测量!J93) | U8: =IF(动作要素测量!J98="","",动作要素测量!J98) | V8: =IF(动作要素测量!J103="","",动作要素测量!J103) | W8: =IF(动作要素测量!J108="","",动作要素测量!J108) | X8: =IF(动作要素测量!J113="","",动作要素测量!J113) | Y8: =IF(动作要素测量!J118="","",动作要素测量!J118) | Z8: =IF(动作要素测量!J123="","",动作要素测量!J123) | AA8: =IF(动作要素测量!J128="","",动作要素测量!J128) | AB8: =IF(动作要素测量!J133="","",动作要素测量!J133) | AC8: =IF(动作要素测量!J138="","",动作要素测量!J138) | AD8: =IF(动作要素测量!J143="","",动作要素测量!J143) | AE8: =IF(动作要素测量!J148="","",动作要素测量!J148) | AF8: =IF(动作要素测量!J153="","",动作要素测量!J153) | AG8: =IF(动作要素测量!J158="","",动作要素测量!J158) | AH8: =IF(动作要素测量!J163="","",动作要素测量!J163) | AI8: =IF(动作要素测量!J168="","",动作要素测量!J168) | AJ8: =IF(动作要素测量!J173="","",动作要素测量!J173) | AK8: =IF(动作要素测量!J178="","",动作要素测量!J178) | AL8: =IF(动作要素测量!J183="","",动作要素测量!J183) | AM8: =IF(动作要素测量!J188="","",动作要素测量!J188) | AN8: =IF(动作要素测量!J193="","",动作要素测量!J193) | AO8: =IF(动作要素测量!J198="","",动作要素测量!J198) | AP8: =IF(动作要素测量!J203="","",动作要素测量!J203) | AQ8: =IF(动作要素测量!J208="","",动作要素测量!J208) | AR8: =IF(动作要素测量!J213="","",动作要素测量!J213) | AS8: =IF(动作要素测量!J218="","",动作要素测量!J218) | AT8: =IF(动作要素测量!J223="","",动作要素测量!J223) | AU8: =IF(动作要素测量!J228="","",动作要素测量!J228) | AV8: =IF(动作要素测量!J233="","",动作要素测量!J233) | AW8: =IF(动作要素测量!J238="","",动作要素测量!J238) | AX8: =IF(动作要素测量!J243="","",动作要素测量!J243) | AY8: =IF(动作要素测量!J248="","",动作要素测量!J248) | AZ8: =IF(动作要素测量!J253="","",动作要素测量!J253) | BA8: =IF(动作要素测量!J258="","",动作要素测量!J258) | BB8: =IF(动作要素测量!J263="","",动作要素测量!J263) | BC8: =IF(动作要素测量!J268="","",动作要素测量!J268) | BD8: =IF(动作要素测量!J273="","",动作要素测量!J273) | BE8: =IF(动作要素测量!J278="","",动作要素测量!J278) | BF8: =IF(动作要素测量!J283="","",动作要素测量!J283) | BG8: =IF(动作要素测量!J288="","",动作要素测量!J288) | BH8: =IF(动作要素测量!J293="","",动作要素测量!J293) | BI8: =IF(动作要素测量!J298="","",动作要素测量!J298) | BJ8: =IF(动作要素测量!J303="","",动作要素测量!J303) | BK8: =IF(动作要素测量!J308="","",动作要素测量!J308) | BL8: =IF(动作要素测量!J313="","",动作要素测量!J313) | BM8: =IF(动作要素测量!J318="","",动作要素测量!J318) | BN8: =IF(动作要素测量!J323="","",动作要素测量!J323) | BO8: =IF(动作要素测量!J328="","",动作要素测量!J328) | BP8: =IF(动作要素测量!J333="","",动作要素测量!J333) | BQ8: =IF(动作要素测量!J338="","",动作要素测量!J338) | BR8: =IF(动作要素测量!J343="","",动作要素测量!J343) | BS8: =IF(动作要素测量!J348="","",动作要素测量!J348) | BT8: =IF(动作要素测量!J353="","",动作要素测量!J353) | BU8: =IF(动作要素测量!J358="","",动作要素测量!J358) | BV8: =IF(动作要素测量!J363="","",动作要素测量!J363) | BW8: =IF(动作要素测量!J368="","",动作要素测量!J368) | BX8: =IF(动作要素测量!J373="","",动作要素测量!J373) | BY8: =IF(动作要素测量!J378="","",动作要素测量!J378) | BZ8: =IF(动作要素测量!J383="","",动作要素测量!J383) | CA8: =IF(动作要素测量!J388="","",动作要素测量!J388) | CB8: =IF(动作要素测量!J393="","",动作要素测量!J393) | CC8: =IF(动作要素测量!J398="","",动作要素测量!J398) | CD8: =IF(动作要素测量!J403="","",动作要素测量!J403) | CE8: =IF(动作要素测量!J408="","",动作要素测量!J408) | CF8: =IF(动作要素测量!J413="","",动作要素测量!J413) | CG8: =IF(动作要素测量!J418="","",动作要素测量!J418) | CH8: =IF(动作要素测量!J423="","",动作要素测量!J423) | CI8: =IF(动作要素测量!J428="","",动作要素测量!J428) | CJ8: =IF(动作要素测量!J433="","",动作要素测量!J433) | CK8: =IF(动作要素测量!J438="","",动作要素测量!J438) | CL8: =IF(动作要素测量!J443="","",动作要素测量!J443) | CM8: =IF(动作要素测量!J448="","",动作要素测量!J448) | CN8: =IF(动作要素测量!J453="","",动作要素测量!J453) | CO8: =IF(动作要素测量!J458="","",动作要素测量!J458) | CP8: =IF(动作要素测量!J463="","",动作要素测量!J463) | CQ8: =IF(动作要素测量!J468="","",动作要素测量!J468) | CR8: =IF(动作要素测量!J473="","",动作要素测量!J473) | CS8: =IF(动作要素测量!J478="","",动作要素测量!J478) | CT8: =IF(动作要素测量!J483="","",动作要素测量!J483) | CU8: =IF(动作要素测量!J488="","",动作要素测量!J488) | CV8: =IF(动作要素测量!J493="","",动作要素测量!J493) | CW8: =IF(动作要素测量!J498="","",动作要素测量!J498) | CX8: =IF(动作要素测量!J503="","",动作要素测量!J503) | CY8: =IF(动作要素测量!J508="","",动作要素测量!J508) | CZ8: =IF(动作要素测量!J513="","",动作要素测量!J513) | DA8: =IF(动作要素测量!J518="","",动作要素测量!J518) | DB8: =IF(动作要素测量!J523="","",动作要素测量!J523) | DC8: =IF(动作要素测量!J528="","",动作要素测量!J528) | DD8: =IF(动作要素测量!J533="","",动作要素测量!J533) | DE8: =IF(动作要素测量!J538="","",动作要素测量!J538) | DF8: =IF(动作要素测量!J543="","",动作要素测量!J543) | DG8: =IF(动作要素测量!J548="","",动作要素测量!J548) | DH8: =IF(动作要素测量!J553="","",动作要素测量!J553) | DI8: =IF(动作要素测量!J558="","",动作要素测量!J558) | DJ8: =IF(动作要素测量!J563="","",动作要素测量!J563) | DK8: =IF(动作要素测量!J568="","",动作要素测量!J568) | DL8: =IF(动作要素测量!J573="","",动作要素测量!J573) | DM8: =IF(动作要素测量!J578="","",动作要素测量!J578) | DN8: =IF(动作要素测量!J583="","",动作要素测量!J583) | DO8: =IF(动作要素测量!J588="","",动作要素测量!J588) | DP8: =IF(动作要素测量!J593="","",动作要素测量!J593) | DQ8: =IF(动作要素测量!J598="","",动作要素测量!J598) | DR8: =IF(动作要素测量!J603="","",动作要素测量!J603) | DS8: =IF(动作要素测量!J608="","",动作要素测量!J608) | DT8: =IF(动作要素测量!J613="","",动作要素测量!J613) | DU8: =IF(动作要素测量!J618="","",动作要素测量!J618) | DV8: =IF(动作要素测量!J623="","",动作要素测量!J623) | DW8: =IF(动作要素测量!J628="","",动作要素测量!J628) | DX8: =IF(动作要素测量!J633="","",动作要素测量!J633) | DY8: =IF(动作要素测量!J638="","",动作要素测量!J638) | DZ8: =IF(动作要素测量!J643="","",动作要素测量!J643) | EA8: =IF(动作要素测量!J648="","",动作要素测量!J648) | EB8: =IF(动作要素测量!J653="","",动作要素测量!J653) | EC8: =IF(动作要素测量!J658="","",动作要素测量!J658) | ED8: =IF(动作要素测量!J663="","",动作要素测量!J663) | EE8: =IF(动作要素测量!J668="","",动作要素测量!J668) | EF8: =IF(动作要素测量!J673="","",动作要素测量!J673) | EG8: =IF(动作要素测量!J678="","",动作要素测量!J678) | EH8: =IF(动作要素测量!J683="","",动作要素测量!J683) | EI8: =IF(动作要素测量!J688="","",动作要素测量!J688) | EJ8: =IF(动作要素测量!J693="","",动作要素测量!J693) | EK8: =IF(动作要素测量!J698="","",动作要素测量!J698)
A9: ST2时间 | B9: =IF(动作要素测量!J4="","",动作要素测量!J4) | C9: =IF(动作要素测量!J9="","",动作要素测量!J9) | D9: =IF(动作要素测量!J14="","",动作要素测量!J14) | E9: =IF(动作要素测量!J19="","",动作要素测量!J19) | F9: =IF(动作要素测量!J24="","",动作要素测量!J24) | G9: =IF(动作要素测量!J29="","",动作要素测量!J29) | H9: =IF(动作要素测量!J34="","",动作要素测量!J34) | I9: =IF(动作要素测量!J39="","",动作要素测量!J39) | J9: =IF(动作要素测量!J44="","",动作要素测量!J44) | K9: =IF(动作要素测量!J49="","",动作要素测量!J49) | L9: =IF(动作要素测量!J54="","",动作要素测量!J54) | M9: =IF(动作要素测量!J59="","",动作要素测量!J59) | N9: =IF(动作要素测量!J64="","",动作要素测量!J64) | O9: =IF(动作要素测量!J69="","",动作要素测量!J69) | P9: =IF(动作要素测量!J74="","",动作要素测量!J74) | Q9: =IF(动作要素测量!J79="","",动作要素测量!J79) | R9: =IF(动作要素测量!J84="","",动作要素测量!J84) | S9: =IF(动作要素测量!J89="","",动作要素测量!J89) | T9: =IF(动作要素测量!J94="","",动作要素测量!J94) | U9: =IF(动作要素测量!J99="","",动作要素测量!J99) | V9: =IF(动作要素测量!J104="","",动作要素测量!J104) | W9: =IF(动作要素测量!J109="","",动作要素测量!J109) | X9: =IF(动作要素测量!J114="","",动作要素测量!J114) | Y9: =IF(动作要素测量!J119="","",动作要素测量!J119) | Z9: =IF(动作要素测量!J124="","",动作要素测量!J124) | AA9: =IF(动作要素测量!J129="","",动作要素测量!J129) | AB9: =IF(动作要素测量!J134="","",动作要素测量!J134) | AC9: =IF(动作要素测量!J139="","",动作要素测量!J139) | AD9: =IF(动作要素测量!J144="","",动作要素测量!J144) | AE9: =IF(动作要素测量!J149="","",动作要素测量!J149) | AF9: =IF(动作要素测量!J154="","",动作要素测量!J154) | AG9: =IF(动作要素测量!J159="","",动作要素测量!J159) | AH9: =IF(动作要素测量!J164="","",动作要素测量!J164) | AI9: =IF(动作要素测量!J169="","",动作要素测量!J169) | AJ9: =IF(动作要素测量!J174="","",动作要素测量!J174) | AK9: =IF(动作要素测量!J179="","",动作要素测量!J179) | AL9: =IF(动作要素测量!J184="","",动作要素测量!J184) | AM9: =IF(动作要素测量!J189="","",动作要素测量!J189) | AN9: =IF(动作要素测量!J194="","",动作要素测量!J194) | AO9: =IF(动作要素测量!J199="","",动作要素测量!J199) | AP9: =IF(动作要素测量!J204="","",动作要素测量!J204) | AQ9: =IF(动作要素测量!J209="","",动作要素测量!J209) | AR9: =IF(动作要素测量!J214="","",动作要素测量!J214) | AS9: =IF(动作要素测量!J219="","",动作要素测量!J219) | AT9: =IF(动作要素测量!J224="","",动作要素测量!J224) | AU9: =IF(动作要素测量!J229="","",动作要素测量!J229) | AV9: =IF(动作要素测量!J234="","",动作要素测量!J234) | AW9: =IF(动作要素测量!J239="","",动作要素测量!J239) | AX9: =IF(动作要素测量!J244="","",动作要素测量!J244) | AY9: =IF(动作要素测量!J249="","",动作要素测量!J249) | AZ9: =IF(动作要素测量!J254="","",动作要素测量!J254) | BA9: =IF(动作要素测量!J259="","",动作要素测量!J259) | BB9: =IF(动作要素测量!J264="","",动作要素测量!J264) | BC9: =IF(动作要素测量!J269="","",动作要素测量!J269) | BD9: =IF(动作要素测量!J274="","",动作要素测量!J274) | BE9: =IF(动作要素测量!J279="","",动作要素测量!J279) | BF9: =IF(动作要素测量!J284="","",动作要素测量!J284) | BG9: =IF(动作要素测量!J289="","",动作要素测量!J289) | BH9: =IF(动作要素测量!J294="","",动作要素测量!J294) | BI9: =IF(动作要素测量!J299="","",动作要素测量!J299) | BJ9: =IF(动作要素测量!J304="","",动作要素测量!J304) | BK9: =IF(动作要素测量!J309="","",动作要素测量!J309) | BL9: =IF(动作要素测量!J314="","",动作要素测量!J314) | BM9: =IF(动作要素测量!J319="","",动作要素测量!J319) | BN9: =IF(动作要素测量!J324="","",动作要素测量!J324) | BO9: =IF(动作要素测量!J329="","",动作要素测量!J329) | BP9: =IF(动作要素测量!J334="","",动作要素测量!J334) | BQ9: =IF(动作要素测量!J339="","",动作要素测量!J339) | BR9: =IF(动作要素测量!J344="","",动作要素测量!J344) | BS9: =IF(动作要素测量!J349="","",动作要素测量!J349) | BT9: =IF(动作要素测量!J354="","",动作要素测量!J354) | BU9: =IF(动作要素测量!J359="","",动作要素测量!J359) | BV9: =IF(动作要素测量!J364="","",动作要素测量!J364) | BW9: =IF(动作要素测量!J369="","",动作要素测量!J369) | BX9: =IF(动作要素测量!J374="","",动作要素测量!J374) | BY9: =IF(动作要素测量!J379="","",动作要素测量!J379) | BZ9: =IF(动作要素测量!J384="","",动作要素测量!J384) | CA9: =IF(动作要素测量!J389="","",动作要素测量!J389) | CB9: =IF(动作要素测量!J394="","",动作要素测量!J394) | CC9: =IF(动作要素测量!J399="","",动作要素测量!J399) | CD9: =IF(动作要素测量!J404="","",动作要素测量!J404) | CE9: =IF(动作要素测量!J409="","",动作要素测量!J409) | CF9: =IF(动作要素测量!J414="","",动作要素测量!J414) | CG9: =IF(动作要素测量!J419="","",动作要素测量!J419) | CH9: =IF(动作要素测量!J424="","",动作要素测量!J424) | CI9: =IF(动作要素测量!J429="","",动作要素测量!J429) | CJ9: =IF(动作要素测量!J434="","",动作要素测量!J434) | CK9: =IF(动作要素测量!J439="","",动作要素测量!J439) | CL9: =IF(动作要素测量!J444="","",动作要素测量!J444) | CM9: =IF(动作要素测量!J449="","",动作要素测量!J449) | CN9: =IF(动作要素测量!J454="","",动作要素测量!J454) | CO9: =IF(动作要素测量!J459="","",动作要素测量!J459) | CP9: =IF(动作要素测量!J464="","",动作要素测量!J464) | CQ9: =IF(动作要素测量!J469="","",动作要素测量!J469) | CR9: =IF(动作要素测量!J474="","",动作要素测量!J474) | CS9: =IF(动作要素测量!J479="","",动作要素测量!J479) | CT9: =IF(动作要素测量!J484="","",动作要素测量!J484) | CU9: =IF(动作要素测量!J489="","",动作要素测量!J489) | CV9: =IF(动作要素测量!J494="","",动作要素测量!J494) | CW9: =IF(动作要素测量!J499="","",动作要素测量!J499) | CX9: =IF(动作要素测量!J504="","",动作要素测量!J504) | CY9: =IF(动作要素测量!J509="","",动作要素测量!J509) | CZ9: =IF(动作要素测量!J514="","",动作要素测量!J514) | DA9: =IF(动作要素测量!J519="","",动作要素测量!J519) | DB9: =IF(动作要素测量!J524="","",动作要素测量!J524) | DC9: =IF(动作要素测量!J529="","",动作要素测量!J529) | DD9: =IF(动作要素测量!J534="","",动作要素测量!J534) | DE9: =IF(动作要素测量!J539="","",动作要素测量!J539) | DF9: =IF(动作要素测量!J544="","",动作要素测量!J544) | DG9: =IF(动作要素测量!J549="","",动作要素测量!J549) | DH9: =IF(动作要素测量!J554="","",动作要素测量!J554) | DI9: =IF(动作要素测量!J559="","",动作要素测量!J559) | DJ9: =IF(动作要素测量!J564="","",动作要素测量!J564) | DK9: =IF(动作要素测量!J569="","",动作要素测量!J569) | DL9: =IF(动作要素测量!J574="","",动作要素测量!J574) | DM9: =IF(动作要素测量!J579="","",动作要素测量!J579) | DN9: =IF(动作要素测量!J584="","",动作要素测量!J584) | DO9: =IF(动作要素测量!J589="","",动作要素测量!J589) | DP9: =IF(动作要素测量!J594="","",动作要素测量!J594) | DQ9: =IF(动作要素测量!J599="","",动作要素测量!J599) | DR9: =IF(动作要素测量!J604="","",动作要素测量!J604) | DS9: =IF(动作要素测量!J609="","",动作要素测量!J609) | DT9: =IF(动作要素测量!J614="","",动作要素测量!J614) | DU9: =IF(动作要素测量!J619="","",动作要素测量!J619) | DV9: =IF(动作要素测量!J624="","",动作要素测量!J624) | DW9: =IF(动作要素测量!J629="","",动作要素测量!J629) | DX9: =IF(动作要素测量!J634="","",动作要素测量!J634) | DY9: =IF(动作要素测量!J639="","",动作要素测量!J639) | DZ9: =IF(动作要素测量!J644="","",动作要素测量!J644) | EA9: =IF(动作要素测量!J649="","",动作要素测量!J649) | EB9: =IF(动作要素测量!J654="","",动作要素测量!J654) | EC9: =IF(动作要素测量!J659="","",动作要素测量!J659) | ED9: =IF(动作要素测量!J664="","",动作要素测量!J664) | EE9: =IF(动作要素测量!J669="","",动作要素测量!J669) | EF9: =IF(动作要素测量!J674="","",动作要素测量!J674) | EG9: =IF(动作要素测量!J679="","",动作要素测量!J679) | EH9: =IF(动作要素测量!J684="","",动作要素测量!J684) | EI9: =IF(动作要素测量!J689="","",动作要素测量!J689) | EJ9: =IF(动作要素测量!J694="","",动作要素测量!J694) | EK9: =IF(动作要素测量!J699="","",动作要素测量!J699)
