Workbook
Name A: #REF!
Name A: #REF!
Name A: #REF!
Name A: #REF!
Name Check: [1]產品基本信息!#REF!
Name Check: [1]產品基本信息!#REF!
Name Check: [2]產品基本信息!#REF!
Name Check: [1]產品基本信息!#REF!
Name Date: [2]產品基本信息!$B$9
Name Date: [1]產品基本信息!$B$9
Name Doc.No.: [2]產品基本信息!$B$2
Name Doc.No.: [1]產品基本信息!$B$2
Name JPY: '[3]UPPER BLOCK'!#REF!
Name JPY: '[3]UPPER BLOCK'!#REF!
Name JPY: '[3]UPPER BLOCK'!#REF!
Name JPY: '[3]UPPER BLOCK'!#REF!
Name lll: [4]HDa16!$B$10:$D$143
Name Prepared: [2]產品基本信息!$B$5
Name Prepared: [1]產品基本信息!$B$5
Name Pro.Model: [2]產品基本信息!$B$4
Name Pro.Model: [1]產品基本信息!$B$4
Name qqq: #REF!
Name qqq: #REF!
Name qqq: #REF!
Name qqq: #REF!
Name TaxTV: 10%
Name TaxXL: 5%
Name USD: '[3]UPPER BLOCK'!#REF!
Name USD: '[3]UPPER BLOCK'!#REF!
Name USD: '[3]UPPER BLOCK'!#REF!
Name USD: '[3]UPPER BLOCK'!#REF!
Name ValidBOMRange: #REF!
Name ValidBOMRange: #REF!
Name ValidBOMRange: #REF!
Name ValidBOMRange: #REF!
Name Ver.: [2]產品基本信息!$B$3
Name Ver.: [1]產品基本信息!$B$3
Name X72H046LineDft: '[5]72HX'!$F$921
Name X72H048LineDft: '[5]72HX'!$K$921
Name X72H051LineDft: '[5]72HX'!$U$921
Name X72H055LineDft: '[5]72HX'!$AE$921
Name X72H056LineDft: '[5]72HX'!$AJ$921
Name X72H057LineDft: '[5]72HX'!$AO$921
Name X72H058LineDft: '[5]72HX'!#REF!
Name X72H058LineDft: '[5]72HX'!#REF!
Name X72H058LineDft: '[5]72HX'!#REF!
Name X72H058LineDft: '[5]72HX'!#REF!
Name X72H058TotOkNo: '[5]72HX'!#REF!
Name X72H058TotOkNo: '[5]72HX'!#REF!
Name X72H058TotOkNo: '[5]72HX'!#REF!
Name X72H058TotOkNo: '[5]72HX'!#REF!
Name X72H058TotSftNo: '[5]72HX'!#REF!
Name X72H058TotSftNo: '[5]72HX'!#REF!
Name X72H058TotSftNo: '[5]72HX'!#REF!
Name X72H058TotSftNo: '[5]72HX'!#REF!
Name X72H063LineDft: '[5]72HX'!$AT$921
Name X72H067LineDft: '[5]72HX'!$BD$921
Name X72H069LineDft: '[5]72HX'!$BI$921
Name X72H072LineDft: '[5]72HX'!$BN$921
Name X75E004LineDft: '[5]75EX'!$F$921

Sheet 工时测量记录表
A1: 工时测量记录表
A2: 机型 | E2: 料号 | K2: 日期 | P2: 测量人
A4: 序号 | B4: 工站 | C4: 人数 | D4: 动作单元 | E4: 实测时间(x) | T4: Σxi | U4: Σxi² | V4: 平均值x(s) | W4: 标准偏差σ | X4: 管制下限LCL | Y4: 管制上限UCL | Z4: 剔除异常值后均值x(s) | AA4: 剔除异常值后Σxi | AB4: 剔除异常值后Σxi² | AC4: 应观测次数 | AU4: 动作变异分析
E5: 1 | F5: 2 | G5: 3 | H5: 4 | I5: 5 | J5: 6 | K5: 7 | L5: 8 | M5: 9 | N5: 10 | O5: 11 | P5: 12 | Q5: 13 | R5: 14 | S5: 15 | T5: A | U5: B | V5: X | W5: σ | X5: X-σ | Y5: X+σ | Z5: X' | AA5: A' | AB5: B' | AC5: N'=[40* n*B'-A'2/A']2 | AE5: 1 | AF5: 2 | AG5: 3 | AH5: 4 | AI5: 5 | AJ5: 6 | AK5: 7 | AL5: 8 | AM5: 9 | AN5: 10 | AO5: 11 | AP5: 12 | AQ5: 13 | AR5: 14 | AS5: 15 | AU5: 1/4位数 | AV5: 最大 | AW5: 最小 | AX5: 3/4位数
A6: 1 | T6: =IF(COUNT(E6:S6)=0,"",SUM(E6:S6)) | U6: =IF(COUNT(E6:S6)=0,"",SUMSQ(E6:S6)) | V6: =IF(COUNT(E6:S6)=0,"",AVERAGE(E6:S6)) | W6: =IF(COUNT(E6:S6)=0,"",STDEVP(E6:S6)) | X6: =IF(COUNT(E6:S6)=0,"",V6-1*W6) | Y6: =IF(COUNT(E6:S6)=0,"",V6+1*W6) | Z6: =IF(COUNT(E6:S6)=0,"",SUM(IF(AND(E6>X6,E6<Y6),E6,0),IF(AND(F6>X6,F6<Y6),F6,0),IF(AND(G6>X6,G6<Y6),G6,0),IF(AND(H6>X6,H6<Y6),H6,0),IF(AND(I6>X6,I6<Y6),I6,0),IF(AND(J6>X6,J6<Y6),J6,0),IF(AND(K6>X6,K6<Y6),K6,0),IF(AND(L6>X6,L6<Y6),L6,0),IF(AND(M6>X6,M6<Y6),M6,0),IF(AND(N6>X6,N6<Y6),N6,0),IF(AND(O6>X6,O6<Y6),O6,0),IF(AND(P6>X6,P6<Y6),P6,0),IF(AND(Q6>X6,Q6<Y6),Q6,0),IF(AND(R6>X6,R6<Y6),R6,0),IF(AND(S6>X6,S6<Y6),S6,0))/SUM(IF(AND(E6>X6,E6<Y6,E6<>0),1,0),IF(AND(F6>X6,F6<Y6,F6<>0),1,0),IF(AND(G6>X6,G6<Y6,G6<>0),1,0),IF(AND(H6>X6,H6<Y6,H6<>0),1,0),IF(AND(I6>X6,I6<Y6,I6<>0),1,0),IF(AND(J6>X6,J6<Y6,J6<>0),1,0),IF(AND(K6>X6,K6<Y6,K6<>0),1,0),IF(AND(L6>X6,L6<Y6,L6<>0),1,0),IF(AND(M6>X6,M6<Y6,M6<>0),1,0),IF(AND(N6>X6,N6<Y6,N6<>0),1,0),IF(AND(O6>X6,O6<Y6,O6<>0),1,0),IF(AND(P6>X6,P6<Y6,P6<>0),1,0),IF(AND(Q6>X6,Q6<Y6,Q6<>0),1,0),IF(AND(R6>X6,R6<Y6,R6<>0),1,0),IF(AND(S6>X6,S6<Y6,S6<>0),1,0))) | AA6: =IF(COUNT(E6:S6)=0,"",SUM(IF(AND(E6>X6,E6<Y6),E6,0),IF(AND(F6>X6,F6<Y6),F6,0),IF(AND(G6>X6,G6<Y6),G6,0),IF(AND(H6>X6,H6<Y6),H6,0),IF(AND(I6>X6,I6<Y6),I6,0),IF(AND(J6>X6,J6<Y6),J6,0),IF(AND(K6>X6,K6<Y6),K6,0),IF(AND(L6>X6,L6<Y6),L6,0),IF(AND(M6>X6,M6<Y6),M6,0),IF(AND(N6>X6,N6<Y6),N6,0),IF(AND(O6>X6,O6<Y6),O6,0),IF(AND(P6>X6,P6<Y6),P6,0),IF(AND(Q6>X6,Q6<Y6),Q6,0),IF(AND(R6>X6,R6<Y6),R6,0),IF(AND(S6>X6,S6<Y6),S6,0))) | AB6: =IF(COUNT(E6:S6)=0,"",SUMSQ(IF(AND(E6>X6,E6<Y6),E6,0),IF(AND(F6>X6,F6<Y6),F6,0),IF(AND(G6>X6,G6<Y6),G6,0),IF(AND(H6>X6,H6<Y6),H6,0),IF(AND(I6>X6,I6<Y6),I6,0),IF(AND(J6>X6,J6<Y6),J6,0),IF(AND(K6>X6,K6<Y6),K6,0),IF(AND(L6>X6,L6<Y6),L6,0),IF(AND(M6>X6,M6<Y6),M6,0),IF(AND(N6>X6,N6<Y6),N6,0),IF(AND(O6>X6,O6<Y6),O6,0),IF(AND(P6>X6,P6<Y6),P6,0),IF(AND(Q6>X6,Q6<Y6),Q6,0),IF(AND(R6>X6,R6<Y6),R6,0),IF(AND(S6>X6,S6<Y6),S6,0))) | AC6: =IF(COUNT(E6:S6)=0,"",POWER(40*SQRT(SUM(IF(AND(E6>X6,E6<Y6),1,0),IF(AND(F6>X6,F6<Y6),1,0),IF(AND(G6>X6,G6<Y6),1,0),IF(AND(H6>X6,H6<Y6),1,0),IF(AND(I6>X6,I6<Y6),1,0),IF(AND(J6>X6,J6<Y6),1,0),IF(AND(K6>X6,K6<Y6),1,0),IF(AND(L6>X6,L6<Y6),1,0),IF(AND(M6>X6,M6<Y6),1,0),IF(AND(N6>X6,N6<Y6),1,0),IF(AND(O6>X6,O6<Y6),1,0),IF(AND(P6>X6,P6<Y6),1,0),IF(AND(Q6>X6,Q6<Y6),1,0),IF(AND(R6>X6,R6<Y6),1,0),IF(AND(S6>X6,S6<Y6),1,0))*AB6-POWER(AA6,2))/AA6,2)) | AD6: 1 | AE6: =IF(SUM(INDIRECT(CHAR(COLUMN()+38)&(ROW()-5)*8-2&":"&CHAR(COLUMN()+38)&(ROW()-5)*8+5))=0,"",SUM(INDIRECT(CHAR(COLUMN()+38)&(ROW()-5)*8-2&":"&CHAR(COLUMN()+38)&(ROW()-5)*8+5))/INDIRECT("C"&(ROW()-5)*8-2)) | AF6: =IF(SUM(INDIRECT(CHAR(COLUMN()+38)&(ROW()-5)*8-2&":"&CHAR(COLUMN()+38)&(ROW()-5)*8+5))=0,"",SUM(INDIRECT(CHAR(COLUMN()+38)&(ROW()-5)*8-2&":"&CHAR(COLUMN()+38)&(ROW()-5)*8+5))/INDIRECT("C"&(ROW()-5)*8-2)) | AG6: =IF(SUM(INDIRECT(CHAR(COLUMN()+38)&(ROW()-5)*8-2&":"&CHAR(COLUMN()+38)&(ROW()-5)*8+5))=0,"",SUM(INDIRECT(CHAR(COLUMN()+38)&(ROW()-5)*8-2&":"&CHAR(COLUMN()+38)&(ROW()-5)*8+5))/INDIRECT("C"&(ROW()-5)*8-2)) | AH6: =IF(SUM(INDIRECT(CHAR(COLUMN()+38)&(ROW()-5)*8-2&":"&CHAR(COLUMN()+38)&(ROW()-5)*8+5))=0,"",SUM(INDIRECT(CHAR(COLUMN()+38)&(ROW()-5)*8-2&":"&CHAR(COLUMN()+38)&(ROW()-5)*8+5))/INDIRECT("C"&(ROW()-5)*8-2)) | AI6: =IF(SUM(INDIRECT(CHAR(COLUMN()+38)&(ROW()-5)*8-2&":"&CHAR(COLUMN()+38)&(ROW()-5)*8+5))=0,"",SUM(INDIRECT(CHAR(COLUMN()+38)&(ROW()-5)*8-2&":"&CHAR(COLUMN()+38)&(ROW()-5)*8+5))/INDIRECT("C"&(ROW()-5)*8-2)) | AJ6: =IF(SUM(INDIRECT(CHAR(COLUMN()+38)&(ROW()-5)*8-2&":"&CHAR(COLUMN()+38)&(ROW()-5)*8+5))=0,"",SUM(INDIRECT(CHAR(COLUMN()+38)&(ROW()-5)*8-2&":"&CHAR(COLUMN()+38)&(ROW()-5)*8+5))/INDIRECT("C"&(ROW()-5)*8-2)) | AK6: =IF(SUM(INDIRECT(CHAR(COLUMN()+38)&(ROW()-5)*8-2&":"&CHAR(COLUMN()+38)&(ROW()-5)*8+5))=0,"",SUM(INDIRECT(CHAR(COLUMN()+38)&(ROW()-5)*8-2&":"&CHAR(COLUMN()+38)&(ROW()-5)*8+5))/INDIRECT("C"&(ROW()-5)*8-2)) | AL6: =IF(SUM(INDIRECT(CHAR(COLUMN()+38)&(ROW()-5)*8-2&":"&CHAR(COLUMN()+38)&(ROW()-5)*8+5))=0,"",SUM(INDIRECT(CHAR(COLUMN()+38)&(ROW()-5)*8-2&":"&CHAR(COLUMN()+38)&(ROW()-5)*8+5))/INDIRECT("C"&(ROW()-5)*8-2)) | ... AS6: =IF(SUM(INDIRECT(CHAR(COLUMN()+38)&(ROW()-5)*8-2&":"&CHAR(COLUMN()+38)&(ROW()-5)*8+5))=0,"",SUM(INDIRECT(CHAR(COLUMN()+38)&(ROW()-5)*8-2&":"&CHAR(COLUMN()+38)&(ROW()-5)*8+5))/INDIRECT("C"&(ROW()-5)*8-2)) | AT6: 1 | AU6: =IF(COUNT($AE6:$AS6)=0,"",PERCENTILE($AE6:$AS6,0.25)) | AV6: =IF(COUNT($AE6:$AS6)=0,"",MAX($AE6:$AS6)) | AW6: =IF(COUNT($AE6:$AS6)=0,"",MIN($AE6:$AS6)) | AX6: =IF(COUNT($AE6:$AS6)=0,"",PERCENTILE($AE6:$AS6,0.75))
T7: =IF(COUNT(E7:S7)=0,"",SUM(E7:S7)) | U7: =IF(COUNT(E7:S7)=0,"",SUMSQ(E7:S7)) | V7: =IF(COUNT(E7:S7)=0,"",AVERAGE(E7:S7)) | W7: =IF(COUNT(E7:S7)=0,"",STDEVP(E7:S7)) | X7: =IF(COUNT(E7:S7)=0,"",V7-1*W7) | Y7: =IF(COUNT(E7:S7)=0,"",V7+1*W7) | Z7: =IF(COUNT(E7:S7)=0,"",SUM(IF(AND(E7>X7,E7<Y7),E7,0),IF(AND(F7>X7,F7<Y7),F7,0),IF(AND(G7>X7,G7<Y7),G7,0),IF(AND(H7>X7,H7<Y7),H7,0),IF(AND(I7>X7,I7<Y7),I7,0),IF(AND(J7>X7,J7<Y7),J7,0),IF(AND(K7>X7,K7<Y7),K7,0),IF(AND(L7>X7,L7<Y7),L7,0),IF(AND(M7>X7,M7<Y7),M7,0),IF(AND(N7>X7,N7<Y7),N7,0),IF(AND(O7>X7,O7<Y7),O7,0),IF(AND(P7>X7,P7<Y7),P7,0),IF(AND(Q7>X7,Q7<Y7),Q7,0),IF(AND(R7>X7,R7<Y7),R7,0),IF(AND(S7>X7,S7<Y7),S7,0))/SUM(IF(AND(E7>X7,E7<Y7,E7<>0),1,0),IF(AND(F7>X7,F7<Y7,F7<>0),1,0),IF(AND(G7>X7,G7<Y7,G7<>0),1,0),IF(AND(H7>X7,H7<Y7,H7<>0),1,0),IF(AND(I7>X7,I7<Y7,I7<>0),1,0),IF(AND(J7>X7,J7<Y7,J7<>0),1,0),IF(AND(K7>X7,K7<Y7,K7<>0),1,0),IF(AND(L7>X7,L7<Y7,L7<>0),1,0),IF(AND(M7>X7,M7<Y7,M7<>0),1,0),IF(AND(N7>X7,N7<Y7,N7<>0),1,0),IF(AND(O7>X7,O7<Y7,O7<>0),1,0),IF(AND(P7>X7,P7<Y7,P7<>0),1,0),IF(AND(Q7>X7,Q7<Y7,Q7<>0),1,0),IF(AND(R7>X7,R7<Y7,R7<>0),1,0),IF(AND(S7>X7,S7<Y7,S7<>0),1,0))) | AA7: =IF(COUNT(E7:S7)=0,"",SUM(IF(AND(E7>X7,E7<Y7),E7,0),IF(AND(F7>X7,F7<Y7),F7,0),IF(AND(G7>X7,G7<Y7),G7,0),IF(AND(H7>X7,H7<Y7),H7,0),IF(AND(I7>X7,I7<Y7),I7,0),IF(AND(J7>X7,J7<Y7),J7,0),IF(AND(K7>X7,K7<Y7),K7,0),IF(AND(L7>X7,L7<Y7),L7,0),IF(AND(M7>X7,M7<Y7),M7,0),IF(AND(N7>X7,N7<Y7),N7,0),IF(AND(O7>X7,O7<Y7),O7,0),IF(AND(P7>X7,P7<Y7),P7,0),IF(AND(Q7>X7,Q7<Y7),Q7,0),IF(AND(R7>X7,R7<Y7),R7,0),IF(AND(S7>X7,S7<Y7),S7,0))) | AB7: =IF(COUNT(E7:S7)=0,"",SUMSQ(IF(AND(E7>X7,E7<Y7),E7,0),IF(AND(F7>X7,F7<Y7),F7,0),IF(AND(G7>X7,G7<Y7),G7,0),IF(AND(H7>X7,H7<Y7),H7,0),IF(AND(I7>X7,I7<Y7),I7,0),IF(AND(J7>X7,J7<Y7),J7,0),IF(AND(K7>X7,K7<Y7),K7,0),IF(AND(L7>X7,L7<Y7),L7,0),IF(AND(M7>X7,M7<Y7),M7,0),IF(AND(N7>X7,N7<Y7),N7,0),IF(AND(O7>X7,O7<Y7),O7,0),IF(AND(P7>X7,P7<Y7),P7,0),IF(AND(Q7>X7,Q7<Y7),Q7,0),IF(AND(R7>X7,R7<Y7),R7,0),IF(AND(S7>X7,S7<Y7),S7,0))) | AC7: =IF(COUNT(E7:S7)=0,"",POWER(40*SQRT(SUM(IF(AND(E7>X7,E7<Y7),1,0),IF(AND(F7>X7,F7<Y7),1,0),IF(AND(G7>X7,G7<Y7),1,0),IF(AND(H7>X7,H7<Y7),1,0),IF(AND(I7>X7,I7<Y7),1,0),IF(AND(J7>X7,J7<Y7),1,0),IF(AND(K7>X7,K7<Y7),1,0),IF(AND(L7>X7,L7<Y7),1,0),IF(AND(M7>X7,M7<Y7),1,0),IF(AND(N7>X7,N7<Y7),1,0),IF(AND(O7>X7,O7<Y7),1,0),IF(AND(P7>X7,P7<Y7),1,0),IF(AND(Q7>X7,Q7<Y7),1,0),IF(AND(R7>X7,R7<Y7),1,0),IF(AND(S7>X7,S7<Y7),1,0))*AB7-POWER(AA7,2))/AA7,2)) | AD7: 2 | AE7: =IF(SUM(INDIRECT(CHAR(COLUMN()+38)&(ROW()-5)*8-2&":"&CHAR(COLUMN()+38)&(ROW()-5)*8+5))=0,"",SUM(INDIRECT(CHAR(COLUMN()+38)&(ROW()-5)*8-2&":"&CHAR(COLUMN()+38)&(ROW()-5)*8+5))/INDIRECT("C"&(ROW()-5)*8-2)) | AF7: =IF(SUM(INDIRECT(CHAR(COLUMN()+38)&(ROW()-5)*8-2&":"&CHAR(COLUMN()+38)&(ROW()-5)*8+5))=0,"",SUM(INDIRECT(CHAR(COLUMN()+38)&(ROW()-5)*8-2&":"&CHAR(COLUMN()+38)&(ROW()-5)*8+5))/INDIRECT("C"&(ROW()-5)*8-2)) | AG7: =IF(SUM(INDIRECT(CHAR(COLUMN()+38)&(ROW()-5)*8-2&":"&CHAR(COLUMN()+38)&(ROW()-5)*8+5))=0,"",SUM(INDIRECT(CHAR(COLUMN()+38)&(ROW()-5)*8-2&":"&CHAR(COLUMN()+38)&(ROW()-5)*8+5))/INDIRECT("C"&(ROW()-5)*8-2)) | AH7: =IF(SUM(INDIRECT(CHAR(COLUMN()+38)&(ROW()-5)*8-2&":"&CHAR(COLUMN()+38)&(ROW()-5)*8+5))=0,"",SUM(INDIRECT(CHAR(COLUMN()+38)&(ROW()-5)*8-2&":"&CHAR(COLUMN()+38)&(ROW()-5)*8+5))/INDIRECT("C"&(ROW()-5)*8-2)) | AI7: =IF(SUM(INDIRECT(CHAR(COLUMN()+38)&(ROW()-5)*8-2&":"&CHAR(COLUMN()+38)&(ROW()-5)*8+5))=0,"",SUM(INDIRECT(CHAR(COLUMN()+38)&(ROW()-5)*8-2&":"&CHAR(COLUMN()+38)&(ROW()-5)*8+5))/INDIRECT("C"&(ROW()-5)*8-2)) | AJ7: =IF(SUM(INDIRECT(CHAR(COLUMN()+38)&(ROW()-5)*8-2&":"&CHAR(COLUMN()+38)&(ROW()-5)*8+5))=0,"",SUM(INDIRECT(CHAR(COLUMN()+38)&(ROW()-5)*8-2&":"&CHAR(COLUMN()+38)&(ROW()-5)*8+5))/INDIRECT("C"&(ROW()-5)*8-2)) | AK7: =IF(SUM(INDIRECT(CHAR(COLUMN()+38)&(ROW()-5)*8-2&":"&CHAR(COLUMN()+38)&(ROW()-5)*8+5))=0,"",SUM(INDIRECT(CHAR(COLUMN()+38)&(ROW()-5)*8-2&":"&CHAR(COLUMN()+38)&(ROW()-5)*8+5))/INDIRECT("C"&(ROW()-5)*8-2)) | AL7: =IF(SUM(INDIRECT(CHAR(COLUMN()+38)&(ROW()-5)*8-2&":"&CHAR(COLUMN()+38)&(ROW()-5)*8+5))=0,"",SUM(INDIRECT(CHAR(COLUMN()+38)&(ROW()-5)*8-2&":"&CHAR(COLUMN()+38)&(ROW()-5)*8+5))/INDIRECT("C"&(ROW()-5)*8-2)) | ... AS7: =IF(SUM(INDIRECT(CHAR(COLUMN()+38)&(ROW()-5)*8-2&":"&CHAR(COLUMN()+38)&(ROW()-5)*8+5))=0,"",SUM(INDIRECT(CHAR(COLUMN()+38)&(ROW()-5)*8-2&":"&CHAR(COLUMN()+38)&(ROW()-5)*8+5))/INDIRECT("C"&(ROW()-5)*8-2)) | AT7: 2 | AU7: =IF(COUNT($AE7:$AS7)=0,"",PERCENTILE($AE7:$AS7,0.25)) | AV7: =IF(COUNT($AE7:$AS7)=0,"",MAX($AE7:$AS7)) | AW7: =IF(COUNT($AE7:$AS7)=0,"",MIN($AE7:$AS7)) | AX7: =IF(COUNT($AE7:$AS7)=0,"",PERCENTILE($AE7:$AS7,0.75))
T8: =IF(COUNT(E8:S8)=0,"",SUM(E8:S8)) | U8: =IF(COUNT(E8:S8)=0,"",SUMSQ(E8:S8)) | V8: =IF(COUNT(E8:S8)=0,"",AVERAGE(E8:S8)) | W8: =IF(COUNT(E8:S8)=0,"",STDEVP(E8:S8)) | X8: =IF(COUNT(E8:S8)=0,"",V8-1*W8) | Y8: =IF(COUNT(E8:S8)=0,"",V8+1*W8) | Z8: =IF(COUNT(E8:S8)=0,"",SUM(IF(AND(E8>X8,E8<Y8),E8,0),IF(AND(F8>X8,F8<Y8),F8,0),IF(AND(G8>X8,G8<Y8),G8,0),IF(AND(H8>X8,H8<Y8),H8,0),IF(AND(I8>X8,I8<Y8),I8,0),IF(AND(J8>X8,J8<Y8),J8,0),IF(AND(K8>X8,K8<Y8),K8,0),IF(AND(L8>X8,L8<Y8),L8,0),IF(AND(M8>X8,M8<Y8),M8,0),IF(AND(N8>X8,N8<Y8),N8,0),IF(AND(O8>X8,O8<Y8),O8,0),IF(AND(P8>X8,P8<Y8),P8,0),IF(AND(Q8>X8,Q8<Y8),Q8,0),IF(AND(R8>X8,R8<Y8),R8,0),IF(AND(S8>X8,S8<Y8),S8,0))/SUM(IF(AND(E8>X8,E8<Y8,E8<>0),1,0),IF(AND(F8>X8,F8<Y8,F8<>0),1,0),IF(AND(G8>X8,G8<Y8,G8<>0),1,0),IF(AND(H8>X8,H8<Y8,H8<>0),1,0),IF(AND(I8>X8,I8<Y8,I8<>0),1,0),IF(AND(J8>X8,J8<Y8,J8<>0),1,0),IF(AND(K8>X8,K8<Y8,K8<>0),1,0),IF(AND(L8>X8,L8<Y8,L8<>0),1,0),IF(AND(M8>X8,M8<Y8,M8<>0),1,0),IF(AND(N8>X8,N8<Y8,N8<>0),1,0),IF(AND(O8>X8,O8<Y8,O8<>0),1,0),IF(AND(P8>X8,P8<Y8,P8<>0),1,0),IF(AND(Q8>X8,Q8<Y8,Q8<>0),1,0),IF(AND(R8>X8,R8<Y8,R8<>0),1,0),IF(AND(S8>X8,S8<Y8,S8<>0),1,0))) | AA8: =IF(COUNT(E8:S8)=0,"",SUM(IF(AND(E8>X8,E8<Y8),E8,0),IF(AND(F8>X8,F8<Y8),F8,0),IF(AND(G8>X8,G8<Y8),G8,0),IF(AND(H8>X8,H8<Y8),H8,0),IF(AND(I8>X8,I8<Y8),I8,0),IF(AND(J8>X8,J8<Y8),J8,0),IF(AND(K8>X8,K8<Y8),K8,0),IF(AND(L8>X8,L8<Y8),L8,0),IF(AND(M8>X8,M8<Y8),M8,0),IF(AND(N8>X8,N8<Y8),N8,0),IF(AND(O8>X8,O8<Y8),O8,0),IF(AND(P8>X8,P8<Y8),P8,0),IF(AND(Q8>X8,Q8<Y8),Q8,0),IF(AND(R8>X8,R8<Y8),R8,0),IF(AND(S8>X8,S8<Y8),S8,0))) | AB8: =IF(COUNT(E8:S8)=0,"",SUMSQ(IF(AND(E8>X8,E8<Y8),E8,0),IF(AND(F8>X8,F8<Y8),F8,0),IF(AND(G8>X8,G8<Y8),G8,0),IF(AND(H8>X8,H8<Y8),H8,0),IF(AND(I8>X8,I8<Y8),I8,0),IF(AND(J8>X8,J8<Y8),J8,0),IF(AND(K8>X8,K8<Y8),K8,0),IF(AND(L8>X8,L8<Y8),L8,0),IF(AND(M8>X8,M8<Y8),M8,0),IF(AND(N8>X8,N8<Y8),N8,0),IF(AND(O8>X8,O8<Y8),O8,0),IF(AND(P8>X8,P8<Y8),P8,0),IF(AND(Q8>X8,Q8<Y8),Q8,0),IF(AND(R8>X8,R8<Y8),R8,0),IF(AND(S8>X8,S8<Y8),S8,0))) | AC8: =IF(COUNT(E8:S8)=0,"",POWER(40*SQRT(SUM(IF(AND(E8>X8,E8<Y8),1,0),IF(AND(F8>X8,F8<Y8),1,0),IF(AND(G8>X8,G8<Y8),1,0),IF(AND(H8>X8,H8<Y8),1,0),IF(AND(I8>X8,I8<Y8),1,0),IF(AND(J8>X8,J8<Y8),1,0),IF(AND(K8>X8,K8<Y8),1,0),IF(AND(L8>X8,L8<Y8),1,0),IF(AND(M8>X8,M8<Y8),1,0),IF(AND(N8>X8,N8<Y8),1,0),IF(AND(O8>X8,O8<Y8),1,0),IF(AND(P8>X8,P8<Y8),1,0),IF(AND(Q8>X8,Q8<Y8),1,0),IF(AND(R8>X8,R8<Y8),1,0),IF(AND(S8>X8,S8<Y8),1,0))*AB8-POWER(AA8,2))/AA8,2)) | AD8: 3 | AE8: =IF(SUM(INDIRECT(CHAR(COLUMN()+38)&(ROW()-5)*8-2&":"&CHAR(COLUMN()+38)&(ROW()-5)*8+5))=0,"",SUM(INDIRECT(CHAR(COLUMN()+38)&(ROW()-5)*8-2&":"&CHAR(COLUMN()+38)&(ROW()-5)*8+5))/INDIRECT("C"&(ROW()-5)*8-2)) | AF8: =IF(SUM(INDIRECT(CHAR(COLUMN()+38)&(ROW()-5)*8-2&":"&CHAR(COLUMN()+38)&(ROW()-5)*8+5))=0,"",SUM(INDIRECT(CHAR(COLUMN()+38)&(ROW()-5)*8-2&":"&CHAR(COLUMN()+38)&(ROW()-5)*8+5))/INDIRECT("C"&(ROW()-5)*8-2)) | AG8: =IF(SUM(INDIRECT(CHAR(COLUMN()+38)&(ROW()-5)*8-2&":"&CHAR(COLUMN()+38)&(ROW()-5)*8+5))=0,"",SUM(INDIRECT(CHAR(COLUMN()+38)&(ROW()-5)*8-2&":"&CHAR(COLUMN()+38)&(ROW()-5)*8+5))/INDIRECT("C"&(ROW()-5)*8-2)) | AH8: =IF(SUM(INDIRECT(CHAR(COLUMN()+38)&(ROW()-5)*8-2&":"&CHAR(COLUMN()+38)&(ROW()-5)*8+5))=0,"",SUM(INDIRECT(CHAR(COLUMN()+38)&(ROW()-5)*8-2&":"&CHAR(COLUMN()+38)&(ROW()-5)*8+5))/INDIRECT("C"&(ROW()-5)*8-2)) | AI8: =IF(SUM(INDIRECT(CHAR(COLUMN()+38)&(ROW()-5)*8-2&":"&CHAR(COLUMN()+38)&(ROW()-5)*8+5))=0,"",SUM(INDIRECT(CHAR(COLUMN()+38)&(ROW()-5)*8-2&":"&CHAR(COLUMN()+38)&(ROW()-5)*8+5))/INDIRECT("C"&(ROW()-5)*8-2)) | AJ8: =IF(SUM(INDIRECT(CHAR(COLUMN()+38)&(ROW()-5)*8-2&":"&CHAR(COLUMN()+38)&(ROW()-5)*8+5))=0,"",SUM(INDIRECT(CHAR(COLUMN()+38)&(ROW()-5)*8-2&":"&CHAR(COLUMN()+38)&(ROW()-5)*8+5))/INDIRECT("C"&(ROW()-5)*8-2)) | AK8: =IF(SUM(INDIRECT(CHAR(COLUMN()+38)&(ROW()-5)*8-2&":"&CHAR(COLUMN()+38)&(ROW()-5)*8+5))=0,"",SUM(INDIRECT(CHAR(COLUMN()+38)&(ROW()-5)*8-2&":"&CHAR(COLUMN()+38)&(ROW()-5)*8+5))/INDIRECT("C"&(ROW()-5)*8-2)) | AL8: =IF(SUM(INDIRECT(CHAR(COLUMN()+38)&(ROW()-5)*8-2&":"&CHAR(COLUMN()+38)&(ROW()-5)*8+5))=0,"",SUM(INDIRECT(CHAR(COLUMN()+38)&(ROW()-5)*8-2&":"&CHAR(COLUMN()+38)&(ROW()-5)*8+5))/INDIRECT("C"&(ROW()-5)*8-2)) | ... AS8: =IF(SUM(INDIRECT(CHAR(COLUMN()+38)&(ROW()-5)*8-2&":"&CHAR(COLUMN()+38)&(ROW()-5)*8+5))=0,"",SUM(INDIRECT(CHAR(COLUMN()+38)&(ROW()-5)*8-2&":"&CHAR(COLUMN()+38)&(ROW()-5)*8+5))/INDIRECT("C"&(ROW()-5)*8-2)) | AT8: 3 | AU8: =IF(COUNT($AE8:$AS8)=0,"",PERCENTILE($AE8:$AS8,0.25)) | AV8: =IF(COUNT($AE8:$AS8)=0,"",MAX($AE8:$AS8)) | AW8: =IF(COUNT($AE8:$AS8)=0,"",MIN($AE8:$AS8)) | AX8: =IF(COUNT($AE8:$AS8)=0,"",PERCENTILE($AE8:$AS8,0.75))
T9: =IF(COUNT(E9:S9)=0,"",SUM(E9:S9)) | U9: =IF(COUNT(E9:S9)=0,"",SUMSQ(E9:S9)) | V9: =IF(COUNT(E9:S9)=0,"",AVERAGE(E9:S9)) | W9: =IF(COUNT(E9:S9)=0,"",STDEVP(E9:S9)) | X9: =IF(COUNT(E9:S9)=0,"",V9-1*W9) | Y9: =IF(COUNT(E9:S9)=0,"",V9+1*W9) | Z9: =IF(COUNT(E9:S9)=0,"",SUM(IF(AND(E9>X9,E9<Y9),E9,0),IF(AND(F9>X9,F9<Y9),F9,0),IF(AND(G9>X9,G9<Y9),G9,0),IF(AND(H9>X9,H9<Y9),H9,0),IF(AND(I9>X9,I9<Y9),I9,0),IF(AND(J9>X9,J9<Y9),J9,0),IF(AND(K9>X9,K9<Y9),K9,0),IF(AND(L9>X9,L9<Y9),L9,0),IF(AND(M9>X9,M9<Y9),M9,0),IF(AND(N9>X9,N9<Y9),N9,0),IF(AND(O9>X9,O9<Y9),O9,0),IF(AND(P9>X9,P9<Y9),P9,0),IF(AND(Q9>X9,Q9<Y9),Q9,0),IF(AND(R9>X9,R9<Y9),R9,0),IF(AND(S9>X9,S9<Y9),S9,0))/SUM(IF(AND(E9>X9,E9<Y9,E9<>0),1,0),IF(AND(F9>X9,F9<Y9,F9<>0),1,0),IF(AND(G9>X9,G9<Y9,G9<>0),1,0),IF(AND(H9>X9,H9<Y9,H9<>0),1,0),IF(AND(I9>X9,I9<Y9,I9<>0),1,0),IF(AND(J9>X9,J9<Y9,J9<>0),1,0),IF(AND(K9>X9,K9<Y9,K9<>0),1,0),IF(AND(L9>X9,L9<Y9,L9<>0),1,0),IF(AND(M9>X9,M9<Y9,M9<>0),1,0),IF(AND(N9>X9,N9<Y9,N9<>0),1,0),IF(AND(O9>X9,O9<Y9,O9<>0),1,0),IF(AND(P9>X9,P9<Y9,P9<>0),1,0),IF(AND(Q9>X9,Q9<Y9,Q9<>0),1,0),IF(AND(R9>X9,R9<Y9,R9<>0),1,0),IF(AND(S9>X9,S9<Y9,S9<>0),1,0))) | AA9: =IF(COUNT(E9:S9)=0,"",SUM(IF(AND(E9>X9,E9<Y9),E9,0),IF(AND(F9>X9,F9<Y9),F9,0),IF(AND(G9>X9,G9<Y9),G9,0),IF(AND(H9>X9,H9<Y9),H9,0),IF(AND(I9>X9,I9<Y9),I9,0),IF(AND(J9>X9,J9<Y9),J9,0),IF(AND(K9>X9,K9<Y9),K9,0),IF(AND(L9>X9,L9<Y9),L9,0),IF(AND(M9>X9,M9<Y9),M9,0),IF(AND(N9>X9,N9<Y9),N9,0),IF(AND(O9>X9,O9<Y9),O9,0),IF(AND(P9>X9,P9<Y9),P9,0),IF(AND(Q9>X9,Q9<Y9),Q9,0),IF(AND(R9>X9,R9<Y9),R9,0),IF(AND(S9>X9,S9<Y9),S9,0))) | AB9: =IF(COUNT(E9:S9)=0,"",SUMSQ(IF(AND(E9>X9,E9<Y9),E9,0),IF(AND(F9>X9,F9<Y9),F9,0),IF(AND(G9>X9,G9<Y9),G9,0),IF(AND(H9>X9,H9<Y9),H9,0),IF(AND(I9>X9,I9<Y9),I9,0),IF(AND(J9>X9,J9<Y9),J9,0),IF(AND(K9>X9,K9<Y9),K9,0),IF(AND(L9>X9,L9<Y9),L9,0),IF(AND(M9>X9,M9<Y9),M9,0),IF(AND(N9>X9,N9<Y9),N9,0),IF(AND(O9>X9,O9<Y9),O9,0),IF(AND(P9>X9,P9<Y9),P9,0),IF(AND(Q9>X9,Q9<Y9),Q9,0),IF(AND(R9>X9,R9<Y9),R9,0),IF(AND(S9>X9,S9<Y9),S9,0))) | AC9: =IF(COUNT(E9:S9)=0,"",POWER(40*SQRT(SUM(IF(AND(E9>X9,E9<Y9),1,0),IF(AND(F9>X9,F9<Y9),1,0),IF(AND(G9>X9,G9<Y9),1,0),IF(AND(H9>X9,H9<Y9),1,0),IF(AND(I9>X9,I9<Y9),1,0),IF(AND(J9>X9,J9<Y9),1,0),IF(AND(K9>X9,K9<Y9),1,0),IF(AND(L9>X9,L9<Y9),1,0),IF(AND(M9>X9,M9<Y9),1,0),IF(AND(N9>X9,N9<Y9),1,0),IF(AND(O9>X9,O9<Y9),1,0),IF(AND(P9>X9,P9<Y9),1,0),IF(AND(Q9>X9,Q9<Y9),1,0),IF(AND(R9>X9,R9<Y9),1,0),IF(AND(S9>X9,S9<Y9),1,0))*AB9-POWER(AA9,2))/AA9,2)) | AD9: 4 | AE9: =IF(SUM(INDIRECT(CHAR(COLUMN()+38)&(ROW()-5)*8-2&":"&CHAR(COLUMN()+38)&(ROW()-5)*8+5))=0,"",SUM(INDIRECT(CHAR(COLUMN()+38)&(ROW()-5)*8-2&":"&CHAR(COLUMN()+38)&(ROW()-5)*8+5))/INDIRECT("C"&(ROW()-5)*8-2)) | AF9: =IF(SUM(INDIRECT(CHAR(COLUMN()+38)&(ROW()-5)*8-2&":"&CHAR(COLUMN()+38)&(ROW()-5)*8+5))=0,"",SUM(INDIRECT(CHAR(COLUMN()+38)&(ROW()-5)*8-2&":"&CHAR(COLUMN()+38)&(ROW()-5)*8+5))/INDIRECT("C"&(ROW()-5)*8-2)) | AG9: =IF(SUM(INDIRECT(CHAR(COLUMN()+38)&(ROW()-5)*8-2&":"&CHAR(COLUMN()+38)&(ROW()-5)*8+5))=0,"",SUM(INDIRECT(CHAR(COLUMN()+38)&(ROW()-5)*8-2&":"&CHAR(COLUMN()+38)&(ROW()-5)*8+5))/INDIRECT("C"&(ROW()-5)*8-2)) | AH9: =IF(SUM(INDIRECT(CHAR(COLUMN()+38)&(ROW()-5)*8-2&":"&CHAR(COLUMN()+38)&(ROW()-5)*8+5))=0,"",SUM(INDIRECT(CHAR(COLUMN()+38)&(ROW()-5)*8-2&":"&CHAR(COLUMN()+38)&(ROW()-5)*8+5))/INDIRECT("C"&(ROW()-5)*8-2)) | AI9: =IF(SUM(INDIRECT(CHAR(COLUMN()+38)&(ROW()-5)*8-2&":"&CHAR(COLUMN()+38)&(ROW()-5)*8+5))=0,"",SUM(INDIRECT(CHAR(COLUMN()+38)&(ROW()-5)*8-2&":"&CHAR(COLUMN()+38)&(ROW()-5)*8+5))/INDIRECT("C"&(ROW()-5)*8-2)) | AJ9: =IF(SUM(INDIRECT(CHAR(COLUMN()+38)&(ROW()-5)*8-2&":"&CHAR(COLUMN()+38)&(ROW()-5)*8+5))=0,"",SUM(INDIRECT(CHAR(COLUMN()+38)&(ROW()-5)*8-2&":"&CHAR(COLUMN()+38)&(ROW()-5)*8+5))/INDIRECT("C"&(ROW()-5)*8-2)) | AK9: =IF(SUM(INDIRECT(CHAR(COLUMN()+38)&(ROW()-5)*8-2&":"&CHAR(COLUMN()+38)&(ROW()-5)*8+5))=0,"",SUM(INDIRECT(CHAR(COLUMN()+38)&(ROW()-5)*8-2&":"&CHAR(COLUMN()+38)&(ROW()-5)*8+5))/INDIRECT("C"&(ROW()-5)*8-2)) | AL9: =IF(SUM(INDIRECT(CHAR(COLUMN()+38)&(ROW()-5)*8-2&":"&CHAR(COLUMN()+38)&(ROW()-5)*8+5))=0,"",SUM(INDIRECT(CHAR(COLUMN()+38)&(ROW()-5)*8-2&":"&CHAR(COLUMN()+38)&(ROW()-5)*8+5))/INDIRECT("C"&(ROW()-5)*8-2)) | ... AS9: =IF(SUM(INDIRECT(CHAR(COLUMN()+38)&(ROW()-5)*8-2&":"&CHAR(COLUMN()+38)&(ROW()-5)*8+5))=0,"",SUM(INDIRECT(CHAR(COLUMN()+38)&(ROW()-5)*8-2&":"&CHAR(COLUMN()+38)&(ROW()-5)*8+5))/INDIRECT("C"&(ROW()-5)*8-2)) | AT9: 4 | AU9: =IF(COUNT($AE9:$AS9)=0,"",PERCENTILE($AE9:$AS9,0.25)) | AV9: =IF(COUNT($AE9:$AS9)=0,"",MAX($AE9:$AS9)) | AW9: =IF(COUNT($AE9:$AS9)=0,"",MIN($AE9:$AS9)) | AX9: =IF(COUNT($AE9:$AS9)=0,"",PERCENTILE($AE9:$AS9,0.75))
T10: =IF(COUNT(E10:S10)=0,"",SUM(E10:S10)) | U10: =IF(COUNT(E10:S10)=0,"",SUMSQ(E10:S10)) | V10: =IF(COUNT(E10:S10)=0,"",AVERAGE(E10:S10)) | W10: =IF(COUNT(E10:S10)=0,"",STDEVP(E10:S10)) | X10: =IF(COUNT(E10:S10)=0,"",V10-1*W10) | Y10: =IF(COUNT(E10:S10)=0,"",V10+1*W10) | Z10: =IF(COUNT(E10:S10)=0,"",SUM(IF(AND(E10>X10,E10<Y10),E10,0),IF(AND(F10>X10,F10<Y10),F10,0),IF(AND(G10>X10,G10<Y10),G10,0),IF(AND(H10>X10,H10<Y10),H10,0),IF(AND(I10>X10,I10<Y10),I10,0),IF(AND(J10>X10,J10<Y10),J10,0),IF(AND(K10>X10,K10<Y10),K10,0),IF(AND(L10>X10,L10<Y10),L10,0),IF(AND(M10>X10,M10<Y10),M10,0),IF(AND(N10>X10,N10<Y10),N10,0),IF(AND(O10>X10,O10<Y10),O10,0),IF(AND(P10>X10,P10<Y10),P10,0),IF(AND(Q10>X10,Q10<Y10),Q10,0),IF(AND(R10>X10,R10<Y10),R10,0),IF(AND(S10>X10,S10<Y10),S10,0))/SUM(IF(AND(E10>X10,E10<Y10,E10<>0),1,0),IF(AND(F10>X10,F10<Y10,F10<>0),1,0),IF(AND(G10>X10,G10<Y10,G10<>0),1,0),IF(AND(H10>X10,H10<Y10,H10<>0),1,0),IF(AND(I10>X10,I10<Y10,I10<>0),1,0),IF(AND(J10>X10,J10<Y10,J10<>0),1,0),IF(AND(K10>X10,K10<Y10,K10<>0),1,0),IF(AND(L10>X10,L10<Y10,L10<>0),1,0),IF(AND(M10>X10,M10<Y10,M10<>0),1,0),IF(AND(N10>X10,N10<Y10,N10<>0),1,0),IF(AND(O10>X10,O10<Y10,O10<>0),1,0),IF(AND(P10>X10,P10<Y10,P10<>0),1,0),IF(AND(Q10>X10,Q10<Y10,Q10<>0),1,0),IF(AND(R10>X10,R10<Y10,R10<>0),1,0),IF(AND(S10>X10,S10<Y10,S10<>0),1,0))) | AA10: =IF(COUNT(E10:S10)=0,"",SUM(IF(AND(E10>X10,E10<Y10),E10,0),IF(AND(F10>X10,F10<Y10),F10,0),IF(AND(G10>X10,G10<Y10),G10,0),IF(AND(H10>X10,H10<Y10),H10,0),IF(AND(I10>X10,I10<Y10),I10,0),IF(AND(J10>X10,J10<Y10),J10,0),IF(AND(K10>X10,K10<Y10),K10,0),IF(AND(L10>X10,L10<Y10),L10,0),IF(AND(M10>X10,M10<Y10),M10,0),IF(AND(N10>X10,N10<Y10),N10,0),IF(AND(O10>X10,O10<Y10),O10,0),IF(AND(P10>X10,P10<Y10),P10,0),IF(AND(Q10>X10,Q10<Y10),Q10,0),IF(AND(R10>X10,R10<Y10),R10,0),IF(AND(S10>X10,S10<Y10),S10,0))) | AB10: =IF(COUNT(E10:S10)=0,"",SUMSQ(IF(AND(E10>X10,E10<Y10),E10,0),IF(AND(F10>X10,F10<Y10),F10,0),IF(AND(G10>X10,G10<Y10),G10,0),IF(AND(H10>X10,H10<Y10),H10,0),IF(AND(I10>X10,I10<Y10),I10,0),IF(AND(J10>X10,J10<Y10),J10,0),IF(AND(K10>X10,K10<Y10),K10,0),IF(AND(L10>X10,L10<Y10),L10,0),IF(AND(M10>X10,M10<Y10),M10,0),IF(AND(N10>X10,N10<Y10),N10,0),IF(AND(O10>X10,O10<Y10),O10,0),IF(AND(P10>X10,P10<Y10),P10,0),IF(AND(Q10>X10,Q10<Y10),Q10,0),IF(AND(R10>X10,R10<Y10),R10,0),IF(AND(S10>X10,S10<Y10),S10,0))) | AC10: =IF(COUNT(E10:S10)=0,"",POWER(40*SQRT(SUM(IF(AND(E10>X10,E10<Y10),1,0),IF(AND(F10>X10,F10<Y10),1,0),IF(AND(G10>X10,G10<Y10),1,0),IF(AND(H10>X10,H10<Y10),1,0),IF(AND(I10>X10,I10<Y10),1,0),IF(AND(J10>X10,J10<Y10),1,0),IF(AND(K10>X10,K10<Y10),1,0),IF(AND(L10>X10,L10<Y10),1,0),IF(AND(M10>X10,M10<Y10),1,0),IF(AND(N10>X10,N10<Y10),1,0),IF(AND(O10>X10,O10<Y10),1,0),IF(AND(P10>X10,P10<Y10),1,0),IF(AND(Q10>X10,Q10<Y10),1,0),IF(AND(R10>X10,R10<Y10),1,0),IF(AND(S10>X10,S10<Y10),1,0))*AB10-POWER(AA10,2))/AA10,2)) | AD10: 5 | AE10: =IF(SUM(INDIRECT(CHAR(COLUMN()+38)&(ROW()-5)*8-2&":"&CHAR(COLUMN()+38)&(ROW()-5)*8+5))=0,"",SUM(INDIRECT(CHAR(COLUMN()+38)&(ROW()-5)*8-2&":"&CHAR(COLUMN()+38)&(ROW()-5)*8+5))/INDIRECT("C"&(ROW()-5)*8-2)) | AF10: =IF(SUM(INDIRECT(CHAR(COLUMN()+38)&(ROW()-5)*8-2&":"&CHAR(COLUMN()+38)&(ROW()-5)*8+5))=0,"",SUM(INDIRECT(CHAR(COLUMN()+38)&(ROW()-5)*8-2&":"&CHAR(COLUMN()+38)&(ROW()-5)*8+5))/INDIRECT("C"&(ROW()-5)*8-2)) | AG10: =IF(SUM(INDIRECT(CHAR(COLUMN()+38)&(ROW()-5)*8-2&":"&CHAR(COLUMN()+38)&(ROW()-5)*8+5))=0,"",SUM(INDIRECT(CHAR(COLUMN()+38)&(ROW()-5)*8-2&":"&CHAR(COLUMN()+38)&(ROW()-5)*8+5))/INDIRECT("C"&(ROW()-5)*8-2)) | AH10: =IF(SUM(INDIRECT(CHAR(COLUMN()+38)&(ROW()-5)*8-2&":"&CHAR(COLUMN()+38)&(ROW()-5)*8+5))=0,"",SUM(INDIRECT(CHAR(COLUMN()+38)&(ROW()-5)*8-2&":"&CHAR(COLUMN()+38)&(ROW()-5)*8+5))/INDIRECT("C"&(ROW()-5)*8-2)) | AI10: =IF(SUM(INDIRECT(CHAR(COLUMN()+38)&(ROW()-5)*8-2&":"&CHAR(COLUMN()+38)&(ROW()-5)*8+5))=0,"",SUM(INDIRECT(CHAR(COLUMN()+38)&(ROW()-5)*8-2&":"&CHAR(COLUMN()+38)&(ROW()-5)*8+5))/INDIRECT("C"&(ROW()-5)*8-2)) | AJ10: =IF(SUM(INDIRECT(CHAR(COLUMN()+38)&(ROW()-5)*8-2&":"&CHAR(COLUMN()+38)&(ROW()-5)*8+5))=0,"",SUM(INDIRECT(CHAR(COLUMN()+38)&(ROW()-5)*8-2&":"&CHAR(COLUMN()+38)&(ROW()-5)*8+5))/INDIRECT("C"&(ROW()-5)*8-2)) | AK10: =IF(SUM(INDIRECT(CHAR(COLUMN()+38)&(ROW()-5)*8-2&":"&CHAR(COLUMN()+38)&(ROW()-5)*8+5))=0,"",SUM(INDIRECT(CHAR(COLUMN()+38)&(ROW()-5)*8-2&":"&CHAR(COLUMN()+38)&(ROW()-5)*8+5))/INDIRECT("C"&(ROW()-5)*8-2)) | AL10: =IF(SUM(INDIRECT(CHAR(COLUMN()+38)&(ROW()-5)*8-2&":"&CHAR(COLUMN()+38)&(ROW()-5)*8+5))=0,"",SUM(INDIRECT(CHAR(COLUMN()+38)&(ROW()-5)*8-2&":"&CHAR(COLUMN()+38)&(ROW()-5)*8+5))/INDIRECT("C"&(ROW()-5)*8-2)) | ... AS10: =IF(SUM(INDIRECT(CHAR(COLUMN()+38)&(ROW()-5)*8-2&":"&CHAR(COLUMN()+38)&(ROW()-5)*8+5))=0,"",SUM(INDIRECT(CHAR(COLUMN()+38)&(ROW()-5)*8-2&":"&CHAR(COLUMN()+38)&(ROW()-5)*8+5))/INDIRECT("C"&(ROW()-5)*8-2)) | AT10: 5 | AU10: =IF(COUNT($AE10:$AS10)=0,"",PERCENTILE($AE10:$AS10,0.25)) | AV10: =IF(COUNT($AE10:$AS10)=0,"",MAX($AE10:$AS10)) | AW10: =IF(COUNT($AE10:$AS10)=0,"",MIN($AE10:$AS10)) | AX10: =IF(COUNT($AE10:$AS10)=0,"",PERCENTILE($AE10:$AS10,0.75))
T11: =IF(COUNT(E11:S11)=0,"",SUM(E11:S11)) | U11: =IF(COUNT(E11:S11)=0,"",SUMSQ(E11:S11)) | V11: =IF(COUNT(E11:S11)=0,"",AVERAGE(E11:S11)) | W11: =IF(COUNT(E11:S11)=0,"",STDEVP(E11:S11)) | X11: =IF(COUNT(E11:S11)=0,"",V11-1*W11) | Y11: =IF(COUNT(E11:S11)=0,"",V11+1*W11) | Z11: =IF(COUNT(E11:S11)=0,"",SUM(IF(AND(E11>X11,E11<Y11),E11,0),IF(AND(F11>X11,F11<Y11),F11,0),IF(AND(G11>X11,G11<Y11),G11,0),IF(AND(H11>X11,H11<Y11),H11,0),IF(AND(I11>X11,I11<Y11),I11,0),IF(AND(J11>X11,J11<Y11),J11,0),IF(AND(K11>X11,K11<Y11),K11,0),IF(AND(L11>X11,L11<Y11),L11,0),IF(AND(M11>X11,M11<Y11),M11,0),IF(AND(N11>X11,N11<Y11),N11,0),IF(AND(O11>X11,O11<Y11),O11,0),IF(AND(P11>X11,P11<Y11),P11,0),IF(AND(Q11>X11,Q11<Y11),Q11,0),IF(AND(R11>X11,R11<Y11),R11,0),IF(AND(S11>X11,S11<Y11),S11,0))/SUM(IF(AND(E11>X11,E11<Y11,E11<>0),1,0),IF(AND(F11>X11,F11<Y11,F11<>0),1,0),IF(AND(G11>X11,G11<Y11,G11<>0),1,0),IF(AND(H11>X11,H11<Y11,H11<>0),1,0),IF(AND(I11>X11,I11<Y11,I11<>0),1,0),IF(AND(J11>X11,J11<Y11,J11<>0),1,0),IF(AND(K11>X11,K11<Y11,K11<>0),1,0),IF(AND(L11>X11,L11<Y11,L11<>0),1,0),IF(AND(M11>X11,M11<Y11,M11<>0),1,0),IF(AND(N11>X11,N11<Y11,N11<>0),1,0),IF(AND(O11>X11,O11<Y11,O11<>0),1,0),IF(AND(P11>X11,P11<Y11,P11<>0),1,0),IF(AND(Q11>X11,Q11<Y11,Q11<>0),1,0),IF(AND(R11>X11,R11<Y11,R11<>0),1,0),IF(AND(S11>X11,S11<Y11,S11<>0),1,0))) | AA11: =IF(COUNT(E11:S11)=0,"",SUM(IF(AND(E11>X11,E11<Y11),E11,0),IF(AND(F11>X11,F11<Y11),F11,0),IF(AND(G11>X11,G11<Y11),G11,0),IF(AND(H11>X11,H11<Y11),H11,0),IF(AND(I11>X11,I11<Y11),I11,0),IF(AND(J11>X11,J11<Y11),J11,0),IF(AND(K11>X11,K11<Y11),K11,0),IF(AND(L11>X11,L11<Y11),L11,0),IF(AND(M11>X11,M11<Y11),M11,0),IF(AND(N11>X11,N11<Y11),N11,0),IF(AND(O11>X11,O11<Y11),O11,0),IF(AND(P11>X11,P11<Y11),P11,0),IF(AND(Q11>X11,Q11<Y11),Q11,0),IF(AND(R11>X11,R11<Y11),R11,0),IF(AND(S11>X11,S11<Y11),S11,0))) | AB11: =IF(COUNT(E11:S11)=0,"",SUMSQ(IF(AND(E11>X11,E11<Y11),E11,0),IF(AND(F11>X11,F11<Y11),F11,0),IF(AND(G11>X11,G11<Y11),G11,0),IF(AND(H11>X11,H11<Y11),H11,0),IF(AND(I11>X11,I11<Y11),I11,0),IF(AND(J11>X11,J11<Y11),J11,0),IF(AND(K11>X11,K11<Y11),K11,0),IF(AND(L11>X11,L11<Y11),L11,0),IF(AND(M11>X11,M11<Y11),M11,0),IF(AND(N11>X11,N11<Y11),N11,0),IF(AND(O11>X11,O11<Y11),O11,0),IF(AND(P11>X11,P11<Y11),P11,0),IF(AND(Q11>X11,Q11<Y11),Q11,0),IF(AND(R11>X11,R11<Y11),R11,0),IF(AND(S11>X11,S11<Y11),S11,0))) | AC11: =IF(COUNT(E11:S11)=0,"",POWER(40*SQRT(SUM(IF(AND(E11>X11,E11<Y11),1,0),IF(AND(F11>X11,F11<Y11),1,0),IF(AND(G11>X11,G11<Y11),1,0),IF(AND(H11>X11,H11<Y11),1,0),IF(AND(I11>X11,I11<Y11),1,0),IF(AND(J11>X11,J11<Y11),1,0),IF(AND(K11>X11,K11<Y11),1,0),IF(AND(L11>X11,L11<Y11),1,0),IF(AND(M11>X11,M11<Y11),1,0),IF(AND(N11>X11,N11<Y11),1,0),IF(AND(O11>X11,O11<Y11),1,0),IF(AND(P11>X11,P11<Y11),1,0),IF(AND(Q11>X11,Q11<Y11),1,0),IF(AND(R11>X11,R11<Y11),1,0),IF(AND(S11>X11,S11<Y11),1,0))*AB11-POWER(AA11,2))/AA11,2)) | AD11: 6 | AE11: =IF(SUM(INDIRECT(CHAR(COLUMN()+38)&(ROW()-5)*8-2&":"&CHAR(COLUMN()+38)&(ROW()-5)*8+5))=0,"",SUM(INDIRECT(CHAR(COLUMN()+38)&(ROW()-5)*8-2&":"&CHAR(COLUMN()+38)&(ROW()-5)*8+5))/INDIRECT("C"&(ROW()-5)*8-2)) | AF11: =IF(SUM(INDIRECT(CHAR(COLUMN()+38)&(ROW()-5)*8-2&":"&CHAR(COLUMN()+38)&(ROW()-5)*8+5))=0,"",SUM(INDIRECT(CHAR(COLUMN()+38)&(ROW()-5)*8-2&":"&CHAR(COLUMN()+38)&(ROW()-5)*8+5))/INDIRECT("C"&(ROW()-5)*8-2)) | AG11: =IF(SUM(INDIRECT(CHAR(COLUMN()+38)&(ROW()-5)*8-2&":"&CHAR(COLUMN()+38)&(ROW()-5)*8+5))=0,"",SUM(INDIRECT(CHAR(COLUMN()+38)&(ROW()-5)*8-2&":"&CHAR(COLUMN()+38)&(ROW()-5)*8+5))/INDIRECT("C"&(ROW()-5)*8-2)) | AH11: =IF(SUM(INDIRECT(CHAR(COLUMN()+38)&(ROW()-5)*8-2&":"&CHAR(COLUMN()+38)&(ROW()-5)*8+5))=0,"",SUM(INDIRECT(CHAR(COLUMN()+38)&(ROW()-5)*8-2&":"&CHAR(COLUMN()+38)&(ROW()-5)*8+5))/INDIRECT("C"&(ROW()-5)*8-2)) | AI11: =IF(SUM(INDIRECT(CHAR(COLUMN()+38)&(ROW()-5)*8-2&":"&CHAR(COLUMN()+38)&(ROW()-5)*8+5))=0,"",SUM(INDIRECT(CHAR(COLUMN()+38)&(ROW()-5)*8-2&":"&CHAR(COLUMN()+38)&(ROW()-5)*8+5))/INDIRECT("C"&(ROW()-5)*8-2)) | AJ11: =IF(SUM(INDIRECT(CHAR(COLUMN()+38)&(ROW()-5)*8-2&":"&CHAR(COLUMN()+38)&(ROW()-5)*8+5))=0,"",SUM(INDIRECT(CHAR(COLUMN()+38)&(ROW()-5)*8-2&":"&CHAR(COLUMN()+38)&(ROW()-5)*8+5))/INDIRECT("C"&(ROW()-5)*8-2)) | AK11: =IF(SUM(INDIRECT(CHAR(COLUMN()+38)&(ROW()-5)*8-2&":"&CHAR(COLUMN()+38)&(ROW()-5)*8+5))=0,"",SUM(INDIRECT(CHAR(COLUMN()+38)&(ROW()-5)*8-2&":"&CHAR(COLUMN()+38)&(ROW()-5)*8+5))/INDIRECT("C"&(ROW()-5)*8-2)) | AL11: =IF(SUM(INDIRECT(CHAR(COLUMN()+38)&(ROW()-5)*8-2&":"&CHAR(COLUMN()+38)&(ROW()-5)*8+5))=0,"",SUM(INDIRECT(CHAR(COLUMN()+38)&(ROW()-5)*8-2&":"&CHAR(COLUMN()+38)&(ROW()-5)*8+5))/INDIRECT("C"&(ROW()-5)*8-2)) | ... AS11: =IF(SUM(INDIRECT(CHAR(COLUMN()+38)&(ROW()-5)*8-2&":"&CHAR(COLUMN()+38)&(ROW()-5)*8+5))=0,"",SUM(INDIRECT(CHAR(COLUMN()+38)&(ROW()-5)*8-2&":"&CHAR(COLUMN()+38)&(ROW()-5)*8+5))/INDIRECT("C"&(ROW()-5)*8-2)) | AT11: 6 | AU11: =IF(COUNT($AE11:$AS11)=0,"",PERCENTILE($AE11:$AS11,0.25)) | AV11: =IF(COUNT($AE11:$AS11)=0,"",MAX($AE11:$AS11)) | AW11: =IF(COUNT($AE11:$AS11)=0,"",MIN($AE11:$AS11)) | AX11: =IF(COUNT($AE11:$AS11)=0,"",PERCENTILE($AE11:$AS11,0.75))
T12: =IF(COUNT(E12:S12)=0,"",SUM(E12:S12)) | U12: =IF(COUNT(E12:S12)=0,"",SUMSQ(E12:S12)) | V12: =IF(COUNT(E12:S12)=0,"",AVERAGE(E12:S12)) | W12: =IF(COUNT(E12:S12)=0,"",STDEVP(E12:S12)) | X12: =IF(COUNT(E12:S12)=0,"",V12-1*W12) | Y12: =IF(COUNT(E12:S12)=0,"",V12+1*W12) | Z12: =IF(COUNT(E12:S12)=0,"",SUM(IF(AND(E12>X12,E12<Y12),E12,0),IF(AND(F12>X12,F12<Y12),F12,0),IF(AND(G12>X12,G12<Y12),G12,0),IF(AND(H12>X12,H12<Y12),H12,0),IF(AND(I12>X12,I12<Y12),I12,0),IF(AND(J12>X12,J12<Y12),J12,0),IF(AND(K12>X12,K12<Y12),K12,0),IF(AND(L12>X12,L12<Y12),L12,0),IF(AND(M12>X12,M12<Y12),M12,0),IF(AND(N12>X12,N12<Y12),N12,0),IF(AND(O12>X12,O12<Y12),O12,0),IF(AND(P12>X12,P12<Y12),P12,0),IF(AND(Q12>X12,Q12<Y12),Q12,0),IF(AND(R12>X12,R12<Y12),R12,0),IF(AND(S12>X12,S12<Y12),S12,0))/SUM(IF(AND(E12>X12,E12<Y12,E12<>0),1,0),IF(AND(F12>X12,F12<Y12,F12<>0),1,0),IF(AND(G12>X12,G12<Y12,G12<>0),1,0),IF(AND(H12>X12,H12<Y12,H12<>0),1,0),IF(AND(I12>X12,I12<Y12,I12<>0),1,0),IF(AND(J12>X12,J12<Y12,J12<>0),1,0),IF(AND(K12>X12,K12<Y12,K12<>0),1,0),IF(AND(L12>X12,L12<Y12,L12<>0),1,0),IF(AND(M12>X12,M12<Y12,M12<>0),1,0),IF(AND(N12>X12,N12<Y12,N12<>0),1,0),IF(AND(O12>X12,O12<Y12,O12<>0),1,0),IF(AND(P12>X12,P12<Y12,P12<>0),1,0),IF(AND(Q12>X12,Q12<Y12,Q12<>0),1,0),IF(AND(R12>X12,R12<Y12,R12<>0),1,0),IF(AND(S12>X12,S12<Y12,S12<>0),1,0))) | AA12: =IF(COUNT(E12:S12)=0,"",SUM(IF(AND(E12>X12,E12<Y12),E12,0),IF(AND(F12>X12,F12<Y12),F12,0),IF(AND(G12>X12,G12<Y12),G12,0),IF(AND(H12>X12,H12<Y12),H12,0),IF(AND(I12>X12,I12<Y12),I12,0),IF(AND(J12>X12,J12<Y12),J12,0),IF(AND(K12>X12,K12<Y12),K12,0),IF(AND(L12>X12,L12<Y12),L12,0),IF(AND(M12>X12,M12<Y12),M12,0),IF(AND(N12>X12,N12<Y12),N12,0),IF(AND(O12>X12,O12<Y12),O12,0),IF(AND(P12>X12,P12<Y12),P12,0),IF(AND(Q12>X12,Q12<Y12),Q12,0),IF(AND(R12>X12,R12<Y12),R12,0),IF(AND(S12>X12,S12<Y12),S12,0))) | AB12: =IF(COUNT(E12:S12)=0,"",SUMSQ(IF(AND(E12>X12,E12<Y12),E12,0),IF(AND(F12>X12,F12<Y12),F12,0),IF(AND(G12>X12,G12<Y12),G12,0),IF(AND(H12>X12,H12<Y12),H12,0),IF(AND(I12>X12,I12<Y12),I12,0),IF(AND(J12>X12,J12<Y12),J12,0),IF(AND(K12>X12,K12<Y12),K12,0),IF(AND(L12>X12,L12<Y12),L12,0),IF(AND(M12>X12,M12<Y12),M12,0),IF(AND(N12>X12,N12<Y12),N12,0),IF(AND(O12>X12,O12<Y12),O12,0),IF(AND(P12>X12,P12<Y12),P12,0),IF(AND(Q12>X12,Q12<Y12),Q12,0),IF(AND(R12>X12,R12<Y12),R12,0),IF(AND(S12>X12,S12<Y12),S12,0))) | AC12: =IF(COUNT(E12:S12)=0,"",POWER(40*SQRT(SUM(IF(AND(E12>X12,E12<Y12),1,0),IF(AND(F12>X12,F12<Y12),1,0),IF(AND(G12>X12,G12<Y12),1,0),IF(AND(H12>X12,H12<Y12),1,0),IF(AND(I12>X12,I12<Y12),1,0),IF(AND(J12>X12,J12<Y12),1,0),IF(AND(K12>X12,K12<Y12),1,0),IF(AND(L12>X12,L12<Y12),1,0),IF(AND(M12>X12,M12<Y12),1,0),IF(AND(N12>X12,N12<Y12),1,0),IF(AND(O12>X12,O12<Y12),1,0),IF(AND(P12>X12,P12<Y12),1,0),IF(AND(Q12>X12,Q12<Y12),1,0),IF(AND(R12>X12,R12<Y12),1,0),IF(AND(S12>X12,S12<Y12),1,0))*AB12-POWER(AA12,2))/AA12,2)) | AD12: 7 | AE12: =IF(SUM(INDIRECT(CHAR(COLUMN()+38)&(ROW()-5)*8-2&":"&CHAR(COLUMN()+38)&(ROW()-5)*8+5))=0,"",SUM(INDIRECT(CHAR(COLUMN()+38)&(ROW()-5)*8-2&":"&CHAR(COLUMN()+38)&(ROW()-5)*8+5))/INDIRECT("C"&(ROW()-5)*8-2)) | AF12: =IF(SUM(INDIRECT(CHAR(COLUMN()+38)&(ROW()-5)*8-2&":"&CHAR(COLUMN()+38)&(ROW()-5)*8+5))=0,"",SUM(INDIRECT(CHAR(COLUMN()+38)&(ROW()-5)*8-2&":"&CHAR(COLUMN()+38)&(ROW()-5)*8+5))/INDIRECT("C"&(ROW()-5)*8-2)) | AG12: =IF(SUM(INDIRECT(CHAR(COLUMN()+38)&(ROW()-5)*8-2&":"&CHAR(COLUMN()+38)&(ROW()-5)*8+5))=0,"",SUM(INDIRECT(CHAR(COLUMN()+38)&(ROW()-5)*8-2&":"&CHAR(COLUMN()+38)&(ROW()-5)*8+5))/INDIRECT("C"&(ROW()-5)*8-2)) | AH12: =IF(SUM(INDIRECT(CHAR(COLUMN()+38)&(ROW()-5)*8-2&":"&CHAR(COLUMN()+38)&(ROW()-5)*8+5))=0,"",SUM(INDIRECT(CHAR(COLUMN()+38)&(ROW()-5)*8-2&":"&CHAR(COLUMN()+38)&(ROW()-5)*8+5))/INDIRECT("C"&(ROW()-5)*8-2)) | AI12: =IF(SUM(INDIRECT(CHAR(COLUMN()+38)&(ROW()-5)*8-2&":"&CHAR(COLUMN()+38)&(ROW()-5)*8+5))=0,"",SUM(INDIRECT(CHAR(COLUMN()+38)&(ROW()-5)*8-2&":"&CHAR(COLUMN()+38)&(ROW()-5)*8+5))/INDIRECT("C"&(ROW()-5)*8-2)) | AJ12: =IF(SUM(INDIRECT(CHAR(COLUMN()+38)&(ROW()-5)*8-2&":"&CHAR(COLUMN()+38)&(ROW()-5)*8+5))=0,"",SUM(INDIRECT(CHAR(COLUMN()+38)&(ROW()-5)*8-2&":"&CHAR(COLUMN()+38)&(ROW()-5)*8+5))/INDIRECT("C"&(ROW()-5)*8-2)) | AK12: =IF(SUM(INDIRECT(CHAR(COLUMN()+38)&(ROW()-5)*8-2&":"&CHAR(COLUMN()+38)&(ROW()-5)*8+5))=0,"",SUM(INDIRECT(CHAR(COLUMN()+38)&(ROW()-5)*8-2&":"&CHAR(COLUMN()+38)&(ROW()-5)*8+5))/INDIRECT("C"&(ROW()-5)*8-2)) | AL12: =IF(SUM(INDIRECT(CHAR(COLUMN()+38)&(ROW()-5)*8-2&":"&CHAR(COLUMN()+38)&(ROW()-5)*8+5))=0,"",SUM(INDIRECT(CHAR(COLUMN()+38)&(ROW()-5)*8-2&":"&CHAR(COLUMN()+38)&(ROW()-5)*8+5))/INDIRECT("C"&(ROW()-5)*8-2)) | ... AS12: =IF(SUM(INDIRECT(CHAR(COLUMN()+38)&(ROW()-5)*8-2&":"&CHAR(COLUMN()+38)&(ROW()-5)*8+5))=0,"",SUM(INDIRECT(CHAR(COLUMN()+38)&(ROW()-5)*8-2&":"&CHAR(COLUMN()+38)&(ROW()-5)*8+5))/INDIRECT("C"&(ROW()-5)*8-2)) | AT12: 7 | AU12: =IF(COUNT($AE12:$AS12)=0,"",PERCENTILE($AE12:$AS12,0.25)) | AV12: =IF(COUNT($AE12:$AS12)=0,"",MAX($AE12:$AS12)) | AW12: =IF(COUNT($AE12:$AS12)=0,"",MIN($AE12:$AS12)) | AX12: =IF(COUNT($AE12:$AS12)=0,"",PERCENTILE($AE12:$AS12,0.75))
T13: =IF(COUNT(E13:S13)=0,"",SUM(E13:S13)) | U13: =IF(COUNT(E13:S13)=0,"",SUMSQ(E13:S13)) | V13: =IF(COUNT(E13:S13)=0,"",AVERAGE(E13:S13)) | W13: =IF(COUNT(E13:S13)=0,"",STDEVP(E13:S13)) | X13: =IF(COUNT(E13:S13)=0,"",V13-1*W13) | Y13: =IF(COUNT(E13:S13)=0,"",V13+1*W13) | AA13: =IF(COUNT(E13:S13)=0,"",SUM(IF(AND(E13>X13,E13<Y13),E13,0),IF(AND(F13>X13,F13<Y13),F13,0),IF(AND(G13>X13,G13<Y13),G13,0),IF(AND(H13>X13,H13<Y13),H13,0),IF(AND(I13>X13,I13<Y13),I13,0),IF(AND(J13>X13,J13<Y13),J13,0),IF(AND(K13>X13,K13<Y13),K13,0),IF(AND(L13>X13,L13<Y13),L13,0),IF(AND(M13>X13,M13<Y13),M13,0),IF(AND(N13>X13,N13<Y13),N13,0),IF(AND(O13>X13,O13<Y13),O13,0),IF(AND(P13>X13,P13<Y13),P13,0),IF(AND(Q13>X13,Q13<Y13),Q13,0),IF(AND(R13>X13,R13<Y13),R13,0),IF(AND(S13>X13,S13<Y13),S13,0))) | AB13: =IF(COUNT(E13:S13)=0,"",SUMSQ(IF(AND(E13>X13,E13<Y13),E13,0),IF(AND(F13>X13,F13<Y13),F13,0),IF(AND(G13>X13,G13<Y13),G13,0),IF(AND(H13>X13,H13<Y13),H13,0),IF(AND(I13>X13,I13<Y13),I13,0),IF(AND(J13>X13,J13<Y13),J13,0),IF(AND(K13>X13,K13<Y13),K13,0),IF(AND(L13>X13,L13<Y13),L13,0),IF(AND(M13>X13,M13<Y13),M13,0),IF(AND(N13>X13,N13<Y13),N13,0),IF(AND(O13>X13,O13<Y13),O13,0),IF(AND(P13>X13,P13<Y13),P13,0),IF(AND(Q13>X13,Q13<Y13),Q13,0),IF(AND(R13>X13,R13<Y13),R13,0),IF(AND(S13>X13,S13<Y13),S13,0))) | AC13: =IF(COUNT(E13:S13)=0,"",POWER(40*SQRT(SUM(IF(AND(E13>X13,E13<Y13),1,0),IF(AND(F13>X13,F13<Y13),1,0),IF(AND(G13>X13,G13<Y13),1,0),IF(AND(H13>X13,H13<Y13),1,0),IF(AND(I13>X13,I13<Y13),1,0),IF(AND(J13>X13,J13<Y13),1,0),IF(AND(K13>X13,K13<Y13),1,0),IF(AND(L13>X13,L13<Y13),1,0),IF(AND(M13>X13,M13<Y13),1,0),IF(AND(N13>X13,N13<Y13),1,0),IF(AND(O13>X13,O13<Y13),1,0),IF(AND(P13>X13,P13<Y13),1,0),IF(AND(Q13>X13,Q13<Y13),1,0),IF(AND(R13>X13,R13<Y13),1,0),IF(AND(S13>X13,S13<Y13),1,0))*AB13-POWER(AA13,2))/AA13,2)) | AD13: 8 | AE13: =IF(SUM(INDIRECT(CHAR(COLUMN()+38)&(ROW()-5)*8-2&":"&CHAR(COLUMN()+38)&(ROW()-5)*8+5))=0,"",SUM(INDIRECT(CHAR(COLUMN()+38)&(ROW()-5)*8-2&":"&CHAR(COLUMN()+38)&(ROW()-5)*8+5))/INDIRECT("C"&(ROW()-5)*8-2)) | AF13: =IF(SUM(INDIRECT(CHAR(COLUMN()+38)&(ROW()-5)*8-2&":"&CHAR(COLUMN()+38)&(ROW()-5)*8+5))=0,"",SUM(INDIRECT(CHAR(COLUMN()+38)&(ROW()-5)*8-2&":"&CHAR(COLUMN()+38)&(ROW()-5)*8+5))/INDIRECT("C"&(ROW()-5)*8-2)) | AG13: =IF(SUM(INDIRECT(CHAR(COLUMN()+38)&(ROW()-5)*8-2&":"&CHAR(COLUMN()+38)&(ROW()-5)*8+5))=0,"",SUM(INDIRECT(CHAR(COLUMN()+38)&(ROW()-5)*8-2&":"&CHAR(COLUMN()+38)&(ROW()-5)*8+5))/INDIRECT("C"&(ROW()-5)*8-2)) | AH13: =IF(SUM(INDIRECT(CHAR(COLUMN()+38)&(ROW()-5)*8-2&":"&CHAR(COLUMN()+38)&(ROW()-5)*8+5))=0,"",SUM(INDIRECT(CHAR(COLUMN()+38)&(ROW()-5)*8-2&":"&CHAR(COLUMN()+38)&(ROW()-5)*8+5))/INDIRECT("C"&(ROW()-5)*8-2)) | AI13: =IF(SUM(INDIRECT(CHAR(COLUMN()+38)&(ROW()-5)*8-2&":"&CHAR(COLUMN()+38)&(ROW()-5)*8+5))=0,"",SUM(INDIRECT(CHAR(COLUMN()+38)&(ROW()-5)*8-2&":"&CHAR(COLUMN()+38)&(ROW()-5)*8+5))/INDIRECT("C"&(ROW()-5)*8-2)) | AJ13: =IF(SUM(INDIRECT(CHAR(COLUMN()+38)&(ROW()-5)*8-2&":"&CHAR(COLUMN()+38)&(ROW()-5)*8+5))=0,"",SUM(INDIRECT(CHAR(COLUMN()+38)&(ROW()-5)*8-2&":"&CHAR(COLUMN()+38)&(ROW()-5)*8+5))/INDIRECT("C"&(ROW()-5)*8-2)) | AK13: =IF(SUM(INDIRECT(CHAR(COLUMN()+38)&(ROW()-5)*8-2&":"&CHAR(COLUMN()+38)&(ROW()-5)*8+5))=0,"",SUM(INDIRECT(CHAR(COLUMN()+38)&(ROW()-5)*8-2&":"&CHAR(COLUMN()+38)&(ROW()-5)*8+5))/INDIRECT("C"&(ROW()-5)*8-2)) | AL13: =IF(SUM(INDIRECT(CHAR(COLUMN()+38)&(ROW()-5)*8-2&":"&CHAR(COLUMN()+38)&(ROW()-5)*8+5))=0,"",SUM(INDIRECT(CHAR(COLUMN()+38)&(ROW()-5)*8-2&":"&CHAR(COLUMN()+38)&(ROW()-5)*8+5))/INDIRECT("C"&(ROW()-5)*8-2)) | ... AS13: =IF(SUM(INDIRECT(CHAR(COLUMN()+38)&(ROW()-5)*8-2&":"&CHAR(COLUMN()+38)&(ROW()-5)*8+5))=0,"",SUM(INDIRECT(CHAR(COLUMN()+38)&(ROW()-5)*8-2&":"&CHAR(COLUMN()+38)&(ROW()-5)*8+5))/INDIRECT("C"&(ROW()-5)*8-2)) | AT13: 8 | AU13: =IF(COUNT($AE13:$AS13)=0,"",PERCENTILE($AE13:$AS13,0.25)) | AV13: =IF(COUNT($AE13:$AS13)=0,"",MAX($AE13:$AS13)) | AW13: =IF(COUNT($AE13:$AS13)=0,"",MIN($AE13:$AS13)) | AX13: =IF(COUNT($AE13:$AS13)=0,"",PERCENTILE($AE13:$AS13,0.75))
A14: 2 | T14: =IF(COUNT(E14:S14)=0,"",SUM(E14:S14)) | U14: =IF(COUNT(E14:S14)=0,"",SUMSQ(E14:S14)) | V14: =IF(COUNT(E14:S14)=0,"",AVERAGE(E14:S14)) | W14: =IF(COUNT(E14:S14)=0,"",STDEVP(E14:S14)) | X14: =IF(COUNT(E14:S14)=0,"",V14-1*W14) | Y14: =IF(COUNT(E14:S14)=0,"",V14+1*W14) | Z14: =IF(COUNT(E14:S14)=0,"",SUM(IF(AND(E14>X14,E14<Y14),E14,0),IF(AND(F14>X14,F14<Y14),F14,0),IF(AND(G14>X14,G14<Y14),G14,0),IF(AND(H14>X14,H14<Y14),H14,0),IF(AND(I14>X14,I14<Y14),I14,0),IF(AND(J14>X14,J14<Y14),J14,0),IF(AND(K14>X14,K14<Y14),K14,0),IF(AND(L14>X14,L14<Y14),L14,0),IF(AND(M14>X14,M14<Y14),M14,0),IF(AND(N14>X14,N14<Y14),N14,0),IF(AND(O14>X14,O14<Y14),O14,0),IF(AND(P14>X14,P14<Y14),P14,0),IF(AND(Q14>X14,Q14<Y14),Q14,0),IF(AND(R14>X14,R14<Y14),R14,0),IF(AND(S14>X14,S14<Y14),S14,0))/SUM(IF(AND(E14>X14,E14<Y14,E14<>0),1,0),IF(AND(F14>X14,F14<Y14,F14<>0),1,0),IF(AND(G14>X14,G14<Y14,G14<>0),1,0),IF(AND(H14>X14,H14<Y14,H14<>0),1,0),IF(AND(I14>X14,I14<Y14,I14<>0),1,0),IF(AND(J14>X14,J14<Y14,J14<>0),1,0),IF(AND(K14>X14,K14<Y14,K14<>0),1,0),IF(AND(L14>X14,L14<Y14,L14<>0),1,0),IF(AND(M14>X14,M14<Y14,M14<>0),1,0),IF(AND(N14>X14,N14<Y14,N14<>0),1,0),IF(AND(O14>X14,O14<Y14,O14<>0),1,0),IF(AND(P14>X14,P14<Y14,P14<>0),1,0),IF(AND(Q14>X14,Q14<Y14,Q14<>0),1,0),IF(AND(R14>X14,R14<Y14,R14<>0),1,0),IF(AND(S14>X14,S14<Y14,S14<>0),1,0))) | AA14: =IF(COUNT(E14:S14)=0,"",SUM(IF(AND(E14>X14,E14<Y14),E14,0),IF(AND(F14>X14,F14<Y14),F14,0),IF(AND(G14>X14,G14<Y14),G14,0),IF(AND(H14>X14,H14<Y14),H14,0),IF(AND(I14>X14,I14<Y14),I14,0),IF(AND(J14>X14,J14<Y14),J14,0),IF(AND(K14>X14,K14<Y14),K14,0),IF(AND(L14>X14,L14<Y14),L14,0),IF(AND(M14>X14,M14<Y14),M14,0),IF(AND(N14>X14,N14<Y14),N14,0),IF(AND(O14>X14,O14<Y14),O14,0),IF(AND(P14>X14,P14<Y14),P14,0),IF(AND(Q14>X14,Q14<Y14),Q14,0),IF(AND(R14>X14,R14<Y14),R14,0),IF(AND(S14>X14,S14<Y14),S14,0))) | AB14: =IF(COUNT(E14:S14)=0,"",SUMSQ(IF(AND(E14>X14,E14<Y14),E14,0),IF(AND(F14>X14,F14<Y14),F14,0),IF(AND(G14>X14,G14<Y14),G14,0),IF(AND(H14>X14,H14<Y14),H14,0),IF(AND(I14>X14,I14<Y14),I14,0),IF(AND(J14>X14,J14<Y14),J14,0),IF(AND(K14>X14,K14<Y14),K14,0),IF(AND(L14>X14,L14<Y14),L14,0),IF(AND(M14>X14,M14<Y14),M14,0),IF(AND(N14>X14,N14<Y14),N14,0),IF(AND(O14>X14,O14<Y14),O14,0),IF(AND(P14>X14,P14<Y14),P14,0),IF(AND(Q14>X14,Q14<Y14),Q14,0),IF(AND(R14>X14,R14<Y14),R14,0),IF(AND(S14>X14,S14<Y14),S14,0))) | AC14: =IF(COUNT(E14:S14)=0,"",POWER(40*SQRT(SUM(IF(AND(E14>X14,E14<Y14),1,0),IF(AND(F14>X14,F14<Y14),1,0),IF(AND(G14>X14,G14<Y14),1,0),IF(AND(H14>X14,H14<Y14),1,0),IF(AND(I14>X14,I14<Y14),1,0),IF(AND(J14>X14,J14<Y14),1,0),IF(AND(K14>X14,K14<Y14),1,0),IF(AND(L14>X14,L14<Y14),1,0),IF(AND(M14>X14,M14<Y14),1,0),IF(AND(N14>X14,N14<Y14),1,0),IF(AND(O14>X14,O14<Y14),1,0),IF(AND(P14>X14,P14<Y14),1,0),IF(AND(Q14>X14,Q14<Y14),1,0),IF(AND(R14>X14,R14<Y14),1,0),IF(AND(S14>X14,S14<Y14),1,0))*AB14-POWER(AA14,2))/AA14,2)) | AD14: 9 | AE14: =IF(SUM(INDIRECT(CHAR(COLUMN()+38)&(ROW()-5)*8-2&":"&CHAR(COLUMN()+38)&(ROW()-5)*8+5))=0,"",SUM(INDIRECT(CHAR(COLUMN()+38)&(ROW()-5)*8-2&":"&CHAR(COLUMN()+38)&(ROW()-5)*8+5))/INDIRECT("C"&(ROW()-5)*8-2)) | AF14: =IF(SUM(INDIRECT(CHAR(COLUMN()+38)&(ROW()-5)*8-2&":"&CHAR(COLUMN()+38)&(ROW()-5)*8+5))=0,"",SUM(INDIRECT(CHAR(COLUMN()+38)&(ROW()-5)*8-2&":"&CHAR(COLUMN()+38)&(ROW()-5)*8+5))/INDIRECT("C"&(ROW()-5)*8-2)) | AG14: =IF(SUM(INDIRECT(CHAR(COLUMN()+38)&(ROW()-5)*8-2&":"&CHAR(COLUMN()+38)&(ROW()-5)*8+5))=0,"",SUM(INDIRECT(CHAR(COLUMN()+38)&(ROW()-5)*8-2&":"&CHAR(COLUMN()+38)&(ROW()-5)*8+5))/INDIRECT("C"&(ROW()-5)*8-2)) | AH14: =IF(SUM(INDIRECT(CHAR(COLUMN()+38)&(ROW()-5)*8-2&":"&CHAR(COLUMN()+38)&(ROW()-5)*8+5))=0,"",SUM(INDIRECT(CHAR(COLUMN()+38)&(ROW()-5)*8-2&":"&CHAR(COLUMN()+38)&(ROW()-5)*8+5))/INDIRECT("C"&(ROW()-5)*8-2)) | AI14: =IF(SUM(INDIRECT(CHAR(COLUMN()+38)&(ROW()-5)*8-2&":"&CHAR(COLUMN()+38)&(ROW()-5)*8+5))=0,"",SUM(INDIRECT(CHAR(COLUMN()+38)&(ROW()-5)*8-2&":"&CHAR(COLUMN()+38)&(ROW()-5)*8+5))/INDIRECT("C"&(ROW()-5)*8-2)) | AJ14: =IF(SUM(INDIRECT(CHAR(COLUMN()+38)&(ROW()-5)*8-2&":"&CHAR(COLUMN()+38)&(ROW()-5)*8+5))=0,"",SUM(INDIRECT(CHAR(COLUMN()+38)&(ROW()-5)*8-2&":"&CHAR(COLUMN()+38)&(ROW()-5)*8+5))/INDIRECT("C"&(ROW()-5)*8-2)) | AK14: =IF(SUM(INDIRECT(CHAR(COLUMN()+38)&(ROW()-5)*8-2&":"&CHAR(COLUMN()+38)&(ROW()-5)*8+5))=0,"",SUM(INDIRECT(CHAR(COLUMN()+38)&(ROW()-5)*8-2&":"&CHAR(COLUMN()+38)&(ROW()-5)*8+5))/INDIRECT("C"&(ROW()-5)*8-2)) | AL14: =IF(SUM(INDIRECT(CHAR(COLUMN()+38)&(ROW()-5)*8-2&":"&CHAR(COLUMN()+38)&(ROW()-5)*8+5))=0,"",SUM(INDIRECT(CHAR(COLUMN()+38)&(ROW()-5)*8-2&":"&CHAR(COLUMN()+38)&(ROW()-5)*8+5))/INDIRECT("C"&(ROW()-5)*8-2)) | ... AS14: =IF(SUM(INDIRECT(CHAR(COLUMN()+38)&(ROW()-5)*8-2&":"&CHAR(COLUMN()+38)&(ROW()-5)*8+5))=0,"",SUM(INDIRECT(CHAR(COLUMN()+38)&(ROW()-5)*8-2&":"&CHAR(COLUMN()+38)&(ROW()-5)*8+5))/INDIRECT("C"&(ROW()-5)*8-2)) | AT14: 9 | AU14: =IF(COUNT($AE14:$AS14)=0,"",PERCENTILE($AE14:$AS14,0.25)) | AV14: =IF(COUNT($AE14:$AS14)=0,"",MAX($AE14:$AS14)) | AW14: =IF(COUNT($AE14:$AS14)=0,"",MIN($AE14:$AS14)) | AX14: =IF(COUNT($AE14:$AS14)=0,"",PERCENTILE($AE14:$AS14,0.75))
T15: =IF(COUNT(E15:S15)=0,"",SUM(E15:S15)) | U15: =IF(COUNT(E15:S15)=0,"",SUMSQ(E15:S15)) | V15: =IF(COUNT(E15:S15)=0,"",AVERAGE(E15:S15)) | W15: =IF(COUNT(E15:S15)=0,"",STDEVP(E15:S15)) | X15: =IF(COUNT(E15:S15)=0,"",V15-1*W15) | Y15: =IF(COUNT(E15:S15)=0,"",V15+1*W15) | Z15: =IF(COUNT(E15:S15)=0,"",SUM(IF(AND(E15>X15,E15<Y15),E15,0),IF(AND(F15>X15,F15<Y15),F15,0),IF(AND(G15>X15,G15<Y15),G15,0),IF(AND(H15>X15,H15<Y15),H15,0),IF(AND(I15>X15,I15<Y15),I15,0),IF(AND(J15>X15,J15<Y15),J15,0),IF(AND(K15>X15,K15<Y15),K15,0),IF(AND(L15>X15,L15<Y15),L15,0),IF(AND(M15>X15,M15<Y15),M15,0),IF(AND(N15>X15,N15<Y15),N15,0),IF(AND(O15>X15,O15<Y15),O15,0),IF(AND(P15>X15,P15<Y15),P15,0),IF(AND(Q15>X15,Q15<Y15),Q15,0),IF(AND(R15>X15,R15<Y15),R15,0),IF(AND(S15>X15,S15<Y15),S15,0))/SUM(IF(AND(E15>X15,E15<Y15,E15<>0),1,0),IF(AND(F15>X15,F15<Y15,F15<>0),1,0),IF(AND(G15>X15,G15<Y15,G15<>0),1,0),IF(AND(H15>X15,H15<Y15,H15<>0),1,0),IF(AND(I15>X15,I15<Y15,I15<>0),1,0),IF(AND(J15>X15,J15<Y15,J15<>0),1,0),IF(AND(K15>X15,K15<Y15,K15<>0),1,0),IF(AND(L15>X15,L15<Y15,L15<>0),1,0),IF(AND(M15>X15,M15<Y15,M15<>0),1,0),IF(AND(N15>X15,N15<Y15,N15<>0),1,0),IF(AND(O15>X15,O15<Y15,O15<>0),1,0),IF(AND(P15>X15,P15<Y15,P15<>0),1,0),IF(AND(Q15>X15,Q15<Y15,Q15<>0),1,0),IF(AND(R15>X15,R15<Y15,R15<>0),1,0),IF(AND(S15>X15,S15<Y15,S15<>0),1,0))) | AA15: =IF(COUNT(E15:S15)=0,"",SUM(IF(AND(E15>X15,E15<Y15),E15,0),IF(AND(F15>X15,F15<Y15),F15,0),IF(AND(G15>X15,G15<Y15),G15,0),IF(AND(H15>X15,H15<Y15),H15,0),IF(AND(I15>X15,I15<Y15),I15,0),IF(AND(J15>X15,J15<Y15),J15,0),IF(AND(K15>X15,K15<Y15),K15,0),IF(AND(L15>X15,L15<Y15),L15,0),IF(AND(M15>X15,M15<Y15),M15,0),IF(AND(N15>X15,N15<Y15),N15,0),IF(AND(O15>X15,O15<Y15),O15,0),IF(AND(P15>X15,P15<Y15),P15,0),IF(AND(Q15>X15,Q15<Y15),Q15,0),IF(AND(R15>X15,R15<Y15),R15,0),IF(AND(S15>X15,S15<Y15),S15,0))) | AB15: =IF(COUNT(E15:S15)=0,"",SUMSQ(IF(AND(E15>X15,E15<Y15),E15,0),IF(AND(F15>X15,F15<Y15),F15,0),IF(AND(G15>X15,G15<Y15),G15,0),IF(AND(H15>X15,H15<Y15),H15,0),IF(AND(I15>X15,I15<Y15),I15,0),IF(AND(J15>X15,J15<Y15),J15,0),IF(AND(K15>X15,K15<Y15),K15,0),IF(AND(L15>X15,L15<Y15),L15,0),IF(AND(M15>X15,M15<Y15),M15,0),IF(AND(N15>X15,N15<Y15),N15,0),IF(AND(O15>X15,O15<Y15),O15,0),IF(AND(P15>X15,P15<Y15),P15,0),IF(AND(Q15>X15,Q15<Y15),Q15,0),IF(AND(R15>X15,R15<Y15),R15,0),IF(AND(S15>X15,S15<Y15),S15,0))) | AC15: =IF(COUNT(E15:S15)=0,"",POWER(40*SQRT(SUM(IF(AND(E15>X15,E15<Y15),1,0),IF(AND(F15>X15,F15<Y15),1,0),IF(AND(G15>X15,G15<Y15),1,0),IF(AND(H15>X15,H15<Y15),1,0),IF(AND(I15>X15,I15<Y15),1,0),IF(AND(J15>X15,J15<Y15),1,0),IF(AND(K15>X15,K15<Y15),1,0),IF(AND(L15>X15,L15<Y15),1,0),IF(AND(M15>X15,M15<Y15),1,0),IF(AND(N15>X15,N15<Y15),1,0),IF(AND(O15>X15,O15<Y15),1,0),IF(AND(P15>X15,P15<Y15),1,0),IF(AND(Q15>X15,Q15<Y15),1,0),IF(AND(R15>X15,R15<Y15),1,0),IF(AND(S15>X15,S15<Y15),1,0))*AB15-POWER(AA15,2))/AA15,2)) | AD15: 10 | AE15: =IF(SUM(INDIRECT(CHAR(COLUMN()+38)&(ROW()-5)*8-2&":"&CHAR(COLUMN()+38)&(ROW()-5)*8+5))=0,"",SUM(INDIRECT(CHAR(COLUMN()+38)&(ROW()-5)*8-2&":"&CHAR(COLUMN()+38)&(ROW()-5)*8+5))/INDIRECT("C"&(ROW()-5)*8-2)) | AF15: =IF(SUM(INDIRECT(CHAR(COLUMN()+38)&(ROW()-5)*8-2&":"&CHAR(COLUMN()+38)&(ROW()-5)*8+5))=0,"",SUM(INDIRECT(CHAR(COLUMN()+38)&(ROW()-5)*8-2&":"&CHAR(COLUMN()+38)&(ROW()-5)*8+5))/INDIRECT("C"&(ROW()-5)*8-2)) | AG15: =IF(SUM(INDIRECT(CHAR(COLUMN()+38)&(ROW()-5)*8-2&":"&CHAR(COLUMN()+38)&(ROW()-5)*8+5))=0,"",SUM(INDIRECT(CHAR(COLUMN()+38)&(ROW()-5)*8-2&":"&CHAR(COLUMN()+38)&(ROW()-5)*8+5))/INDIRECT("C"&(ROW()-5)*8-2)) | AH15: =IF(SUM(INDIRECT(CHAR(COLUMN()+38)&(ROW()-5)*8-2&":"&CHAR(COLUMN()+38)&(ROW()-5)*8+5))=0,"",SUM(INDIRECT(CHAR(COLUMN()+38)&(ROW()-5)*8-2&":"&CHAR(COLUMN()+38)&(ROW()-5)*8+5))/INDIRECT("C"&(ROW()-5)*8-2)) | AI15: =IF(SUM(INDIRECT(CHAR(COLUMN()+38)&(ROW()-5)*8-2&":"&CHAR(COLUMN()+38)&(ROW()-5)*8+5))=0,"",SUM(INDIRECT(CHAR(COLUMN()+38)&(ROW()-5)*8-2&":"&CHAR(COLUMN()+38)&(ROW()-5)*8+5))/INDIRECT("C"&(ROW()-5)*8-2)) | AJ15: =IF(SUM(INDIRECT(CHAR(COLUMN()+38)&(ROW()-5)*8-2&":"&CHAR(COLUMN()+38)&(ROW()-5)*8+5))=0,"",SUM(INDIRECT(CHAR(COLUMN()+38)&(ROW()-5)*8-2&":"&CHAR(COLUMN()+38)&(ROW()-5)*8+5))/INDIRECT("C"&(ROW()-5)*8-2)) | AK15: =IF(SUM(INDIRECT(CHAR(COLUMN()+38)&(ROW()-5)*8-2&":"&CHAR(COLUMN()+38)&(ROW()-5)*8+5))=0,"",SUM(INDIRECT(CHAR(COLUMN()+38)&(ROW()-5)*8-2&":"&CHAR(COLUMN()+38)&(ROW()-5)*8+5))/INDIRECT("C"&(ROW()-5)*8-2)) | AL15: =IF(SUM(INDIRECT(CHAR(COLUMN()+38)&(ROW()-5)*8-2&":"&CHAR(COLUMN()+38)&(ROW()-5)*8+5))=0,"",SUM(INDIRECT(CHAR(COLUMN()+38)&(ROW()-5)*8-2&":"&CHAR(COLUMN()+38)&(ROW()-5)*8+5))/INDIRECT("C"&(ROW()-5)*8-2)) | ... AS15: =IF(SUM(INDIRECT(CHAR(COLUMN()+38)&(ROW()-5)*8-2&":"&CHAR(COLUMN()+38)&(ROW()-5)*8+5))=0,"",SUM(INDIRECT(CHAR(COLUMN()+38)&(ROW()-5)*8-2&":"&CHAR(COLUMN()+38)&(ROW()-5)*8+5))/INDIRECT("C"&(ROW()-5)*8-2)) | AT15: 10 | AU15: =IF(COUNT($AE15:$AS15)=0,"",PERCENTILE($AE15:$AS15,0.25)) | AV15: =IF(COUNT($AE15:$AS15)=0,"",MAX($AE15:$AS15)) | AW15: =IF(COUNT($AE15:$AS15)=0,"",MIN($AE15:$AS15)) | AX15: =IF(COUNT($AE15:$AS15)=0,"",PERCENTILE($AE15:$AS15,0.75))
T16: =IF(COUNT(E16:S16)=0,"",SUM(E16:S16)) | U16: =IF(COUNT(E16:S16)=0,"",SUMSQ(E16:S16)) | V16: =IF(COUNT(E16:S16)=0,"",AVERAGE(E16:S16)) | W16: =IF(COUNT(E16:S16)=0,"",STDEVP(E16:S16)) | X16: =IF(COUNT(E16:S16)=0,"",V16-1*W16) | Y16: =IF(COUNT(E16:S16)=0,"",V16+1*W16) | Z16: =IF(COUNT(E16:S16)=0,"",SUM(IF(AND(E16>X16,E16<Y16),E16,0),IF(AND(F16>X16,F16<Y16),F16,0),IF(AND(G16>X16,G16<Y16),G16,0),IF(AND(H16>X16,H16<Y16),H16,0),IF(AND(I16>X16,I16<Y16),I16,0),IF(AND(J16>X16,J16<Y16),J16,0),IF(AND(K16>X16,K16<Y16),K16,0),IF(AND(L16>X16,L16<Y16),L16,0),IF(AND(M16>X16,M16<Y16),M16,0),IF(AND(N16>X16,N16<Y16),N16,0),IF(AND(O16>X16,O16<Y16),O16,0),IF(AND(P16>X16,P16<Y16),P16,0),IF(AND(Q16>X16,Q16<Y16),Q16,0),IF(AND(R16>X16,R16<Y16),R16,0),IF(AND(S16>X16,S16<Y16),S16,0))/SUM(IF(AND(E16>X16,E16<Y16,E16<>0),1,0),IF(AND(F16>X16,F16<Y16,F16<>0),1,0),IF(AND(G16>X16,G16<Y16,G16<>0),1,0),IF(AND(H16>X16,H16<Y16,H16<>0),1,0),IF(AND(I16>X16,I16<Y16,I16<>0),1,0),IF(AND(J16>X16,J16<Y16,J16<>0),1,0),IF(AND(K16>X16,K16<Y16,K16<>0),1,0),IF(AND(L16>X16,L16<Y16,L16<>0),1,0),IF(AND(M16>X16,M16<Y16,M16<>0),1,0),IF(AND(N16>X16,N16<Y16,N16<>0),1,0),IF(AND(O16>X16,O16<Y16,O16<>0),1,0),IF(AND(P16>X16,P16<Y16,P16<>0),1,0),IF(AND(Q16>X16,Q16<Y16,Q16<>0),1,0),IF(AND(R16>X16,R16<Y16,R16<>0),1,0),IF(AND(S16>X16,S16<Y16,S16<>0),1,0))) | AA16: =IF(COUNT(E16:S16)=0,"",SUM(IF(AND(E16>X16,E16<Y16),E16,0),IF(AND(F16>X16,F16<Y16),F16,0),IF(AND(G16>X16,G16<Y16),G16,0),IF(AND(H16>X16,H16<Y16),H16,0),IF(AND(I16>X16,I16<Y16),I16,0),IF(AND(J16>X16,J16<Y16),J16,0),IF(AND(K16>X16,K16<Y16),K16,0),IF(AND(L16>X16,L16<Y16),L16,0),IF(AND(M16>X16,M16<Y16),M16,0),IF(AND(N16>X16,N16<Y16),N16,0),IF(AND(O16>X16,O16<Y16),O16,0),IF(AND(P16>X16,P16<Y16),P16,0),IF(AND(Q16>X16,Q16<Y16),Q16,0),IF(AND(R16>X16,R16<Y16),R16,0),IF(AND(S16>X16,S16<Y16),S16,0))) | AB16: =IF(COUNT(E16:S16)=0,"",SUMSQ(IF(AND(E16>X16,E16<Y16),E16,0),IF(AND(F16>X16,F16<Y16),F16,0),IF(AND(G16>X16,G16<Y16),G16,0),IF(AND(H16>X16,H16<Y16),H16,0),IF(AND(I16>X16,I16<Y16),I16,0),IF(AND(J16>X16,J16<Y16),J16,0),IF(AND(K16>X16,K16<Y16),K16,0),IF(AND(L16>X16,L16<Y16),L16,0),IF(AND(M16>X16,M16<Y16),M16,0),IF(AND(N16>X16,N16<Y16),N16,0),IF(AND(O16>X16,O16<Y16),O16,0),IF(AND(P16>X16,P16<Y16),P16,0),IF(AND(Q16>X16,Q16<Y16),Q16,0),IF(AND(R16>X16,R16<Y16),R16,0),IF(AND(S16>X16,S16<Y16),S16,0))) | AC16: =IF(COUNT(E16:S16)=0,"",POWER(40*SQRT(SUM(IF(AND(E16>X16,E16<Y16),1,0),IF(AND(F16>X16,F16<Y16),1,0),IF(AND(G16>X16,G16<Y16),1,0),IF(AND(H16>X16,H16<Y16),1,0),IF(AND(I16>X16,I16<Y16),1,0),IF(AND(J16>X16,J16<Y16),1,0),IF(AND(K16>X16,K16<Y16),1,0),IF(AND(L16>X16,L16<Y16),1,0),IF(AND(M16>X16,M16<Y16),1,0),IF(AND(N16>X16,N16<Y16),1,0),IF(AND(O16>X16,O16<Y16),1,0),IF(AND(P16>X16,P16<Y16),1,0),IF(AND(Q16>X16,Q16<Y16),1,0),IF(AND(R16>X16,R16<Y16),1,0),IF(AND(S16>X16,S16<Y16),1,0))*AB16-POWER(AA16,2))/AA16,2)) | AD16: 11 | AE16: =IF(SUM(INDIRECT(CHAR(COLUMN()+38)&(ROW()-5)*8-2&":"&CHAR(COLUMN()+38)&(ROW()-5)*8+5))=0,"",SUM(INDIRECT(CHAR(COLUMN()+38)&(ROW()-5)*8-2&":"&CHAR(COLUMN()+38)&(ROW()-5)*8+5))/INDIRECT("C"&(ROW()-5)*8-2)) | AF16: =IF(SUM(INDIRECT(CHAR(COLUMN()+38)&(ROW()-5)*8-2&":"&CHAR(COLUMN()+38)&(ROW()-5)*8+5))=0,"",SUM(INDIRECT(CHAR(COLUMN()+38)&(ROW()-5)*8-2&":"&CHAR(COLUMN()+38)&(ROW()-5)*8+5))/INDIRECT("C"&(ROW()-5)*8-2)) | AG16: =IF(SUM(INDIRECT(CHAR(COLUMN()+38)&(ROW()-5)*8-2&":"&CHAR(COLUMN()+38)&(ROW()-5)*8+5))=0,"",SUM(INDIRECT(CHAR(COLUMN()+38)&(ROW()-5)*8-2&":"&CHAR(COLUMN()+38)&(ROW()-5)*8+5))/INDIRECT("C"&(ROW()-5)*8-2)) | AH16: =IF(SUM(INDIRECT(CHAR(COLUMN()+38)&(ROW()-5)*8-2&":"&CHAR(COLUMN()+38)&(ROW()-5)*8+5))=0,"",SUM(INDIRECT(CHAR(COLUMN()+38)&(ROW()-5)*8-2&":"&CHAR(COLUMN()+38)&(ROW()-5)*8+5))/INDIRECT("C"&(ROW()-5)*8-2)) | AI16: =IF(SUM(INDIRECT(CHAR(COLUMN()+38)&(ROW()-5)*8-2&":"&CHAR(COLUMN()+38)&(ROW()-5)*8+5))=0,"",SUM(INDIRECT(CHAR(COLUMN()+38)&(ROW()-5)*8-2&":"&CHAR(COLUMN()+38)&(ROW()-5)*8+5))/INDIRECT("C"&(ROW()-5)*8-2)) | AJ16: =IF(SUM(INDIRECT(CHAR(COLUMN()+38)&(ROW()-5)*8-2&":"&CHAR(COLUMN()+38)&(ROW()-5)*8+5))=0,"",SUM(INDIRECT(CHAR(COLUMN()+38)&(ROW()-5)*8-2&":"&CHAR(COLUMN()+38)&(ROW()-5)*8+5))/INDIRECT("C"&(ROW()-5)*8-2)) | AK16: =IF(SUM(INDIRECT(CHAR(COLUMN()+38)&(ROW()-5)*8-2&":"&CHAR(COLUMN()+38)&(ROW()-5)*8+5))=0,"",SUM(INDIRECT(CHAR(COLUMN()+38)&(ROW()-5)*8-2&":"&CHAR(COLUMN()+38)&(ROW()-5)*8+5))/INDIRECT("C"&(ROW()-5)*8-2)) | AL16: =IF(SUM(INDIRECT(CHAR(COLUMN()+38)&(ROW()-5)*8-2&":"&CHAR(COLUMN()+38)&(ROW()-5)*8+5))=0,"",SUM(INDIRECT(CHAR(COLUMN()+38)&(ROW()-5)*8-2&":"&CHAR(COLUMN()+38)&(ROW()-5)*8+5))/INDIRECT("C"&(ROW()-5)*8-2)) | ... AS16: =IF(SUM(INDIRECT(CHAR(COLUMN()+38)&(ROW()-5)*8-2&":"&CHAR(COLUMN()+38)&(ROW()-5)*8+5))=0,"",SUM(INDIRECT(CHAR(COLUMN()+38)&(ROW()-5)*8-2&":"&CHAR(COLUMN()+38)&(ROW()-5)*8+5))/INDIRECT("C"&(ROW()-5)*8-2)) | AT16: 11 | AU16: =IF(COUNT($AE16:$AS16)=0,"",PERCENTILE($AE16:$AS16,0.25)) | AV16: =IF(COUNT($AE16:$AS16)=0,"",MAX($AE16:$AS16)) | AW16: =IF(COUNT($AE16:$AS16)=0,"",MIN($AE16:$AS16)) | AX16: =IF(COUNT($AE16:$AS16)=0,"",PERCENTILE($AE16:$AS16,0.75))
T17: =IF(COUNT(E17:S17)=0,"",SUM(E17:S17)) | U17: =IF(COUNT(E17:S17)=0,"",SUMSQ(E17:S17)) | V17: =IF(COUNT(E17:S17)=0,"",AVERAGE(E17:S17)) | W17: =IF(COUNT(E17:S17)=0,"",STDEVP(E17:S17)) | X17: =IF(COUNT(E17:S17)=0,"",V17-1*W17) | Y17: =IF(COUNT(E17:S17)=0,"",V17+1*W17) | Z17: =IF(COUNT(E17:S17)=0,"",SUM(IF(AND(E17>X17,E17<Y17),E17,0),IF(AND(F17>X17,F17<Y17),F17,0),IF(AND(G17>X17,G17<Y17),G17,0),IF(AND(H17>X17,H17<Y17),H17,0),IF(AND(I17>X17,I17<Y17),I17,0),IF(AND(J17>X17,J17<Y17),J17,0),IF(AND(K17>X17,K17<Y17),K17,0),IF(AND(L17>X17,L17<Y17),L17,0),IF(AND(M17>X17,M17<Y17),M17,0),IF(AND(N17>X17,N17<Y17),N17,0),IF(AND(O17>X17,O17<Y17),O17,0),IF(AND(P17>X17,P17<Y17),P17,0),IF(AND(Q17>X17,Q17<Y17),Q17,0),IF(AND(R17>X17,R17<Y17),R17,0),IF(AND(S17>X17,S17<Y17),S17,0))/SUM(IF(AND(E17>X17,E17<Y17,E17<>0),1,0),IF(AND(F17>X17,F17<Y17,F17<>0),1,0),IF(AND(G17>X17,G17<Y17,G17<>0),1,0),IF(AND(H17>X17,H17<Y17,H17<>0),1,0),IF(AND(I17>X17,I17<Y17,I17<>0),1,0),IF(AND(J17>X17,J17<Y17,J17<>0),1,0),IF(AND(K17>X17,K17<Y17,K17<>0),1,0),IF(AND(L17>X17,L17<Y17,L17<>0),1,0),IF(AND(M17>X17,M17<Y17,M17<>0),1,0),IF(AND(N17>X17,N17<Y17,N17<>0),1,0),IF(AND(O17>X17,O17<Y17,O17<>0),1,0),IF(AND(P17>X17,P17<Y17,P17<>0),1,0),IF(AND(Q17>X17,Q17<Y17,Q17<>0),1,0),IF(AND(R17>X17,R17<Y17,R17<>0),1,0),IF(AND(S17>X17,S17<Y17,S17<>0),1,0))) | AA17: =IF(COUNT(E17:S17)=0,"",SUM(IF(AND(E17>X17,E17<Y17),E17,0),IF(AND(F17>X17,F17<Y17),F17,0),IF(AND(G17>X17,G17<Y17),G17,0),IF(AND(H17>X17,H17<Y17),H17,0),IF(AND(I17>X17,I17<Y17),I17,0),IF(AND(J17>X17,J17<Y17),J17,0),IF(AND(K17>X17,K17<Y17),K17,0),IF(AND(L17>X17,L17<Y17),L17,0),IF(AND(M17>X17,M17<Y17),M17,0),IF(AND(N17>X17,N17<Y17),N17,0),IF(AND(O17>X17,O17<Y17),O17,0),IF(AND(P17>X17,P17<Y17),P17,0),IF(AND(Q17>X17,Q17<Y17),Q17,0),IF(AND(R17>X17,R17<Y17),R17,0),IF(AND(S17>X17,S17<Y17),S17,0))) | AB17: =IF(COUNT(E17:S17)=0,"",SUMSQ(IF(AND(E17>X17,E17<Y17),E17,0),IF(AND(F17>X17,F17<Y17),F17,0),IF(AND(G17>X17,G17<Y17),G17,0),IF(AND(H17>X17,H17<Y17),H17,0),IF(AND(I17>X17,I17<Y17),I17,0),IF(AND(J17>X17,J17<Y17),J17,0),IF(AND(K17>X17,K17<Y17),K17,0),IF(AND(L17>X17,L17<Y17),L17,0),IF(AND(M17>X17,M17<Y17),M17,0),IF(AND(N17>X17,N17<Y17),N17,0),IF(AND(O17>X17,O17<Y17),O17,0),IF(AND(P17>X17,P17<Y17),P17,0),IF(AND(Q17>X17,Q17<Y17),Q17,0),IF(AND(R17>X17,R17<Y17),R17,0),IF(AND(S17>X17,S17<Y17),S17,0))) | AC17: =IF(COUNT(E17:S17)=0,"",POWER(40*SQRT(SUM(IF(AND(E17>X17,E17<Y17),1,0),IF(AND(F17>X17,F17<Y17),1,0),IF(AND(G17>X17,G17<Y17),1,0),IF(AND(H17>X17,H17<Y17),1,0),IF(AND(I17>X17,I17<Y17),1,0),IF(AND(J17>X17,J17<Y17),1,0),IF(AND(K17>X17,K17<Y17),1,0),IF(AND(L17>X17,L17<Y17),1,0),IF(AND(M17>X17,M17<Y17),1,0),IF(AND(N17>X17,N17<Y17),1,0),IF(AND(O17>X17,O17<Y17),1,0),IF(AND(P17>X17,P17<Y17),1,0),IF(AND(Q17>X17,Q17<Y17),1,0),IF(AND(R17>X17,R17<Y17),1,0),IF(AND(S17>X17,S17<Y17),1,0))*AB17-POWER(AA17,2))/AA17,2)) | AD17: 12 | AE17: =IF(SUM(INDIRECT(CHAR(COLUMN()+38)&(ROW()-5)*8-2&":"&CHAR(COLUMN()+38)&(ROW()-5)*8+5))=0,"",SUM(INDIRECT(CHAR(COLUMN()+38)&(ROW()-5)*8-2&":"&CHAR(COLUMN()+38)&(ROW()-5)*8+5))/INDIRECT("C"&(ROW()-5)*8-2)) | AF17: =IF(SUM(INDIRECT(CHAR(COLUMN()+38)&(ROW()-5)*8-2&":"&CHAR(COLUMN()+38)&(ROW()-5)*8+5))=0,"",SUM(INDIRECT(CHAR(COLUMN()+38)&(ROW()-5)*8-2&":"&CHAR(COLUMN()+38)&(ROW()-5)*8+5))/INDIRECT("C"&(ROW()-5)*8-2)) | AG17: =IF(SUM(INDIRECT(CHAR(COLUMN()+38)&(ROW()-5)*8-2&":"&CHAR(COLUMN()+38)&(ROW()-5)*8+5))=0,"",SUM(INDIRECT(CHAR(COLUMN()+38)&(ROW()-5)*8-2&":"&CHAR(COLUMN()+38)&(ROW()-5)*8+5))/INDIRECT("C"&(ROW()-5)*8-2)) | AH17: =IF(SUM(INDIRECT(CHAR(COLUMN()+38)&(ROW()-5)*8-2&":"&CHAR(COLUMN()+38)&(ROW()-5)*8+5))=0,"",SUM(INDIRECT(CHAR(COLUMN()+38)&(ROW()-5)*8-2&":"&CHAR(COLUMN()+38)&(ROW()-5)*8+5))/INDIRECT("C"&(ROW()-5)*8-2)) | AI17: =IF(SUM(INDIRECT(CHAR(COLUMN()+38)&(ROW()-5)*8-2&":"&CHAR(COLUMN()+38)&(ROW()-5)*8+5))=0,"",SUM(INDIRECT(CHAR(COLUMN()+38)&(ROW()-5)*8-2&":"&CHAR(COLUMN()+38)&(ROW()-5)*8+5))/INDIRECT("C"&(ROW()-5)*8-2)) | AJ17: =IF(SUM(INDIRECT(CHAR(COLUMN()+38)&(ROW()-5)*8-2&":"&CHAR(COLUMN()+38)&(ROW()-5)*8+5))=0,"",SUM(INDIRECT(CHAR(COLUMN()+38)&(ROW()-5)*8-2&":"&CHAR(COLUMN()+38)&(ROW()-5)*8+5))/INDIRECT("C"&(ROW()-5)*8-2)) | AK17: =IF(SUM(INDIRECT(CHAR(COLUMN()+38)&(ROW()-5)*8-2&":"&CHAR(COLUMN()+38)&(ROW()-5)*8+5))=0,"",SUM(INDIRECT(CHAR(COLUMN()+38)&(ROW()-5)*8-2&":"&CHAR(COLUMN()+38)&(ROW()-5)*8+5))/INDIRECT("C"&(ROW()-5)*8-2)) | AL17: =IF(SUM(INDIRECT(CHAR(COLUMN()+38)&(ROW()-5)*8-2&":"&CHAR(COLUMN()+38)&(ROW()-5)*8+5))=0,"",SUM(INDIRECT(CHAR(COLUMN()+38)&(ROW()-5)*8-2&":"&CHAR(COLUMN()+38)&(ROW()-5)*8+5))/INDIRECT("C"&(ROW()-5)*8-2)) | ... AS17: =IF(SUM(INDIRECT(CHAR(COLUMN()+38)&(ROW()-5)*8-2&":"&CHAR(COLUMN()+38)&(ROW()-5)*8+5))=0,"",SUM(INDIRECT(CHAR(COLUMN()+38)&(ROW()-5)*8-2&":"&CHAR(COLUMN()+38)&(ROW()-5)*8+5))/INDIRECT("C"&(ROW()-5)*8-2)) | AT17: 12 | AU17: =IF(COUNT($AE17:$AS17)=0,"",PERCENTILE($AE17:$AS17,0.25)) | AV17: =IF(COUNT($AE17:$AS17)=0,"",MAX($AE17:$AS17)) | AW17: =IF(COUNT($AE17:$AS17)=0,"",MIN($AE17:$AS17)) | AX17: =IF(COUNT($AE17:$AS17)=0,"",PERCENTILE($AE17:$AS17,0.75))
